[2022-12-11T00:20:56.649+0000] {processor.py:154} INFO - Started process (PID=25322) to work on /opt/airflow/dags/data_tools_final_oprator.py
[2022-12-11T00:20:56.651+0000] {processor.py:756} INFO - Processing file /opt/airflow/dags/data_tools_final_oprator.py for tasks to queue
[2022-12-11T00:20:56.652+0000] {logging_mixin.py:137} INFO - [2022-12-11T00:20:56.652+0000] {dagbag.py:537} INFO - Filling up the DagBag from /opt/airflow/dags/data_tools_final_oprator.py
[2022-12-11T00:21:03.433+0000] {logging_mixin.py:137} INFO - [2022-12-11T00:21:03.378+0000] {dagbag.py:342} ERROR - Failed to import: /opt/airflow/dags/data_tools_final_oprator.py
Traceback (most recent call last):
  File "/home/airflow/.local/lib/python3.7/site-packages/airflow/models/dagbag.py", line 338, in parse
    loader.exec_module(new_module)
  File "<frozen importlib._bootstrap_external>", line 728, in exec_module
  File "<frozen importlib._bootstrap>", line 219, in _call_with_frames_removed
  File "/opt/airflow/dags/data_tools_final_oprator.py", line 13, in <module>
    import datatool_model
  File "/opt/airflow/plugins/datatool_model.py", line 106, in <module>
    preprocess = traffy.import_data()
  File "/opt/airflow/plugins/datatool_model.py", line 24, in import_data
    df = pd.read_csv('/Users/80524/Downloads/apache_airflow/data/traffy_fondue_data.csv')
  File "/home/airflow/.local/lib/python3.7/site-packages/pandas/util/_decorators.py", line 311, in wrapper
    return func(*args, **kwargs)
  File "/home/airflow/.local/lib/python3.7/site-packages/pandas/io/parsers/readers.py", line 586, in read_csv
    return _read(filepath_or_buffer, kwds)
  File "/home/airflow/.local/lib/python3.7/site-packages/pandas/io/parsers/readers.py", line 482, in _read
    parser = TextFileReader(filepath_or_buffer, **kwds)
  File "/home/airflow/.local/lib/python3.7/site-packages/pandas/io/parsers/readers.py", line 811, in __init__
    self._engine = self._make_engine(self.engine)
  File "/home/airflow/.local/lib/python3.7/site-packages/pandas/io/parsers/readers.py", line 1040, in _make_engine
    return mapping[engine](self.f, **self.options)  # type: ignore[call-arg]
  File "/home/airflow/.local/lib/python3.7/site-packages/pandas/io/parsers/c_parser_wrapper.py", line 51, in __init__
    self._open_handles(src, kwds)
  File "/home/airflow/.local/lib/python3.7/site-packages/pandas/io/parsers/base_parser.py", line 229, in _open_handles
    errors=kwds.get("encoding_errors", "strict"),
  File "/home/airflow/.local/lib/python3.7/site-packages/pandas/io/common.py", line 707, in get_handle
    newline="",
FileNotFoundError: [Errno 2] No such file or directory: '/Users/80524/Downloads/apache_airflow/data/traffy_fondue_data.csv'
[2022-12-11T00:21:03.442+0000] {processor.py:768} WARNING - No viable dags retrieved from /opt/airflow/dags/data_tools_final_oprator.py
[2022-12-11T00:21:03.517+0000] {processor.py:176} INFO - Processing /opt/airflow/dags/data_tools_final_oprator.py took 6.870 seconds
[2022-12-11T01:16:50.352+0000] {processor.py:154} INFO - Started process (PID=25350) to work on /opt/airflow/dags/data_tools_final_oprator.py
[2022-12-11T01:16:50.354+0000] {processor.py:756} INFO - Processing file /opt/airflow/dags/data_tools_final_oprator.py for tasks to queue
[2022-12-11T01:16:50.356+0000] {logging_mixin.py:137} INFO - [2022-12-11T01:16:50.356+0000] {dagbag.py:537} INFO - Filling up the DagBag from /opt/airflow/dags/data_tools_final_oprator.py
[2022-12-11T01:16:53.828+0000] {logging_mixin.py:137} INFO - [2022-12-11T01:16:53.817+0000] {dagbag.py:342} ERROR - Failed to import: /opt/airflow/dags/data_tools_final_oprator.py
Traceback (most recent call last):
  File "/home/airflow/.local/lib/python3.7/site-packages/airflow/models/dagbag.py", line 338, in parse
    loader.exec_module(new_module)
  File "<frozen importlib._bootstrap_external>", line 728, in exec_module
  File "<frozen importlib._bootstrap>", line 219, in _call_with_frames_removed
  File "/opt/airflow/dags/data_tools_final_oprator.py", line 13, in <module>
    import datatool_model
  File "/opt/airflow/plugins/datatool_model.py", line 106, in <module>
    preprocess = traffy.import_data()
  File "/opt/airflow/plugins/datatool_model.py", line 24, in import_data
    df = pd.read_csv('/Users/80524/Downloads/apache_airflow/data/traffy_fondue_data.csv')
  File "/home/airflow/.local/lib/python3.7/site-packages/pandas/util/_decorators.py", line 311, in wrapper
    return func(*args, **kwargs)
  File "/home/airflow/.local/lib/python3.7/site-packages/pandas/io/parsers/readers.py", line 586, in read_csv
    return _read(filepath_or_buffer, kwds)
  File "/home/airflow/.local/lib/python3.7/site-packages/pandas/io/parsers/readers.py", line 482, in _read
    parser = TextFileReader(filepath_or_buffer, **kwds)
  File "/home/airflow/.local/lib/python3.7/site-packages/pandas/io/parsers/readers.py", line 811, in __init__
    self._engine = self._make_engine(self.engine)
  File "/home/airflow/.local/lib/python3.7/site-packages/pandas/io/parsers/readers.py", line 1040, in _make_engine
    return mapping[engine](self.f, **self.options)  # type: ignore[call-arg]
  File "/home/airflow/.local/lib/python3.7/site-packages/pandas/io/parsers/c_parser_wrapper.py", line 51, in __init__
    self._open_handles(src, kwds)
  File "/home/airflow/.local/lib/python3.7/site-packages/pandas/io/parsers/base_parser.py", line 229, in _open_handles
    errors=kwds.get("encoding_errors", "strict"),
  File "/home/airflow/.local/lib/python3.7/site-packages/pandas/io/common.py", line 707, in get_handle
    newline="",
FileNotFoundError: [Errno 2] No such file or directory: '/Users/80524/Downloads/apache_airflow/data/traffy_fondue_data.csv'
[2022-12-11T01:16:53.831+0000] {processor.py:768} WARNING - No viable dags retrieved from /opt/airflow/dags/data_tools_final_oprator.py
[2022-12-11T01:16:53.848+0000] {processor.py:176} INFO - Processing /opt/airflow/dags/data_tools_final_oprator.py took 3.509 seconds
[2022-12-11T01:30:33.302+0000] {processor.py:154} INFO - Started process (PID=25379) to work on /opt/airflow/dags/data_tools_final_oprator.py
[2022-12-11T01:30:33.303+0000] {processor.py:756} INFO - Processing file /opt/airflow/dags/data_tools_final_oprator.py for tasks to queue
[2022-12-11T01:30:33.304+0000] {logging_mixin.py:137} INFO - [2022-12-11T01:30:33.304+0000] {dagbag.py:537} INFO - Filling up the DagBag from /opt/airflow/dags/data_tools_final_oprator.py
[2022-12-11T01:30:37.273+0000] {logging_mixin.py:137} INFO - [2022-12-11T01:30:37.268+0000] {dagbag.py:342} ERROR - Failed to import: /opt/airflow/dags/data_tools_final_oprator.py
Traceback (most recent call last):
  File "/home/airflow/.local/lib/python3.7/site-packages/airflow/models/dagbag.py", line 338, in parse
    loader.exec_module(new_module)
  File "<frozen importlib._bootstrap_external>", line 728, in exec_module
  File "<frozen importlib._bootstrap>", line 219, in _call_with_frames_removed
  File "/opt/airflow/dags/data_tools_final_oprator.py", line 13, in <module>
    import datatool_model
  File "/opt/airflow/plugins/datatool_model.py", line 106, in <module>
    preprocess = traffy.import_data()
  File "/opt/airflow/plugins/datatool_model.py", line 24, in import_data
    df = pd.read_csv('/Users/80524/Downloads/apache_airflow/data/traffy_fondue_data.csv')
  File "/home/airflow/.local/lib/python3.7/site-packages/pandas/util/_decorators.py", line 311, in wrapper
    return func(*args, **kwargs)
  File "/home/airflow/.local/lib/python3.7/site-packages/pandas/io/parsers/readers.py", line 586, in read_csv
    return _read(filepath_or_buffer, kwds)
  File "/home/airflow/.local/lib/python3.7/site-packages/pandas/io/parsers/readers.py", line 482, in _read
    parser = TextFileReader(filepath_or_buffer, **kwds)
  File "/home/airflow/.local/lib/python3.7/site-packages/pandas/io/parsers/readers.py", line 811, in __init__
    self._engine = self._make_engine(self.engine)
  File "/home/airflow/.local/lib/python3.7/site-packages/pandas/io/parsers/readers.py", line 1040, in _make_engine
    return mapping[engine](self.f, **self.options)  # type: ignore[call-arg]
  File "/home/airflow/.local/lib/python3.7/site-packages/pandas/io/parsers/c_parser_wrapper.py", line 51, in __init__
    self._open_handles(src, kwds)
  File "/home/airflow/.local/lib/python3.7/site-packages/pandas/io/parsers/base_parser.py", line 229, in _open_handles
    errors=kwds.get("encoding_errors", "strict"),
  File "/home/airflow/.local/lib/python3.7/site-packages/pandas/io/common.py", line 707, in get_handle
    newline="",
FileNotFoundError: [Errno 2] No such file or directory: '/Users/80524/Downloads/apache_airflow/data/traffy_fondue_data.csv'
[2022-12-11T01:30:37.275+0000] {processor.py:768} WARNING - No viable dags retrieved from /opt/airflow/dags/data_tools_final_oprator.py
[2022-12-11T01:30:37.294+0000] {processor.py:176} INFO - Processing /opt/airflow/dags/data_tools_final_oprator.py took 3.995 seconds
[2022-12-11T01:59:41.197+0000] {processor.py:154} INFO - Started process (PID=25408) to work on /opt/airflow/dags/data_tools_final_oprator.py
[2022-12-11T01:59:41.199+0000] {processor.py:756} INFO - Processing file /opt/airflow/dags/data_tools_final_oprator.py for tasks to queue
[2022-12-11T01:59:41.200+0000] {logging_mixin.py:137} INFO - [2022-12-11T01:59:41.200+0000] {dagbag.py:537} INFO - Filling up the DagBag from /opt/airflow/dags/data_tools_final_oprator.py
[2022-12-11T01:59:44.040+0000] {logging_mixin.py:137} INFO - [2022-12-11T01:59:44.034+0000] {dagbag.py:342} ERROR - Failed to import: /opt/airflow/dags/data_tools_final_oprator.py
Traceback (most recent call last):
  File "/home/airflow/.local/lib/python3.7/site-packages/airflow/models/dagbag.py", line 338, in parse
    loader.exec_module(new_module)
  File "<frozen importlib._bootstrap_external>", line 728, in exec_module
  File "<frozen importlib._bootstrap>", line 219, in _call_with_frames_removed
  File "/opt/airflow/dags/data_tools_final_oprator.py", line 13, in <module>
    import datatool_model
  File "/opt/airflow/plugins/datatool_model.py", line 106, in <module>
    preprocess = traffy.import_data()
  File "/opt/airflow/plugins/datatool_model.py", line 24, in import_data
    df = pd.read_csv('/Users/80524/Downloads/apache_airflow/data/traffy_fondue_data.csv')
  File "/home/airflow/.local/lib/python3.7/site-packages/pandas/util/_decorators.py", line 311, in wrapper
    return func(*args, **kwargs)
  File "/home/airflow/.local/lib/python3.7/site-packages/pandas/io/parsers/readers.py", line 586, in read_csv
    return _read(filepath_or_buffer, kwds)
  File "/home/airflow/.local/lib/python3.7/site-packages/pandas/io/parsers/readers.py", line 482, in _read
    parser = TextFileReader(filepath_or_buffer, **kwds)
  File "/home/airflow/.local/lib/python3.7/site-packages/pandas/io/parsers/readers.py", line 811, in __init__
    self._engine = self._make_engine(self.engine)
  File "/home/airflow/.local/lib/python3.7/site-packages/pandas/io/parsers/readers.py", line 1040, in _make_engine
    return mapping[engine](self.f, **self.options)  # type: ignore[call-arg]
  File "/home/airflow/.local/lib/python3.7/site-packages/pandas/io/parsers/c_parser_wrapper.py", line 51, in __init__
    self._open_handles(src, kwds)
  File "/home/airflow/.local/lib/python3.7/site-packages/pandas/io/parsers/base_parser.py", line 229, in _open_handles
    errors=kwds.get("encoding_errors", "strict"),
  File "/home/airflow/.local/lib/python3.7/site-packages/pandas/io/common.py", line 707, in get_handle
    newline="",
FileNotFoundError: [Errno 2] No such file or directory: '/Users/80524/Downloads/apache_airflow/data/traffy_fondue_data.csv'
[2022-12-11T01:59:44.059+0000] {processor.py:768} WARNING - No viable dags retrieved from /opt/airflow/dags/data_tools_final_oprator.py
[2022-12-11T01:59:44.071+0000] {processor.py:176} INFO - Processing /opt/airflow/dags/data_tools_final_oprator.py took 2.878 seconds
[2022-12-11T03:09:54.567+0000] {processor.py:154} INFO - Started process (PID=25429) to work on /opt/airflow/dags/data_tools_final_oprator.py
[2022-12-11T03:09:54.572+0000] {processor.py:756} INFO - Processing file /opt/airflow/dags/data_tools_final_oprator.py for tasks to queue
[2022-12-11T03:09:54.574+0000] {logging_mixin.py:137} INFO - [2022-12-11T03:09:54.574+0000] {dagbag.py:537} INFO - Filling up the DagBag from /opt/airflow/dags/data_tools_final_oprator.py
[2022-12-11T03:09:58.495+0000] {logging_mixin.py:137} INFO - [2022-12-11T03:09:58.450+0000] {dagbag.py:342} ERROR - Failed to import: /opt/airflow/dags/data_tools_final_oprator.py
Traceback (most recent call last):
  File "/home/airflow/.local/lib/python3.7/site-packages/airflow/models/dagbag.py", line 338, in parse
    loader.exec_module(new_module)
  File "<frozen importlib._bootstrap_external>", line 728, in exec_module
  File "<frozen importlib._bootstrap>", line 219, in _call_with_frames_removed
  File "/opt/airflow/dags/data_tools_final_oprator.py", line 13, in <module>
    import datatool_model
  File "/opt/airflow/plugins/datatool_model.py", line 106, in <module>
    preprocess = traffy.import_data()
  File "/opt/airflow/plugins/datatool_model.py", line 24, in import_data
    df = pd.read_csv('/Users/80524/Downloads/apache_airflow/data/traffy_fondue_data.csv')
  File "/home/airflow/.local/lib/python3.7/site-packages/pandas/util/_decorators.py", line 311, in wrapper
    return func(*args, **kwargs)
  File "/home/airflow/.local/lib/python3.7/site-packages/pandas/io/parsers/readers.py", line 586, in read_csv
    return _read(filepath_or_buffer, kwds)
  File "/home/airflow/.local/lib/python3.7/site-packages/pandas/io/parsers/readers.py", line 482, in _read
    parser = TextFileReader(filepath_or_buffer, **kwds)
  File "/home/airflow/.local/lib/python3.7/site-packages/pandas/io/parsers/readers.py", line 811, in __init__
    self._engine = self._make_engine(self.engine)
  File "/home/airflow/.local/lib/python3.7/site-packages/pandas/io/parsers/readers.py", line 1040, in _make_engine
    return mapping[engine](self.f, **self.options)  # type: ignore[call-arg]
  File "/home/airflow/.local/lib/python3.7/site-packages/pandas/io/parsers/c_parser_wrapper.py", line 51, in __init__
    self._open_handles(src, kwds)
  File "/home/airflow/.local/lib/python3.7/site-packages/pandas/io/parsers/base_parser.py", line 229, in _open_handles
    errors=kwds.get("encoding_errors", "strict"),
  File "/home/airflow/.local/lib/python3.7/site-packages/pandas/io/common.py", line 707, in get_handle
    newline="",
FileNotFoundError: [Errno 2] No such file or directory: '/Users/80524/Downloads/apache_airflow/data/traffy_fondue_data.csv'
[2022-12-11T03:09:58.496+0000] {processor.py:768} WARNING - No viable dags retrieved from /opt/airflow/dags/data_tools_final_oprator.py
[2022-12-11T03:09:58.511+0000] {processor.py:176} INFO - Processing /opt/airflow/dags/data_tools_final_oprator.py took 3.954 seconds
[2022-12-11T04:06:12.744+0000] {processor.py:154} INFO - Started process (PID=25459) to work on /opt/airflow/dags/data_tools_final_oprator.py
[2022-12-11T04:06:12.746+0000] {processor.py:756} INFO - Processing file /opt/airflow/dags/data_tools_final_oprator.py for tasks to queue
[2022-12-11T04:06:12.748+0000] {logging_mixin.py:137} INFO - [2022-12-11T04:06:12.748+0000] {dagbag.py:537} INFO - Filling up the DagBag from /opt/airflow/dags/data_tools_final_oprator.py
[2022-12-11T04:06:15.868+0000] {logging_mixin.py:137} INFO - [2022-12-11T04:06:15.863+0000] {dagbag.py:342} ERROR - Failed to import: /opt/airflow/dags/data_tools_final_oprator.py
Traceback (most recent call last):
  File "/home/airflow/.local/lib/python3.7/site-packages/airflow/models/dagbag.py", line 338, in parse
    loader.exec_module(new_module)
  File "<frozen importlib._bootstrap_external>", line 728, in exec_module
  File "<frozen importlib._bootstrap>", line 219, in _call_with_frames_removed
  File "/opt/airflow/dags/data_tools_final_oprator.py", line 13, in <module>
    import datatool_model
  File "/opt/airflow/plugins/datatool_model.py", line 106, in <module>
    preprocess = traffy.import_data()
  File "/opt/airflow/plugins/datatool_model.py", line 24, in import_data
    df = pd.read_csv('/Users/80524/Downloads/apache_airflow/data/traffy_fondue_data.csv')
  File "/home/airflow/.local/lib/python3.7/site-packages/pandas/util/_decorators.py", line 311, in wrapper
    return func(*args, **kwargs)
  File "/home/airflow/.local/lib/python3.7/site-packages/pandas/io/parsers/readers.py", line 586, in read_csv
    return _read(filepath_or_buffer, kwds)
  File "/home/airflow/.local/lib/python3.7/site-packages/pandas/io/parsers/readers.py", line 482, in _read
    parser = TextFileReader(filepath_or_buffer, **kwds)
  File "/home/airflow/.local/lib/python3.7/site-packages/pandas/io/parsers/readers.py", line 811, in __init__
    self._engine = self._make_engine(self.engine)
  File "/home/airflow/.local/lib/python3.7/site-packages/pandas/io/parsers/readers.py", line 1040, in _make_engine
    return mapping[engine](self.f, **self.options)  # type: ignore[call-arg]
  File "/home/airflow/.local/lib/python3.7/site-packages/pandas/io/parsers/c_parser_wrapper.py", line 51, in __init__
    self._open_handles(src, kwds)
  File "/home/airflow/.local/lib/python3.7/site-packages/pandas/io/parsers/base_parser.py", line 229, in _open_handles
    errors=kwds.get("encoding_errors", "strict"),
  File "/home/airflow/.local/lib/python3.7/site-packages/pandas/io/common.py", line 707, in get_handle
    newline="",
FileNotFoundError: [Errno 2] No such file or directory: '/Users/80524/Downloads/apache_airflow/data/traffy_fondue_data.csv'
[2022-12-11T04:06:15.870+0000] {processor.py:768} WARNING - No viable dags retrieved from /opt/airflow/dags/data_tools_final_oprator.py
[2022-12-11T04:06:15.884+0000] {processor.py:176} INFO - Processing /opt/airflow/dags/data_tools_final_oprator.py took 3.143 seconds
[2022-12-11T04:06:45.979+0000] {processor.py:154} INFO - Started process (PID=25488) to work on /opt/airflow/dags/data_tools_final_oprator.py
[2022-12-11T04:06:45.981+0000] {processor.py:756} INFO - Processing file /opt/airflow/dags/data_tools_final_oprator.py for tasks to queue
[2022-12-11T04:06:45.983+0000] {logging_mixin.py:137} INFO - [2022-12-11T04:06:45.983+0000] {dagbag.py:537} INFO - Filling up the DagBag from /opt/airflow/dags/data_tools_final_oprator.py
[2022-12-11T04:06:48.285+0000] {logging_mixin.py:137} INFO - [2022-12-11T04:06:48.280+0000] {dagbag.py:342} ERROR - Failed to import: /opt/airflow/dags/data_tools_final_oprator.py
Traceback (most recent call last):
  File "/home/airflow/.local/lib/python3.7/site-packages/airflow/models/dagbag.py", line 338, in parse
    loader.exec_module(new_module)
  File "<frozen importlib._bootstrap_external>", line 728, in exec_module
  File "<frozen importlib._bootstrap>", line 219, in _call_with_frames_removed
  File "/opt/airflow/dags/data_tools_final_oprator.py", line 13, in <module>
    import datatool_model
  File "/opt/airflow/plugins/datatool_model.py", line 106, in <module>
    preprocess = traffy.import_data()
  File "/opt/airflow/plugins/datatool_model.py", line 24, in import_data
    df = pd.read_csv('/Users/80524/Downloads/apache_airflow/data/traffy_fondue_data.csv')
  File "/home/airflow/.local/lib/python3.7/site-packages/pandas/util/_decorators.py", line 311, in wrapper
    return func(*args, **kwargs)
  File "/home/airflow/.local/lib/python3.7/site-packages/pandas/io/parsers/readers.py", line 586, in read_csv
    return _read(filepath_or_buffer, kwds)
  File "/home/airflow/.local/lib/python3.7/site-packages/pandas/io/parsers/readers.py", line 482, in _read
    parser = TextFileReader(filepath_or_buffer, **kwds)
  File "/home/airflow/.local/lib/python3.7/site-packages/pandas/io/parsers/readers.py", line 811, in __init__
    self._engine = self._make_engine(self.engine)
  File "/home/airflow/.local/lib/python3.7/site-packages/pandas/io/parsers/readers.py", line 1040, in _make_engine
    return mapping[engine](self.f, **self.options)  # type: ignore[call-arg]
  File "/home/airflow/.local/lib/python3.7/site-packages/pandas/io/parsers/c_parser_wrapper.py", line 51, in __init__
    self._open_handles(src, kwds)
  File "/home/airflow/.local/lib/python3.7/site-packages/pandas/io/parsers/base_parser.py", line 229, in _open_handles
    errors=kwds.get("encoding_errors", "strict"),
  File "/home/airflow/.local/lib/python3.7/site-packages/pandas/io/common.py", line 707, in get_handle
    newline="",
FileNotFoundError: [Errno 2] No such file or directory: '/Users/80524/Downloads/apache_airflow/data/traffy_fondue_data.csv'
[2022-12-11T04:06:48.287+0000] {processor.py:768} WARNING - No viable dags retrieved from /opt/airflow/dags/data_tools_final_oprator.py
[2022-12-11T04:06:48.301+0000] {processor.py:176} INFO - Processing /opt/airflow/dags/data_tools_final_oprator.py took 2.326 seconds
[2022-12-11T04:07:18.468+0000] {processor.py:154} INFO - Started process (PID=25517) to work on /opt/airflow/dags/data_tools_final_oprator.py
[2022-12-11T04:07:18.471+0000] {processor.py:756} INFO - Processing file /opt/airflow/dags/data_tools_final_oprator.py for tasks to queue
[2022-12-11T04:07:18.473+0000] {logging_mixin.py:137} INFO - [2022-12-11T04:07:18.473+0000] {dagbag.py:537} INFO - Filling up the DagBag from /opt/airflow/dags/data_tools_final_oprator.py
[2022-12-11T04:07:20.631+0000] {logging_mixin.py:137} INFO - [2022-12-11T04:07:20.627+0000] {dagbag.py:342} ERROR - Failed to import: /opt/airflow/dags/data_tools_final_oprator.py
Traceback (most recent call last):
  File "/home/airflow/.local/lib/python3.7/site-packages/airflow/models/dagbag.py", line 338, in parse
    loader.exec_module(new_module)
  File "<frozen importlib._bootstrap_external>", line 728, in exec_module
  File "<frozen importlib._bootstrap>", line 219, in _call_with_frames_removed
  File "/opt/airflow/dags/data_tools_final_oprator.py", line 13, in <module>
    import datatool_model
  File "/opt/airflow/plugins/datatool_model.py", line 106, in <module>
    preprocess = traffy.import_data()
  File "/opt/airflow/plugins/datatool_model.py", line 24, in import_data
    df = pd.read_csv('/Users/80524/Downloads/apache_airflow/data/traffy_fondue_data.csv')
  File "/home/airflow/.local/lib/python3.7/site-packages/pandas/util/_decorators.py", line 311, in wrapper
    return func(*args, **kwargs)
  File "/home/airflow/.local/lib/python3.7/site-packages/pandas/io/parsers/readers.py", line 586, in read_csv
    return _read(filepath_or_buffer, kwds)
  File "/home/airflow/.local/lib/python3.7/site-packages/pandas/io/parsers/readers.py", line 482, in _read
    parser = TextFileReader(filepath_or_buffer, **kwds)
  File "/home/airflow/.local/lib/python3.7/site-packages/pandas/io/parsers/readers.py", line 811, in __init__
    self._engine = self._make_engine(self.engine)
  File "/home/airflow/.local/lib/python3.7/site-packages/pandas/io/parsers/readers.py", line 1040, in _make_engine
    return mapping[engine](self.f, **self.options)  # type: ignore[call-arg]
  File "/home/airflow/.local/lib/python3.7/site-packages/pandas/io/parsers/c_parser_wrapper.py", line 51, in __init__
    self._open_handles(src, kwds)
  File "/home/airflow/.local/lib/python3.7/site-packages/pandas/io/parsers/base_parser.py", line 229, in _open_handles
    errors=kwds.get("encoding_errors", "strict"),
  File "/home/airflow/.local/lib/python3.7/site-packages/pandas/io/common.py", line 707, in get_handle
    newline="",
FileNotFoundError: [Errno 2] No such file or directory: '/Users/80524/Downloads/apache_airflow/data/traffy_fondue_data.csv'
[2022-12-11T04:07:20.632+0000] {processor.py:768} WARNING - No viable dags retrieved from /opt/airflow/dags/data_tools_final_oprator.py
[2022-12-11T04:07:20.644+0000] {processor.py:176} INFO - Processing /opt/airflow/dags/data_tools_final_oprator.py took 2.180 seconds
[2022-12-11T04:07:50.973+0000] {processor.py:154} INFO - Started process (PID=25546) to work on /opt/airflow/dags/data_tools_final_oprator.py
[2022-12-11T04:07:50.975+0000] {processor.py:756} INFO - Processing file /opt/airflow/dags/data_tools_final_oprator.py for tasks to queue
[2022-12-11T04:07:50.976+0000] {logging_mixin.py:137} INFO - [2022-12-11T04:07:50.976+0000] {dagbag.py:537} INFO - Filling up the DagBag from /opt/airflow/dags/data_tools_final_oprator.py
[2022-12-11T04:07:52.963+0000] {logging_mixin.py:137} INFO - [2022-12-11T04:07:52.959+0000] {dagbag.py:342} ERROR - Failed to import: /opt/airflow/dags/data_tools_final_oprator.py
Traceback (most recent call last):
  File "/home/airflow/.local/lib/python3.7/site-packages/airflow/models/dagbag.py", line 338, in parse
    loader.exec_module(new_module)
  File "<frozen importlib._bootstrap_external>", line 728, in exec_module
  File "<frozen importlib._bootstrap>", line 219, in _call_with_frames_removed
  File "/opt/airflow/dags/data_tools_final_oprator.py", line 13, in <module>
    import datatool_model
  File "/opt/airflow/plugins/datatool_model.py", line 106, in <module>
    preprocess = traffy.import_data()
  File "/opt/airflow/plugins/datatool_model.py", line 24, in import_data
    df = pd.read_csv('/Users/80524/Downloads/apache_airflow/data/traffy_fondue_data.csv')
  File "/home/airflow/.local/lib/python3.7/site-packages/pandas/util/_decorators.py", line 311, in wrapper
    return func(*args, **kwargs)
  File "/home/airflow/.local/lib/python3.7/site-packages/pandas/io/parsers/readers.py", line 586, in read_csv
    return _read(filepath_or_buffer, kwds)
  File "/home/airflow/.local/lib/python3.7/site-packages/pandas/io/parsers/readers.py", line 482, in _read
    parser = TextFileReader(filepath_or_buffer, **kwds)
  File "/home/airflow/.local/lib/python3.7/site-packages/pandas/io/parsers/readers.py", line 811, in __init__
    self._engine = self._make_engine(self.engine)
  File "/home/airflow/.local/lib/python3.7/site-packages/pandas/io/parsers/readers.py", line 1040, in _make_engine
    return mapping[engine](self.f, **self.options)  # type: ignore[call-arg]
  File "/home/airflow/.local/lib/python3.7/site-packages/pandas/io/parsers/c_parser_wrapper.py", line 51, in __init__
    self._open_handles(src, kwds)
  File "/home/airflow/.local/lib/python3.7/site-packages/pandas/io/parsers/base_parser.py", line 229, in _open_handles
    errors=kwds.get("encoding_errors", "strict"),
  File "/home/airflow/.local/lib/python3.7/site-packages/pandas/io/common.py", line 707, in get_handle
    newline="",
FileNotFoundError: [Errno 2] No such file or directory: '/Users/80524/Downloads/apache_airflow/data/traffy_fondue_data.csv'
[2022-12-11T04:07:52.966+0000] {processor.py:768} WARNING - No viable dags retrieved from /opt/airflow/dags/data_tools_final_oprator.py
[2022-12-11T04:07:52.977+0000] {processor.py:176} INFO - Processing /opt/airflow/dags/data_tools_final_oprator.py took 2.009 seconds
[2022-12-11T04:08:23.348+0000] {processor.py:154} INFO - Started process (PID=25575) to work on /opt/airflow/dags/data_tools_final_oprator.py
[2022-12-11T04:08:23.350+0000] {processor.py:756} INFO - Processing file /opt/airflow/dags/data_tools_final_oprator.py for tasks to queue
[2022-12-11T04:08:23.351+0000] {logging_mixin.py:137} INFO - [2022-12-11T04:08:23.351+0000] {dagbag.py:537} INFO - Filling up the DagBag from /opt/airflow/dags/data_tools_final_oprator.py
[2022-12-11T04:08:25.327+0000] {logging_mixin.py:137} INFO - [2022-12-11T04:08:25.324+0000] {dagbag.py:342} ERROR - Failed to import: /opt/airflow/dags/data_tools_final_oprator.py
Traceback (most recent call last):
  File "/home/airflow/.local/lib/python3.7/site-packages/airflow/models/dagbag.py", line 338, in parse
    loader.exec_module(new_module)
  File "<frozen importlib._bootstrap_external>", line 728, in exec_module
  File "<frozen importlib._bootstrap>", line 219, in _call_with_frames_removed
  File "/opt/airflow/dags/data_tools_final_oprator.py", line 13, in <module>
    import datatool_model
  File "/opt/airflow/plugins/datatool_model.py", line 106, in <module>
    preprocess = traffy.import_data()
  File "/opt/airflow/plugins/datatool_model.py", line 24, in import_data
    df = pd.read_csv('/Users/80524/Downloads/apache_airflow/data/traffy_fondue_data.csv')
  File "/home/airflow/.local/lib/python3.7/site-packages/pandas/util/_decorators.py", line 311, in wrapper
    return func(*args, **kwargs)
  File "/home/airflow/.local/lib/python3.7/site-packages/pandas/io/parsers/readers.py", line 586, in read_csv
    return _read(filepath_or_buffer, kwds)
  File "/home/airflow/.local/lib/python3.7/site-packages/pandas/io/parsers/readers.py", line 482, in _read
    parser = TextFileReader(filepath_or_buffer, **kwds)
  File "/home/airflow/.local/lib/python3.7/site-packages/pandas/io/parsers/readers.py", line 811, in __init__
    self._engine = self._make_engine(self.engine)
  File "/home/airflow/.local/lib/python3.7/site-packages/pandas/io/parsers/readers.py", line 1040, in _make_engine
    return mapping[engine](self.f, **self.options)  # type: ignore[call-arg]
  File "/home/airflow/.local/lib/python3.7/site-packages/pandas/io/parsers/c_parser_wrapper.py", line 51, in __init__
    self._open_handles(src, kwds)
  File "/home/airflow/.local/lib/python3.7/site-packages/pandas/io/parsers/base_parser.py", line 229, in _open_handles
    errors=kwds.get("encoding_errors", "strict"),
  File "/home/airflow/.local/lib/python3.7/site-packages/pandas/io/common.py", line 707, in get_handle
    newline="",
FileNotFoundError: [Errno 2] No such file or directory: '/Users/80524/Downloads/apache_airflow/data/traffy_fondue_data.csv'
[2022-12-11T04:08:25.329+0000] {processor.py:768} WARNING - No viable dags retrieved from /opt/airflow/dags/data_tools_final_oprator.py
[2022-12-11T04:08:25.340+0000] {processor.py:176} INFO - Processing /opt/airflow/dags/data_tools_final_oprator.py took 1.997 seconds
[2022-12-11T04:08:55.645+0000] {processor.py:154} INFO - Started process (PID=25603) to work on /opt/airflow/dags/data_tools_final_oprator.py
[2022-12-11T04:08:55.648+0000] {processor.py:756} INFO - Processing file /opt/airflow/dags/data_tools_final_oprator.py for tasks to queue
[2022-12-11T04:08:55.651+0000] {logging_mixin.py:137} INFO - [2022-12-11T04:08:55.651+0000] {dagbag.py:537} INFO - Filling up the DagBag from /opt/airflow/dags/data_tools_final_oprator.py
[2022-12-11T04:08:57.624+0000] {logging_mixin.py:137} INFO - [2022-12-11T04:08:57.620+0000] {dagbag.py:342} ERROR - Failed to import: /opt/airflow/dags/data_tools_final_oprator.py
Traceback (most recent call last):
  File "/home/airflow/.local/lib/python3.7/site-packages/airflow/models/dagbag.py", line 338, in parse
    loader.exec_module(new_module)
  File "<frozen importlib._bootstrap_external>", line 728, in exec_module
  File "<frozen importlib._bootstrap>", line 219, in _call_with_frames_removed
  File "/opt/airflow/dags/data_tools_final_oprator.py", line 13, in <module>
    import datatool_model
  File "/opt/airflow/plugins/datatool_model.py", line 106, in <module>
    preprocess = traffy.import_data()
  File "/opt/airflow/plugins/datatool_model.py", line 24, in import_data
    df = pd.read_csv('/Users/80524/Downloads/apache_airflow/data/traffy_fondue_data.csv')
  File "/home/airflow/.local/lib/python3.7/site-packages/pandas/util/_decorators.py", line 311, in wrapper
    return func(*args, **kwargs)
  File "/home/airflow/.local/lib/python3.7/site-packages/pandas/io/parsers/readers.py", line 586, in read_csv
    return _read(filepath_or_buffer, kwds)
  File "/home/airflow/.local/lib/python3.7/site-packages/pandas/io/parsers/readers.py", line 482, in _read
    parser = TextFileReader(filepath_or_buffer, **kwds)
  File "/home/airflow/.local/lib/python3.7/site-packages/pandas/io/parsers/readers.py", line 811, in __init__
    self._engine = self._make_engine(self.engine)
  File "/home/airflow/.local/lib/python3.7/site-packages/pandas/io/parsers/readers.py", line 1040, in _make_engine
    return mapping[engine](self.f, **self.options)  # type: ignore[call-arg]
  File "/home/airflow/.local/lib/python3.7/site-packages/pandas/io/parsers/c_parser_wrapper.py", line 51, in __init__
    self._open_handles(src, kwds)
  File "/home/airflow/.local/lib/python3.7/site-packages/pandas/io/parsers/base_parser.py", line 229, in _open_handles
    errors=kwds.get("encoding_errors", "strict"),
  File "/home/airflow/.local/lib/python3.7/site-packages/pandas/io/common.py", line 707, in get_handle
    newline="",
FileNotFoundError: [Errno 2] No such file or directory: '/Users/80524/Downloads/apache_airflow/data/traffy_fondue_data.csv'
[2022-12-11T04:08:57.625+0000] {processor.py:768} WARNING - No viable dags retrieved from /opt/airflow/dags/data_tools_final_oprator.py
[2022-12-11T04:08:57.636+0000] {processor.py:176} INFO - Processing /opt/airflow/dags/data_tools_final_oprator.py took 1.994 seconds
[2022-12-11T04:09:28.008+0000] {processor.py:154} INFO - Started process (PID=25632) to work on /opt/airflow/dags/data_tools_final_oprator.py
[2022-12-11T04:09:28.010+0000] {processor.py:756} INFO - Processing file /opt/airflow/dags/data_tools_final_oprator.py for tasks to queue
[2022-12-11T04:09:28.012+0000] {logging_mixin.py:137} INFO - [2022-12-11T04:09:28.012+0000] {dagbag.py:537} INFO - Filling up the DagBag from /opt/airflow/dags/data_tools_final_oprator.py
[2022-12-11T04:09:29.997+0000] {logging_mixin.py:137} INFO - [2022-12-11T04:09:29.994+0000] {dagbag.py:342} ERROR - Failed to import: /opt/airflow/dags/data_tools_final_oprator.py
Traceback (most recent call last):
  File "/home/airflow/.local/lib/python3.7/site-packages/airflow/models/dagbag.py", line 338, in parse
    loader.exec_module(new_module)
  File "<frozen importlib._bootstrap_external>", line 728, in exec_module
  File "<frozen importlib._bootstrap>", line 219, in _call_with_frames_removed
  File "/opt/airflow/dags/data_tools_final_oprator.py", line 13, in <module>
    import datatool_model
  File "/opt/airflow/plugins/datatool_model.py", line 106, in <module>
    preprocess = traffy.import_data()
  File "/opt/airflow/plugins/datatool_model.py", line 24, in import_data
    df = pd.read_csv('/Users/80524/Downloads/apache_airflow/data/traffy_fondue_data.csv')
  File "/home/airflow/.local/lib/python3.7/site-packages/pandas/util/_decorators.py", line 311, in wrapper
    return func(*args, **kwargs)
  File "/home/airflow/.local/lib/python3.7/site-packages/pandas/io/parsers/readers.py", line 586, in read_csv
    return _read(filepath_or_buffer, kwds)
  File "/home/airflow/.local/lib/python3.7/site-packages/pandas/io/parsers/readers.py", line 482, in _read
    parser = TextFileReader(filepath_or_buffer, **kwds)
  File "/home/airflow/.local/lib/python3.7/site-packages/pandas/io/parsers/readers.py", line 811, in __init__
    self._engine = self._make_engine(self.engine)
  File "/home/airflow/.local/lib/python3.7/site-packages/pandas/io/parsers/readers.py", line 1040, in _make_engine
    return mapping[engine](self.f, **self.options)  # type: ignore[call-arg]
  File "/home/airflow/.local/lib/python3.7/site-packages/pandas/io/parsers/c_parser_wrapper.py", line 51, in __init__
    self._open_handles(src, kwds)
  File "/home/airflow/.local/lib/python3.7/site-packages/pandas/io/parsers/base_parser.py", line 229, in _open_handles
    errors=kwds.get("encoding_errors", "strict"),
  File "/home/airflow/.local/lib/python3.7/site-packages/pandas/io/common.py", line 707, in get_handle
    newline="",
FileNotFoundError: [Errno 2] No such file or directory: '/Users/80524/Downloads/apache_airflow/data/traffy_fondue_data.csv'
[2022-12-11T04:09:29.999+0000] {processor.py:768} WARNING - No viable dags retrieved from /opt/airflow/dags/data_tools_final_oprator.py
[2022-12-11T04:09:30.014+0000] {processor.py:176} INFO - Processing /opt/airflow/dags/data_tools_final_oprator.py took 2.008 seconds
[2022-12-11T04:10:00.301+0000] {processor.py:154} INFO - Started process (PID=25660) to work on /opt/airflow/dags/data_tools_final_oprator.py
[2022-12-11T04:10:00.302+0000] {processor.py:756} INFO - Processing file /opt/airflow/dags/data_tools_final_oprator.py for tasks to queue
[2022-12-11T04:10:00.304+0000] {logging_mixin.py:137} INFO - [2022-12-11T04:10:00.304+0000] {dagbag.py:537} INFO - Filling up the DagBag from /opt/airflow/dags/data_tools_final_oprator.py
[2022-12-11T04:10:02.268+0000] {logging_mixin.py:137} INFO - [2022-12-11T04:10:02.263+0000] {dagbag.py:342} ERROR - Failed to import: /opt/airflow/dags/data_tools_final_oprator.py
Traceback (most recent call last):
  File "/home/airflow/.local/lib/python3.7/site-packages/airflow/models/dagbag.py", line 338, in parse
    loader.exec_module(new_module)
  File "<frozen importlib._bootstrap_external>", line 728, in exec_module
  File "<frozen importlib._bootstrap>", line 219, in _call_with_frames_removed
  File "/opt/airflow/dags/data_tools_final_oprator.py", line 13, in <module>
    import datatool_model
  File "/opt/airflow/plugins/datatool_model.py", line 106, in <module>
    preprocess = traffy.import_data()
  File "/opt/airflow/plugins/datatool_model.py", line 24, in import_data
    df = pd.read_csv('/Users/80524/Downloads/apache_airflow/data/traffy_fondue_data.csv')
  File "/home/airflow/.local/lib/python3.7/site-packages/pandas/util/_decorators.py", line 311, in wrapper
    return func(*args, **kwargs)
  File "/home/airflow/.local/lib/python3.7/site-packages/pandas/io/parsers/readers.py", line 586, in read_csv
    return _read(filepath_or_buffer, kwds)
  File "/home/airflow/.local/lib/python3.7/site-packages/pandas/io/parsers/readers.py", line 482, in _read
    parser = TextFileReader(filepath_or_buffer, **kwds)
  File "/home/airflow/.local/lib/python3.7/site-packages/pandas/io/parsers/readers.py", line 811, in __init__
    self._engine = self._make_engine(self.engine)
  File "/home/airflow/.local/lib/python3.7/site-packages/pandas/io/parsers/readers.py", line 1040, in _make_engine
    return mapping[engine](self.f, **self.options)  # type: ignore[call-arg]
  File "/home/airflow/.local/lib/python3.7/site-packages/pandas/io/parsers/c_parser_wrapper.py", line 51, in __init__
    self._open_handles(src, kwds)
  File "/home/airflow/.local/lib/python3.7/site-packages/pandas/io/parsers/base_parser.py", line 229, in _open_handles
    errors=kwds.get("encoding_errors", "strict"),
  File "/home/airflow/.local/lib/python3.7/site-packages/pandas/io/common.py", line 707, in get_handle
    newline="",
FileNotFoundError: [Errno 2] No such file or directory: '/Users/80524/Downloads/apache_airflow/data/traffy_fondue_data.csv'
[2022-12-11T04:10:02.270+0000] {processor.py:768} WARNING - No viable dags retrieved from /opt/airflow/dags/data_tools_final_oprator.py
[2022-12-11T04:10:02.283+0000] {processor.py:176} INFO - Processing /opt/airflow/dags/data_tools_final_oprator.py took 1.984 seconds
[2022-12-11T04:10:32.627+0000] {processor.py:154} INFO - Started process (PID=25688) to work on /opt/airflow/dags/data_tools_final_oprator.py
[2022-12-11T04:10:32.630+0000] {processor.py:756} INFO - Processing file /opt/airflow/dags/data_tools_final_oprator.py for tasks to queue
[2022-12-11T04:10:32.632+0000] {logging_mixin.py:137} INFO - [2022-12-11T04:10:32.632+0000] {dagbag.py:537} INFO - Filling up the DagBag from /opt/airflow/dags/data_tools_final_oprator.py
[2022-12-11T04:10:34.663+0000] {logging_mixin.py:137} INFO - [2022-12-11T04:10:34.659+0000] {dagbag.py:342} ERROR - Failed to import: /opt/airflow/dags/data_tools_final_oprator.py
Traceback (most recent call last):
  File "/home/airflow/.local/lib/python3.7/site-packages/airflow/models/dagbag.py", line 338, in parse
    loader.exec_module(new_module)
  File "<frozen importlib._bootstrap_external>", line 728, in exec_module
  File "<frozen importlib._bootstrap>", line 219, in _call_with_frames_removed
  File "/opt/airflow/dags/data_tools_final_oprator.py", line 13, in <module>
    import datatool_model
  File "/opt/airflow/plugins/datatool_model.py", line 106, in <module>
    preprocess = traffy.import_data()
  File "/opt/airflow/plugins/datatool_model.py", line 24, in import_data
    df = pd.read_csv('/Users/80524/Downloads/apache_airflow/data/traffy_fondue_data.csv')
  File "/home/airflow/.local/lib/python3.7/site-packages/pandas/util/_decorators.py", line 311, in wrapper
    return func(*args, **kwargs)
  File "/home/airflow/.local/lib/python3.7/site-packages/pandas/io/parsers/readers.py", line 586, in read_csv
    return _read(filepath_or_buffer, kwds)
  File "/home/airflow/.local/lib/python3.7/site-packages/pandas/io/parsers/readers.py", line 482, in _read
    parser = TextFileReader(filepath_or_buffer, **kwds)
  File "/home/airflow/.local/lib/python3.7/site-packages/pandas/io/parsers/readers.py", line 811, in __init__
    self._engine = self._make_engine(self.engine)
  File "/home/airflow/.local/lib/python3.7/site-packages/pandas/io/parsers/readers.py", line 1040, in _make_engine
    return mapping[engine](self.f, **self.options)  # type: ignore[call-arg]
  File "/home/airflow/.local/lib/python3.7/site-packages/pandas/io/parsers/c_parser_wrapper.py", line 51, in __init__
    self._open_handles(src, kwds)
  File "/home/airflow/.local/lib/python3.7/site-packages/pandas/io/parsers/base_parser.py", line 229, in _open_handles
    errors=kwds.get("encoding_errors", "strict"),
  File "/home/airflow/.local/lib/python3.7/site-packages/pandas/io/common.py", line 707, in get_handle
    newline="",
FileNotFoundError: [Errno 2] No such file or directory: '/Users/80524/Downloads/apache_airflow/data/traffy_fondue_data.csv'
[2022-12-11T04:10:34.665+0000] {processor.py:768} WARNING - No viable dags retrieved from /opt/airflow/dags/data_tools_final_oprator.py
[2022-12-11T04:10:34.678+0000] {processor.py:176} INFO - Processing /opt/airflow/dags/data_tools_final_oprator.py took 2.056 seconds
[2022-12-11T04:11:04.920+0000] {processor.py:154} INFO - Started process (PID=25716) to work on /opt/airflow/dags/data_tools_final_oprator.py
[2022-12-11T04:11:04.923+0000] {processor.py:756} INFO - Processing file /opt/airflow/dags/data_tools_final_oprator.py for tasks to queue
[2022-12-11T04:11:04.924+0000] {logging_mixin.py:137} INFO - [2022-12-11T04:11:04.924+0000] {dagbag.py:537} INFO - Filling up the DagBag from /opt/airflow/dags/data_tools_final_oprator.py
[2022-12-11T04:11:06.827+0000] {logging_mixin.py:137} INFO - [2022-12-11T04:11:06.824+0000] {dagbag.py:342} ERROR - Failed to import: /opt/airflow/dags/data_tools_final_oprator.py
Traceback (most recent call last):
  File "/home/airflow/.local/lib/python3.7/site-packages/airflow/models/dagbag.py", line 338, in parse
    loader.exec_module(new_module)
  File "<frozen importlib._bootstrap_external>", line 728, in exec_module
  File "<frozen importlib._bootstrap>", line 219, in _call_with_frames_removed
  File "/opt/airflow/dags/data_tools_final_oprator.py", line 13, in <module>
    import datatool_model
  File "/opt/airflow/plugins/datatool_model.py", line 106, in <module>
    preprocess = traffy.import_data()
  File "/opt/airflow/plugins/datatool_model.py", line 24, in import_data
    df = pd.read_csv('/Users/80524/Downloads/apache_airflow/data/traffy_fondue_data.csv')
  File "/home/airflow/.local/lib/python3.7/site-packages/pandas/util/_decorators.py", line 311, in wrapper
    return func(*args, **kwargs)
  File "/home/airflow/.local/lib/python3.7/site-packages/pandas/io/parsers/readers.py", line 586, in read_csv
    return _read(filepath_or_buffer, kwds)
  File "/home/airflow/.local/lib/python3.7/site-packages/pandas/io/parsers/readers.py", line 482, in _read
    parser = TextFileReader(filepath_or_buffer, **kwds)
  File "/home/airflow/.local/lib/python3.7/site-packages/pandas/io/parsers/readers.py", line 811, in __init__
    self._engine = self._make_engine(self.engine)
  File "/home/airflow/.local/lib/python3.7/site-packages/pandas/io/parsers/readers.py", line 1040, in _make_engine
    return mapping[engine](self.f, **self.options)  # type: ignore[call-arg]
  File "/home/airflow/.local/lib/python3.7/site-packages/pandas/io/parsers/c_parser_wrapper.py", line 51, in __init__
    self._open_handles(src, kwds)
  File "/home/airflow/.local/lib/python3.7/site-packages/pandas/io/parsers/base_parser.py", line 229, in _open_handles
    errors=kwds.get("encoding_errors", "strict"),
  File "/home/airflow/.local/lib/python3.7/site-packages/pandas/io/common.py", line 707, in get_handle
    newline="",
FileNotFoundError: [Errno 2] No such file or directory: '/Users/80524/Downloads/apache_airflow/data/traffy_fondue_data.csv'
[2022-12-11T04:11:06.829+0000] {processor.py:768} WARNING - No viable dags retrieved from /opt/airflow/dags/data_tools_final_oprator.py
[2022-12-11T04:11:06.840+0000] {processor.py:176} INFO - Processing /opt/airflow/dags/data_tools_final_oprator.py took 1.924 seconds
[2022-12-11T04:11:37.251+0000] {processor.py:154} INFO - Started process (PID=25745) to work on /opt/airflow/dags/data_tools_final_oprator.py
[2022-12-11T04:11:37.253+0000] {processor.py:756} INFO - Processing file /opt/airflow/dags/data_tools_final_oprator.py for tasks to queue
[2022-12-11T04:11:37.255+0000] {logging_mixin.py:137} INFO - [2022-12-11T04:11:37.255+0000] {dagbag.py:537} INFO - Filling up the DagBag from /opt/airflow/dags/data_tools_final_oprator.py
[2022-12-11T04:11:39.115+0000] {logging_mixin.py:137} INFO - [2022-12-11T04:11:39.110+0000] {dagbag.py:342} ERROR - Failed to import: /opt/airflow/dags/data_tools_final_oprator.py
Traceback (most recent call last):
  File "/home/airflow/.local/lib/python3.7/site-packages/airflow/models/dagbag.py", line 338, in parse
    loader.exec_module(new_module)
  File "<frozen importlib._bootstrap_external>", line 728, in exec_module
  File "<frozen importlib._bootstrap>", line 219, in _call_with_frames_removed
  File "/opt/airflow/dags/data_tools_final_oprator.py", line 13, in <module>
    import datatool_model
  File "/opt/airflow/plugins/datatool_model.py", line 106, in <module>
    preprocess = traffy.import_data()
  File "/opt/airflow/plugins/datatool_model.py", line 24, in import_data
    df = pd.read_csv('/Users/80524/Downloads/apache_airflow/data/traffy_fondue_data.csv')
  File "/home/airflow/.local/lib/python3.7/site-packages/pandas/util/_decorators.py", line 311, in wrapper
    return func(*args, **kwargs)
  File "/home/airflow/.local/lib/python3.7/site-packages/pandas/io/parsers/readers.py", line 586, in read_csv
    return _read(filepath_or_buffer, kwds)
  File "/home/airflow/.local/lib/python3.7/site-packages/pandas/io/parsers/readers.py", line 482, in _read
    parser = TextFileReader(filepath_or_buffer, **kwds)
  File "/home/airflow/.local/lib/python3.7/site-packages/pandas/io/parsers/readers.py", line 811, in __init__
    self._engine = self._make_engine(self.engine)
  File "/home/airflow/.local/lib/python3.7/site-packages/pandas/io/parsers/readers.py", line 1040, in _make_engine
    return mapping[engine](self.f, **self.options)  # type: ignore[call-arg]
  File "/home/airflow/.local/lib/python3.7/site-packages/pandas/io/parsers/c_parser_wrapper.py", line 51, in __init__
    self._open_handles(src, kwds)
  File "/home/airflow/.local/lib/python3.7/site-packages/pandas/io/parsers/base_parser.py", line 229, in _open_handles
    errors=kwds.get("encoding_errors", "strict"),
  File "/home/airflow/.local/lib/python3.7/site-packages/pandas/io/common.py", line 707, in get_handle
    newline="",
FileNotFoundError: [Errno 2] No such file or directory: '/Users/80524/Downloads/apache_airflow/data/traffy_fondue_data.csv'
[2022-12-11T04:11:39.116+0000] {processor.py:768} WARNING - No viable dags retrieved from /opt/airflow/dags/data_tools_final_oprator.py
[2022-12-11T04:11:39.127+0000] {processor.py:176} INFO - Processing /opt/airflow/dags/data_tools_final_oprator.py took 1.879 seconds
[2022-12-11T04:12:09.527+0000] {processor.py:154} INFO - Started process (PID=25774) to work on /opt/airflow/dags/data_tools_final_oprator.py
[2022-12-11T04:12:09.529+0000] {processor.py:756} INFO - Processing file /opt/airflow/dags/data_tools_final_oprator.py for tasks to queue
[2022-12-11T04:12:09.531+0000] {logging_mixin.py:137} INFO - [2022-12-11T04:12:09.531+0000] {dagbag.py:537} INFO - Filling up the DagBag from /opt/airflow/dags/data_tools_final_oprator.py
[2022-12-11T04:12:11.395+0000] {logging_mixin.py:137} INFO - [2022-12-11T04:12:11.390+0000] {dagbag.py:342} ERROR - Failed to import: /opt/airflow/dags/data_tools_final_oprator.py
Traceback (most recent call last):
  File "/home/airflow/.local/lib/python3.7/site-packages/airflow/models/dagbag.py", line 338, in parse
    loader.exec_module(new_module)
  File "<frozen importlib._bootstrap_external>", line 728, in exec_module
  File "<frozen importlib._bootstrap>", line 219, in _call_with_frames_removed
  File "/opt/airflow/dags/data_tools_final_oprator.py", line 13, in <module>
    import datatool_model
  File "/opt/airflow/plugins/datatool_model.py", line 106, in <module>
    preprocess = traffy.import_data()
  File "/opt/airflow/plugins/datatool_model.py", line 24, in import_data
    df = pd.read_csv('/Users/80524/Downloads/apache_airflow/data/traffy_fondue_data.csv')
  File "/home/airflow/.local/lib/python3.7/site-packages/pandas/util/_decorators.py", line 311, in wrapper
    return func(*args, **kwargs)
  File "/home/airflow/.local/lib/python3.7/site-packages/pandas/io/parsers/readers.py", line 586, in read_csv
    return _read(filepath_or_buffer, kwds)
  File "/home/airflow/.local/lib/python3.7/site-packages/pandas/io/parsers/readers.py", line 482, in _read
    parser = TextFileReader(filepath_or_buffer, **kwds)
  File "/home/airflow/.local/lib/python3.7/site-packages/pandas/io/parsers/readers.py", line 811, in __init__
    self._engine = self._make_engine(self.engine)
  File "/home/airflow/.local/lib/python3.7/site-packages/pandas/io/parsers/readers.py", line 1040, in _make_engine
    return mapping[engine](self.f, **self.options)  # type: ignore[call-arg]
  File "/home/airflow/.local/lib/python3.7/site-packages/pandas/io/parsers/c_parser_wrapper.py", line 51, in __init__
    self._open_handles(src, kwds)
  File "/home/airflow/.local/lib/python3.7/site-packages/pandas/io/parsers/base_parser.py", line 229, in _open_handles
    errors=kwds.get("encoding_errors", "strict"),
  File "/home/airflow/.local/lib/python3.7/site-packages/pandas/io/common.py", line 707, in get_handle
    newline="",
FileNotFoundError: [Errno 2] No such file or directory: '/Users/80524/Downloads/apache_airflow/data/traffy_fondue_data.csv'
[2022-12-11T04:12:11.397+0000] {processor.py:768} WARNING - No viable dags retrieved from /opt/airflow/dags/data_tools_final_oprator.py
[2022-12-11T04:12:11.410+0000] {processor.py:176} INFO - Processing /opt/airflow/dags/data_tools_final_oprator.py took 1.886 seconds
[2022-12-11T04:12:41.884+0000] {processor.py:154} INFO - Started process (PID=25804) to work on /opt/airflow/dags/data_tools_final_oprator.py
[2022-12-11T04:12:41.887+0000] {processor.py:756} INFO - Processing file /opt/airflow/dags/data_tools_final_oprator.py for tasks to queue
[2022-12-11T04:12:41.889+0000] {logging_mixin.py:137} INFO - [2022-12-11T04:12:41.889+0000] {dagbag.py:537} INFO - Filling up the DagBag from /opt/airflow/dags/data_tools_final_oprator.py
[2022-12-11T04:12:43.760+0000] {logging_mixin.py:137} INFO - [2022-12-11T04:12:43.757+0000] {dagbag.py:342} ERROR - Failed to import: /opt/airflow/dags/data_tools_final_oprator.py
Traceback (most recent call last):
  File "/home/airflow/.local/lib/python3.7/site-packages/airflow/models/dagbag.py", line 338, in parse
    loader.exec_module(new_module)
  File "<frozen importlib._bootstrap_external>", line 728, in exec_module
  File "<frozen importlib._bootstrap>", line 219, in _call_with_frames_removed
  File "/opt/airflow/dags/data_tools_final_oprator.py", line 13, in <module>
    import datatool_model
  File "/opt/airflow/plugins/datatool_model.py", line 106, in <module>
    preprocess = traffy.import_data()
  File "/opt/airflow/plugins/datatool_model.py", line 24, in import_data
    df = pd.read_csv('/Users/80524/Downloads/apache_airflow/data/traffy_fondue_data.csv')
  File "/home/airflow/.local/lib/python3.7/site-packages/pandas/util/_decorators.py", line 311, in wrapper
    return func(*args, **kwargs)
  File "/home/airflow/.local/lib/python3.7/site-packages/pandas/io/parsers/readers.py", line 586, in read_csv
    return _read(filepath_or_buffer, kwds)
  File "/home/airflow/.local/lib/python3.7/site-packages/pandas/io/parsers/readers.py", line 482, in _read
    parser = TextFileReader(filepath_or_buffer, **kwds)
  File "/home/airflow/.local/lib/python3.7/site-packages/pandas/io/parsers/readers.py", line 811, in __init__
    self._engine = self._make_engine(self.engine)
  File "/home/airflow/.local/lib/python3.7/site-packages/pandas/io/parsers/readers.py", line 1040, in _make_engine
    return mapping[engine](self.f, **self.options)  # type: ignore[call-arg]
  File "/home/airflow/.local/lib/python3.7/site-packages/pandas/io/parsers/c_parser_wrapper.py", line 51, in __init__
    self._open_handles(src, kwds)
  File "/home/airflow/.local/lib/python3.7/site-packages/pandas/io/parsers/base_parser.py", line 229, in _open_handles
    errors=kwds.get("encoding_errors", "strict"),
  File "/home/airflow/.local/lib/python3.7/site-packages/pandas/io/common.py", line 707, in get_handle
    newline="",
FileNotFoundError: [Errno 2] No such file or directory: '/Users/80524/Downloads/apache_airflow/data/traffy_fondue_data.csv'
[2022-12-11T04:12:43.763+0000] {processor.py:768} WARNING - No viable dags retrieved from /opt/airflow/dags/data_tools_final_oprator.py
[2022-12-11T04:12:43.774+0000] {processor.py:176} INFO - Processing /opt/airflow/dags/data_tools_final_oprator.py took 1.892 seconds
[2022-12-11T04:13:14.224+0000] {processor.py:154} INFO - Started process (PID=25835) to work on /opt/airflow/dags/data_tools_final_oprator.py
[2022-12-11T04:13:14.227+0000] {processor.py:756} INFO - Processing file /opt/airflow/dags/data_tools_final_oprator.py for tasks to queue
[2022-12-11T04:13:14.228+0000] {logging_mixin.py:137} INFO - [2022-12-11T04:13:14.228+0000] {dagbag.py:537} INFO - Filling up the DagBag from /opt/airflow/dags/data_tools_final_oprator.py
[2022-12-11T04:13:16.074+0000] {logging_mixin.py:137} INFO - [2022-12-11T04:13:16.070+0000] {dagbag.py:342} ERROR - Failed to import: /opt/airflow/dags/data_tools_final_oprator.py
Traceback (most recent call last):
  File "/home/airflow/.local/lib/python3.7/site-packages/airflow/models/dagbag.py", line 338, in parse
    loader.exec_module(new_module)
  File "<frozen importlib._bootstrap_external>", line 728, in exec_module
  File "<frozen importlib._bootstrap>", line 219, in _call_with_frames_removed
  File "/opt/airflow/dags/data_tools_final_oprator.py", line 13, in <module>
    import datatool_model
  File "/opt/airflow/plugins/datatool_model.py", line 106, in <module>
    preprocess = traffy.import_data()
  File "/opt/airflow/plugins/datatool_model.py", line 24, in import_data
    df = pd.read_csv('/Users/80524/Downloads/apache_airflow/data/traffy_fondue_data.csv')
  File "/home/airflow/.local/lib/python3.7/site-packages/pandas/util/_decorators.py", line 311, in wrapper
    return func(*args, **kwargs)
  File "/home/airflow/.local/lib/python3.7/site-packages/pandas/io/parsers/readers.py", line 586, in read_csv
    return _read(filepath_or_buffer, kwds)
  File "/home/airflow/.local/lib/python3.7/site-packages/pandas/io/parsers/readers.py", line 482, in _read
    parser = TextFileReader(filepath_or_buffer, **kwds)
  File "/home/airflow/.local/lib/python3.7/site-packages/pandas/io/parsers/readers.py", line 811, in __init__
    self._engine = self._make_engine(self.engine)
  File "/home/airflow/.local/lib/python3.7/site-packages/pandas/io/parsers/readers.py", line 1040, in _make_engine
    return mapping[engine](self.f, **self.options)  # type: ignore[call-arg]
  File "/home/airflow/.local/lib/python3.7/site-packages/pandas/io/parsers/c_parser_wrapper.py", line 51, in __init__
    self._open_handles(src, kwds)
  File "/home/airflow/.local/lib/python3.7/site-packages/pandas/io/parsers/base_parser.py", line 229, in _open_handles
    errors=kwds.get("encoding_errors", "strict"),
  File "/home/airflow/.local/lib/python3.7/site-packages/pandas/io/common.py", line 707, in get_handle
    newline="",
FileNotFoundError: [Errno 2] No such file or directory: '/Users/80524/Downloads/apache_airflow/data/traffy_fondue_data.csv'
[2022-12-11T04:13:16.075+0000] {processor.py:768} WARNING - No viable dags retrieved from /opt/airflow/dags/data_tools_final_oprator.py
[2022-12-11T04:13:16.087+0000] {processor.py:176} INFO - Processing /opt/airflow/dags/data_tools_final_oprator.py took 1.866 seconds
[2022-12-11T04:13:46.544+0000] {processor.py:154} INFO - Started process (PID=25864) to work on /opt/airflow/dags/data_tools_final_oprator.py
[2022-12-11T04:13:46.547+0000] {processor.py:756} INFO - Processing file /opt/airflow/dags/data_tools_final_oprator.py for tasks to queue
[2022-12-11T04:13:46.549+0000] {logging_mixin.py:137} INFO - [2022-12-11T04:13:46.548+0000] {dagbag.py:537} INFO - Filling up the DagBag from /opt/airflow/dags/data_tools_final_oprator.py
[2022-12-11T04:13:48.435+0000] {logging_mixin.py:137} INFO - [2022-12-11T04:13:48.430+0000] {dagbag.py:342} ERROR - Failed to import: /opt/airflow/dags/data_tools_final_oprator.py
Traceback (most recent call last):
  File "/home/airflow/.local/lib/python3.7/site-packages/airflow/models/dagbag.py", line 338, in parse
    loader.exec_module(new_module)
  File "<frozen importlib._bootstrap_external>", line 728, in exec_module
  File "<frozen importlib._bootstrap>", line 219, in _call_with_frames_removed
  File "/opt/airflow/dags/data_tools_final_oprator.py", line 13, in <module>
    import datatool_model
  File "/opt/airflow/plugins/datatool_model.py", line 106, in <module>
    preprocess = traffy.import_data()
  File "/opt/airflow/plugins/datatool_model.py", line 24, in import_data
    df = pd.read_csv('/Users/80524/Downloads/apache_airflow/data/traffy_fondue_data.csv')
  File "/home/airflow/.local/lib/python3.7/site-packages/pandas/util/_decorators.py", line 311, in wrapper
    return func(*args, **kwargs)
  File "/home/airflow/.local/lib/python3.7/site-packages/pandas/io/parsers/readers.py", line 586, in read_csv
    return _read(filepath_or_buffer, kwds)
  File "/home/airflow/.local/lib/python3.7/site-packages/pandas/io/parsers/readers.py", line 482, in _read
    parser = TextFileReader(filepath_or_buffer, **kwds)
  File "/home/airflow/.local/lib/python3.7/site-packages/pandas/io/parsers/readers.py", line 811, in __init__
    self._engine = self._make_engine(self.engine)
  File "/home/airflow/.local/lib/python3.7/site-packages/pandas/io/parsers/readers.py", line 1040, in _make_engine
    return mapping[engine](self.f, **self.options)  # type: ignore[call-arg]
  File "/home/airflow/.local/lib/python3.7/site-packages/pandas/io/parsers/c_parser_wrapper.py", line 51, in __init__
    self._open_handles(src, kwds)
  File "/home/airflow/.local/lib/python3.7/site-packages/pandas/io/parsers/base_parser.py", line 229, in _open_handles
    errors=kwds.get("encoding_errors", "strict"),
  File "/home/airflow/.local/lib/python3.7/site-packages/pandas/io/common.py", line 707, in get_handle
    newline="",
FileNotFoundError: [Errno 2] No such file or directory: '/Users/80524/Downloads/apache_airflow/data/traffy_fondue_data.csv'
[2022-12-11T04:13:48.437+0000] {processor.py:768} WARNING - No viable dags retrieved from /opt/airflow/dags/data_tools_final_oprator.py
[2022-12-11T04:13:48.447+0000] {processor.py:176} INFO - Processing /opt/airflow/dags/data_tools_final_oprator.py took 1.907 seconds
[2022-12-11T04:14:18.861+0000] {processor.py:154} INFO - Started process (PID=25893) to work on /opt/airflow/dags/data_tools_final_oprator.py
[2022-12-11T04:14:18.863+0000] {processor.py:756} INFO - Processing file /opt/airflow/dags/data_tools_final_oprator.py for tasks to queue
[2022-12-11T04:14:18.865+0000] {logging_mixin.py:137} INFO - [2022-12-11T04:14:18.865+0000] {dagbag.py:537} INFO - Filling up the DagBag from /opt/airflow/dags/data_tools_final_oprator.py
[2022-12-11T04:14:20.728+0000] {logging_mixin.py:137} INFO - [2022-12-11T04:14:20.724+0000] {dagbag.py:342} ERROR - Failed to import: /opt/airflow/dags/data_tools_final_oprator.py
Traceback (most recent call last):
  File "/home/airflow/.local/lib/python3.7/site-packages/airflow/models/dagbag.py", line 338, in parse
    loader.exec_module(new_module)
  File "<frozen importlib._bootstrap_external>", line 728, in exec_module
  File "<frozen importlib._bootstrap>", line 219, in _call_with_frames_removed
  File "/opt/airflow/dags/data_tools_final_oprator.py", line 13, in <module>
    import datatool_model
  File "/opt/airflow/plugins/datatool_model.py", line 106, in <module>
    preprocess = traffy.import_data()
  File "/opt/airflow/plugins/datatool_model.py", line 24, in import_data
    df = pd.read_csv('/Users/80524/Downloads/apache_airflow/data/traffy_fondue_data.csv')
  File "/home/airflow/.local/lib/python3.7/site-packages/pandas/util/_decorators.py", line 311, in wrapper
    return func(*args, **kwargs)
  File "/home/airflow/.local/lib/python3.7/site-packages/pandas/io/parsers/readers.py", line 586, in read_csv
    return _read(filepath_or_buffer, kwds)
  File "/home/airflow/.local/lib/python3.7/site-packages/pandas/io/parsers/readers.py", line 482, in _read
    parser = TextFileReader(filepath_or_buffer, **kwds)
  File "/home/airflow/.local/lib/python3.7/site-packages/pandas/io/parsers/readers.py", line 811, in __init__
    self._engine = self._make_engine(self.engine)
  File "/home/airflow/.local/lib/python3.7/site-packages/pandas/io/parsers/readers.py", line 1040, in _make_engine
    return mapping[engine](self.f, **self.options)  # type: ignore[call-arg]
  File "/home/airflow/.local/lib/python3.7/site-packages/pandas/io/parsers/c_parser_wrapper.py", line 51, in __init__
    self._open_handles(src, kwds)
  File "/home/airflow/.local/lib/python3.7/site-packages/pandas/io/parsers/base_parser.py", line 229, in _open_handles
    errors=kwds.get("encoding_errors", "strict"),
  File "/home/airflow/.local/lib/python3.7/site-packages/pandas/io/common.py", line 707, in get_handle
    newline="",
FileNotFoundError: [Errno 2] No such file or directory: '/Users/80524/Downloads/apache_airflow/data/traffy_fondue_data.csv'
[2022-12-11T04:14:20.730+0000] {processor.py:768} WARNING - No viable dags retrieved from /opt/airflow/dags/data_tools_final_oprator.py
[2022-12-11T04:14:20.742+0000] {processor.py:176} INFO - Processing /opt/airflow/dags/data_tools_final_oprator.py took 1.886 seconds
[2022-12-11T04:14:51.088+0000] {processor.py:154} INFO - Started process (PID=25921) to work on /opt/airflow/dags/data_tools_final_oprator.py
[2022-12-11T04:14:51.090+0000] {processor.py:756} INFO - Processing file /opt/airflow/dags/data_tools_final_oprator.py for tasks to queue
[2022-12-11T04:14:51.092+0000] {logging_mixin.py:137} INFO - [2022-12-11T04:14:51.092+0000] {dagbag.py:537} INFO - Filling up the DagBag from /opt/airflow/dags/data_tools_final_oprator.py
[2022-12-11T04:14:53.152+0000] {logging_mixin.py:137} INFO - [2022-12-11T04:14:53.147+0000] {dagbag.py:342} ERROR - Failed to import: /opt/airflow/dags/data_tools_final_oprator.py
Traceback (most recent call last):
  File "/home/airflow/.local/lib/python3.7/site-packages/airflow/models/dagbag.py", line 338, in parse
    loader.exec_module(new_module)
  File "<frozen importlib._bootstrap_external>", line 728, in exec_module
  File "<frozen importlib._bootstrap>", line 219, in _call_with_frames_removed
  File "/opt/airflow/dags/data_tools_final_oprator.py", line 13, in <module>
    import datatool_model
  File "/opt/airflow/plugins/datatool_model.py", line 106, in <module>
    preprocess = traffy.import_data()
  File "/opt/airflow/plugins/datatool_model.py", line 24, in import_data
    df = pd.read_csv('/Users/80524/Downloads/apache_airflow/data/traffy_fondue_data.csv')
  File "/home/airflow/.local/lib/python3.7/site-packages/pandas/util/_decorators.py", line 311, in wrapper
    return func(*args, **kwargs)
  File "/home/airflow/.local/lib/python3.7/site-packages/pandas/io/parsers/readers.py", line 586, in read_csv
    return _read(filepath_or_buffer, kwds)
  File "/home/airflow/.local/lib/python3.7/site-packages/pandas/io/parsers/readers.py", line 482, in _read
    parser = TextFileReader(filepath_or_buffer, **kwds)
  File "/home/airflow/.local/lib/python3.7/site-packages/pandas/io/parsers/readers.py", line 811, in __init__
    self._engine = self._make_engine(self.engine)
  File "/home/airflow/.local/lib/python3.7/site-packages/pandas/io/parsers/readers.py", line 1040, in _make_engine
    return mapping[engine](self.f, **self.options)  # type: ignore[call-arg]
  File "/home/airflow/.local/lib/python3.7/site-packages/pandas/io/parsers/c_parser_wrapper.py", line 51, in __init__
    self._open_handles(src, kwds)
  File "/home/airflow/.local/lib/python3.7/site-packages/pandas/io/parsers/base_parser.py", line 229, in _open_handles
    errors=kwds.get("encoding_errors", "strict"),
  File "/home/airflow/.local/lib/python3.7/site-packages/pandas/io/common.py", line 707, in get_handle
    newline="",
FileNotFoundError: [Errno 2] No such file or directory: '/Users/80524/Downloads/apache_airflow/data/traffy_fondue_data.csv'
[2022-12-11T04:14:53.153+0000] {processor.py:768} WARNING - No viable dags retrieved from /opt/airflow/dags/data_tools_final_oprator.py
[2022-12-11T04:14:53.167+0000] {processor.py:176} INFO - Processing /opt/airflow/dags/data_tools_final_oprator.py took 2.081 seconds
[2022-12-11T04:15:23.403+0000] {processor.py:154} INFO - Started process (PID=25950) to work on /opt/airflow/dags/data_tools_final_oprator.py
[2022-12-11T04:15:23.405+0000] {processor.py:756} INFO - Processing file /opt/airflow/dags/data_tools_final_oprator.py for tasks to queue
[2022-12-11T04:15:23.407+0000] {logging_mixin.py:137} INFO - [2022-12-11T04:15:23.407+0000] {dagbag.py:537} INFO - Filling up the DagBag from /opt/airflow/dags/data_tools_final_oprator.py
[2022-12-11T04:15:25.447+0000] {logging_mixin.py:137} INFO - [2022-12-11T04:15:25.442+0000] {dagbag.py:342} ERROR - Failed to import: /opt/airflow/dags/data_tools_final_oprator.py
Traceback (most recent call last):
  File "/home/airflow/.local/lib/python3.7/site-packages/airflow/models/dagbag.py", line 338, in parse
    loader.exec_module(new_module)
  File "<frozen importlib._bootstrap_external>", line 728, in exec_module
  File "<frozen importlib._bootstrap>", line 219, in _call_with_frames_removed
  File "/opt/airflow/dags/data_tools_final_oprator.py", line 13, in <module>
    import datatool_model
  File "/opt/airflow/plugins/datatool_model.py", line 106, in <module>
    preprocess = traffy.import_data()
  File "/opt/airflow/plugins/datatool_model.py", line 24, in import_data
    df = pd.read_csv('/Users/80524/Downloads/apache_airflow/data/traffy_fondue_data.csv')
  File "/home/airflow/.local/lib/python3.7/site-packages/pandas/util/_decorators.py", line 311, in wrapper
    return func(*args, **kwargs)
  File "/home/airflow/.local/lib/python3.7/site-packages/pandas/io/parsers/readers.py", line 586, in read_csv
    return _read(filepath_or_buffer, kwds)
  File "/home/airflow/.local/lib/python3.7/site-packages/pandas/io/parsers/readers.py", line 482, in _read
    parser = TextFileReader(filepath_or_buffer, **kwds)
  File "/home/airflow/.local/lib/python3.7/site-packages/pandas/io/parsers/readers.py", line 811, in __init__
    self._engine = self._make_engine(self.engine)
  File "/home/airflow/.local/lib/python3.7/site-packages/pandas/io/parsers/readers.py", line 1040, in _make_engine
    return mapping[engine](self.f, **self.options)  # type: ignore[call-arg]
  File "/home/airflow/.local/lib/python3.7/site-packages/pandas/io/parsers/c_parser_wrapper.py", line 51, in __init__
    self._open_handles(src, kwds)
  File "/home/airflow/.local/lib/python3.7/site-packages/pandas/io/parsers/base_parser.py", line 229, in _open_handles
    errors=kwds.get("encoding_errors", "strict"),
  File "/home/airflow/.local/lib/python3.7/site-packages/pandas/io/common.py", line 707, in get_handle
    newline="",
FileNotFoundError: [Errno 2] No such file or directory: '/Users/80524/Downloads/apache_airflow/data/traffy_fondue_data.csv'
[2022-12-11T04:15:25.448+0000] {processor.py:768} WARNING - No viable dags retrieved from /opt/airflow/dags/data_tools_final_oprator.py
[2022-12-11T04:15:25.460+0000] {processor.py:176} INFO - Processing /opt/airflow/dags/data_tools_final_oprator.py took 2.060 seconds
[2022-12-11T04:15:55.868+0000] {processor.py:154} INFO - Started process (PID=25979) to work on /opt/airflow/dags/data_tools_final_oprator.py
[2022-12-11T04:15:55.871+0000] {processor.py:756} INFO - Processing file /opt/airflow/dags/data_tools_final_oprator.py for tasks to queue
[2022-12-11T04:15:55.872+0000] {logging_mixin.py:137} INFO - [2022-12-11T04:15:55.872+0000] {dagbag.py:537} INFO - Filling up the DagBag from /opt/airflow/dags/data_tools_final_oprator.py
[2022-12-11T04:15:57.814+0000] {logging_mixin.py:137} INFO - [2022-12-11T04:15:57.809+0000] {dagbag.py:342} ERROR - Failed to import: /opt/airflow/dags/data_tools_final_oprator.py
Traceback (most recent call last):
  File "/home/airflow/.local/lib/python3.7/site-packages/airflow/models/dagbag.py", line 338, in parse
    loader.exec_module(new_module)
  File "<frozen importlib._bootstrap_external>", line 728, in exec_module
  File "<frozen importlib._bootstrap>", line 219, in _call_with_frames_removed
  File "/opt/airflow/dags/data_tools_final_oprator.py", line 13, in <module>
    import datatool_model
  File "/opt/airflow/plugins/datatool_model.py", line 106, in <module>
    preprocess = traffy.import_data()
  File "/opt/airflow/plugins/datatool_model.py", line 24, in import_data
    df = pd.read_csv('/Users/80524/Downloads/apache_airflow/data/traffy_fondue_data.csv')
  File "/home/airflow/.local/lib/python3.7/site-packages/pandas/util/_decorators.py", line 311, in wrapper
    return func(*args, **kwargs)
  File "/home/airflow/.local/lib/python3.7/site-packages/pandas/io/parsers/readers.py", line 586, in read_csv
    return _read(filepath_or_buffer, kwds)
  File "/home/airflow/.local/lib/python3.7/site-packages/pandas/io/parsers/readers.py", line 482, in _read
    parser = TextFileReader(filepath_or_buffer, **kwds)
  File "/home/airflow/.local/lib/python3.7/site-packages/pandas/io/parsers/readers.py", line 811, in __init__
    self._engine = self._make_engine(self.engine)
  File "/home/airflow/.local/lib/python3.7/site-packages/pandas/io/parsers/readers.py", line 1040, in _make_engine
    return mapping[engine](self.f, **self.options)  # type: ignore[call-arg]
  File "/home/airflow/.local/lib/python3.7/site-packages/pandas/io/parsers/c_parser_wrapper.py", line 51, in __init__
    self._open_handles(src, kwds)
  File "/home/airflow/.local/lib/python3.7/site-packages/pandas/io/parsers/base_parser.py", line 229, in _open_handles
    errors=kwds.get("encoding_errors", "strict"),
  File "/home/airflow/.local/lib/python3.7/site-packages/pandas/io/common.py", line 707, in get_handle
    newline="",
FileNotFoundError: [Errno 2] No such file or directory: '/Users/80524/Downloads/apache_airflow/data/traffy_fondue_data.csv'
[2022-12-11T04:15:57.816+0000] {processor.py:768} WARNING - No viable dags retrieved from /opt/airflow/dags/data_tools_final_oprator.py
[2022-12-11T04:15:57.829+0000] {processor.py:176} INFO - Processing /opt/airflow/dags/data_tools_final_oprator.py took 1.965 seconds
[2022-12-11T04:16:28.251+0000] {processor.py:154} INFO - Started process (PID=26008) to work on /opt/airflow/dags/data_tools_final_oprator.py
[2022-12-11T04:16:28.253+0000] {processor.py:756} INFO - Processing file /opt/airflow/dags/data_tools_final_oprator.py for tasks to queue
[2022-12-11T04:16:28.255+0000] {logging_mixin.py:137} INFO - [2022-12-11T04:16:28.254+0000] {dagbag.py:537} INFO - Filling up the DagBag from /opt/airflow/dags/data_tools_final_oprator.py
[2022-12-11T04:16:30.127+0000] {logging_mixin.py:137} INFO - [2022-12-11T04:16:30.123+0000] {dagbag.py:342} ERROR - Failed to import: /opt/airflow/dags/data_tools_final_oprator.py
Traceback (most recent call last):
  File "/home/airflow/.local/lib/python3.7/site-packages/airflow/models/dagbag.py", line 338, in parse
    loader.exec_module(new_module)
  File "<frozen importlib._bootstrap_external>", line 728, in exec_module
  File "<frozen importlib._bootstrap>", line 219, in _call_with_frames_removed
  File "/opt/airflow/dags/data_tools_final_oprator.py", line 13, in <module>
    import datatool_model
  File "/opt/airflow/plugins/datatool_model.py", line 106, in <module>
    preprocess = traffy.import_data()
  File "/opt/airflow/plugins/datatool_model.py", line 24, in import_data
    df = pd.read_csv('/Users/80524/Downloads/apache_airflow/data/traffy_fondue_data.csv')
  File "/home/airflow/.local/lib/python3.7/site-packages/pandas/util/_decorators.py", line 311, in wrapper
    return func(*args, **kwargs)
  File "/home/airflow/.local/lib/python3.7/site-packages/pandas/io/parsers/readers.py", line 586, in read_csv
    return _read(filepath_or_buffer, kwds)
  File "/home/airflow/.local/lib/python3.7/site-packages/pandas/io/parsers/readers.py", line 482, in _read
    parser = TextFileReader(filepath_or_buffer, **kwds)
  File "/home/airflow/.local/lib/python3.7/site-packages/pandas/io/parsers/readers.py", line 811, in __init__
    self._engine = self._make_engine(self.engine)
  File "/home/airflow/.local/lib/python3.7/site-packages/pandas/io/parsers/readers.py", line 1040, in _make_engine
    return mapping[engine](self.f, **self.options)  # type: ignore[call-arg]
  File "/home/airflow/.local/lib/python3.7/site-packages/pandas/io/parsers/c_parser_wrapper.py", line 51, in __init__
    self._open_handles(src, kwds)
  File "/home/airflow/.local/lib/python3.7/site-packages/pandas/io/parsers/base_parser.py", line 229, in _open_handles
    errors=kwds.get("encoding_errors", "strict"),
  File "/home/airflow/.local/lib/python3.7/site-packages/pandas/io/common.py", line 707, in get_handle
    newline="",
FileNotFoundError: [Errno 2] No such file or directory: '/Users/80524/Downloads/apache_airflow/data/traffy_fondue_data.csv'
[2022-12-11T04:16:30.129+0000] {processor.py:768} WARNING - No viable dags retrieved from /opt/airflow/dags/data_tools_final_oprator.py
[2022-12-11T04:16:30.141+0000] {processor.py:176} INFO - Processing /opt/airflow/dags/data_tools_final_oprator.py took 1.893 seconds
[2022-12-11T04:17:00.553+0000] {processor.py:154} INFO - Started process (PID=26037) to work on /opt/airflow/dags/data_tools_final_oprator.py
[2022-12-11T04:17:00.555+0000] {processor.py:756} INFO - Processing file /opt/airflow/dags/data_tools_final_oprator.py for tasks to queue
[2022-12-11T04:17:00.557+0000] {logging_mixin.py:137} INFO - [2022-12-11T04:17:00.557+0000] {dagbag.py:537} INFO - Filling up the DagBag from /opt/airflow/dags/data_tools_final_oprator.py
[2022-12-11T04:17:02.536+0000] {logging_mixin.py:137} INFO - [2022-12-11T04:17:02.532+0000] {dagbag.py:342} ERROR - Failed to import: /opt/airflow/dags/data_tools_final_oprator.py
Traceback (most recent call last):
  File "/home/airflow/.local/lib/python3.7/site-packages/airflow/models/dagbag.py", line 338, in parse
    loader.exec_module(new_module)
  File "<frozen importlib._bootstrap_external>", line 728, in exec_module
  File "<frozen importlib._bootstrap>", line 219, in _call_with_frames_removed
  File "/opt/airflow/dags/data_tools_final_oprator.py", line 13, in <module>
    import datatool_model
  File "/opt/airflow/plugins/datatool_model.py", line 106, in <module>
    preprocess = traffy.import_data()
  File "/opt/airflow/plugins/datatool_model.py", line 24, in import_data
    df = pd.read_csv('/Users/80524/Downloads/apache_airflow/data/traffy_fondue_data.csv')
  File "/home/airflow/.local/lib/python3.7/site-packages/pandas/util/_decorators.py", line 311, in wrapper
    return func(*args, **kwargs)
  File "/home/airflow/.local/lib/python3.7/site-packages/pandas/io/parsers/readers.py", line 586, in read_csv
    return _read(filepath_or_buffer, kwds)
  File "/home/airflow/.local/lib/python3.7/site-packages/pandas/io/parsers/readers.py", line 482, in _read
    parser = TextFileReader(filepath_or_buffer, **kwds)
  File "/home/airflow/.local/lib/python3.7/site-packages/pandas/io/parsers/readers.py", line 811, in __init__
    self._engine = self._make_engine(self.engine)
  File "/home/airflow/.local/lib/python3.7/site-packages/pandas/io/parsers/readers.py", line 1040, in _make_engine
    return mapping[engine](self.f, **self.options)  # type: ignore[call-arg]
  File "/home/airflow/.local/lib/python3.7/site-packages/pandas/io/parsers/c_parser_wrapper.py", line 51, in __init__
    self._open_handles(src, kwds)
  File "/home/airflow/.local/lib/python3.7/site-packages/pandas/io/parsers/base_parser.py", line 229, in _open_handles
    errors=kwds.get("encoding_errors", "strict"),
  File "/home/airflow/.local/lib/python3.7/site-packages/pandas/io/common.py", line 707, in get_handle
    newline="",
FileNotFoundError: [Errno 2] No such file or directory: '/Users/80524/Downloads/apache_airflow/data/traffy_fondue_data.csv'
[2022-12-11T04:17:02.538+0000] {processor.py:768} WARNING - No viable dags retrieved from /opt/airflow/dags/data_tools_final_oprator.py
[2022-12-11T04:17:02.556+0000] {processor.py:176} INFO - Processing /opt/airflow/dags/data_tools_final_oprator.py took 2.007 seconds
[2022-12-11T04:17:32.916+0000] {processor.py:154} INFO - Started process (PID=26068) to work on /opt/airflow/dags/data_tools_final_oprator.py
[2022-12-11T04:17:32.919+0000] {processor.py:756} INFO - Processing file /opt/airflow/dags/data_tools_final_oprator.py for tasks to queue
[2022-12-11T04:17:32.921+0000] {logging_mixin.py:137} INFO - [2022-12-11T04:17:32.921+0000] {dagbag.py:537} INFO - Filling up the DagBag from /opt/airflow/dags/data_tools_final_oprator.py
[2022-12-11T04:17:34.884+0000] {logging_mixin.py:137} INFO - [2022-12-11T04:17:34.879+0000] {dagbag.py:342} ERROR - Failed to import: /opt/airflow/dags/data_tools_final_oprator.py
Traceback (most recent call last):
  File "/home/airflow/.local/lib/python3.7/site-packages/airflow/models/dagbag.py", line 338, in parse
    loader.exec_module(new_module)
  File "<frozen importlib._bootstrap_external>", line 728, in exec_module
  File "<frozen importlib._bootstrap>", line 219, in _call_with_frames_removed
  File "/opt/airflow/dags/data_tools_final_oprator.py", line 13, in <module>
    import datatool_model
  File "/opt/airflow/plugins/datatool_model.py", line 106, in <module>
    preprocess = traffy.import_data()
  File "/opt/airflow/plugins/datatool_model.py", line 24, in import_data
    df = pd.read_csv('/Users/80524/Downloads/apache_airflow/data/traffy_fondue_data.csv')
  File "/home/airflow/.local/lib/python3.7/site-packages/pandas/util/_decorators.py", line 311, in wrapper
    return func(*args, **kwargs)
  File "/home/airflow/.local/lib/python3.7/site-packages/pandas/io/parsers/readers.py", line 586, in read_csv
    return _read(filepath_or_buffer, kwds)
  File "/home/airflow/.local/lib/python3.7/site-packages/pandas/io/parsers/readers.py", line 482, in _read
    parser = TextFileReader(filepath_or_buffer, **kwds)
  File "/home/airflow/.local/lib/python3.7/site-packages/pandas/io/parsers/readers.py", line 811, in __init__
    self._engine = self._make_engine(self.engine)
  File "/home/airflow/.local/lib/python3.7/site-packages/pandas/io/parsers/readers.py", line 1040, in _make_engine
    return mapping[engine](self.f, **self.options)  # type: ignore[call-arg]
  File "/home/airflow/.local/lib/python3.7/site-packages/pandas/io/parsers/c_parser_wrapper.py", line 51, in __init__
    self._open_handles(src, kwds)
  File "/home/airflow/.local/lib/python3.7/site-packages/pandas/io/parsers/base_parser.py", line 229, in _open_handles
    errors=kwds.get("encoding_errors", "strict"),
  File "/home/airflow/.local/lib/python3.7/site-packages/pandas/io/common.py", line 707, in get_handle
    newline="",
FileNotFoundError: [Errno 2] No such file or directory: '/Users/80524/Downloads/apache_airflow/data/traffy_fondue_data.csv'
[2022-12-11T04:17:34.885+0000] {processor.py:768} WARNING - No viable dags retrieved from /opt/airflow/dags/data_tools_final_oprator.py
[2022-12-11T04:17:34.896+0000] {processor.py:176} INFO - Processing /opt/airflow/dags/data_tools_final_oprator.py took 1.985 seconds
[2022-12-11T04:18:05.227+0000] {processor.py:154} INFO - Started process (PID=26099) to work on /opt/airflow/dags/data_tools_final_oprator.py
[2022-12-11T04:18:05.230+0000] {processor.py:756} INFO - Processing file /opt/airflow/dags/data_tools_final_oprator.py for tasks to queue
[2022-12-11T04:18:05.232+0000] {logging_mixin.py:137} INFO - [2022-12-11T04:18:05.232+0000] {dagbag.py:537} INFO - Filling up the DagBag from /opt/airflow/dags/data_tools_final_oprator.py
[2022-12-11T04:18:07.051+0000] {logging_mixin.py:137} INFO - [2022-12-11T04:18:07.046+0000] {dagbag.py:342} ERROR - Failed to import: /opt/airflow/dags/data_tools_final_oprator.py
Traceback (most recent call last):
  File "/home/airflow/.local/lib/python3.7/site-packages/airflow/models/dagbag.py", line 338, in parse
    loader.exec_module(new_module)
  File "<frozen importlib._bootstrap_external>", line 728, in exec_module
  File "<frozen importlib._bootstrap>", line 219, in _call_with_frames_removed
  File "/opt/airflow/dags/data_tools_final_oprator.py", line 13, in <module>
    import datatool_model
  File "/opt/airflow/plugins/datatool_model.py", line 106, in <module>
    preprocess = traffy.import_data()
  File "/opt/airflow/plugins/datatool_model.py", line 24, in import_data
    df = pd.read_csv('/Users/80524/Downloads/apache_airflow/data/traffy_fondue_data.csv')
  File "/home/airflow/.local/lib/python3.7/site-packages/pandas/util/_decorators.py", line 311, in wrapper
    return func(*args, **kwargs)
  File "/home/airflow/.local/lib/python3.7/site-packages/pandas/io/parsers/readers.py", line 586, in read_csv
    return _read(filepath_or_buffer, kwds)
  File "/home/airflow/.local/lib/python3.7/site-packages/pandas/io/parsers/readers.py", line 482, in _read
    parser = TextFileReader(filepath_or_buffer, **kwds)
  File "/home/airflow/.local/lib/python3.7/site-packages/pandas/io/parsers/readers.py", line 811, in __init__
    self._engine = self._make_engine(self.engine)
  File "/home/airflow/.local/lib/python3.7/site-packages/pandas/io/parsers/readers.py", line 1040, in _make_engine
    return mapping[engine](self.f, **self.options)  # type: ignore[call-arg]
  File "/home/airflow/.local/lib/python3.7/site-packages/pandas/io/parsers/c_parser_wrapper.py", line 51, in __init__
    self._open_handles(src, kwds)
  File "/home/airflow/.local/lib/python3.7/site-packages/pandas/io/parsers/base_parser.py", line 229, in _open_handles
    errors=kwds.get("encoding_errors", "strict"),
  File "/home/airflow/.local/lib/python3.7/site-packages/pandas/io/common.py", line 707, in get_handle
    newline="",
FileNotFoundError: [Errno 2] No such file or directory: '/Users/80524/Downloads/apache_airflow/data/traffy_fondue_data.csv'
[2022-12-11T04:18:07.052+0000] {processor.py:768} WARNING - No viable dags retrieved from /opt/airflow/dags/data_tools_final_oprator.py
[2022-12-11T04:18:07.064+0000] {processor.py:176} INFO - Processing /opt/airflow/dags/data_tools_final_oprator.py took 1.841 seconds
[2022-12-11T04:18:37.439+0000] {processor.py:154} INFO - Started process (PID=26130) to work on /opt/airflow/dags/data_tools_final_oprator.py
[2022-12-11T04:18:37.442+0000] {processor.py:756} INFO - Processing file /opt/airflow/dags/data_tools_final_oprator.py for tasks to queue
[2022-12-11T04:18:37.444+0000] {logging_mixin.py:137} INFO - [2022-12-11T04:18:37.443+0000] {dagbag.py:537} INFO - Filling up the DagBag from /opt/airflow/dags/data_tools_final_oprator.py
[2022-12-11T04:18:39.262+0000] {logging_mixin.py:137} INFO - [2022-12-11T04:18:39.257+0000] {dagbag.py:342} ERROR - Failed to import: /opt/airflow/dags/data_tools_final_oprator.py
Traceback (most recent call last):
  File "/home/airflow/.local/lib/python3.7/site-packages/airflow/models/dagbag.py", line 338, in parse
    loader.exec_module(new_module)
  File "<frozen importlib._bootstrap_external>", line 728, in exec_module
  File "<frozen importlib._bootstrap>", line 219, in _call_with_frames_removed
  File "/opt/airflow/dags/data_tools_final_oprator.py", line 13, in <module>
    import datatool_model
  File "/opt/airflow/plugins/datatool_model.py", line 106, in <module>
    preprocess = traffy.import_data()
  File "/opt/airflow/plugins/datatool_model.py", line 24, in import_data
    df = pd.read_csv('/Users/80524/Downloads/apache_airflow/data/traffy_fondue_data.csv')
  File "/home/airflow/.local/lib/python3.7/site-packages/pandas/util/_decorators.py", line 311, in wrapper
    return func(*args, **kwargs)
  File "/home/airflow/.local/lib/python3.7/site-packages/pandas/io/parsers/readers.py", line 586, in read_csv
    return _read(filepath_or_buffer, kwds)
  File "/home/airflow/.local/lib/python3.7/site-packages/pandas/io/parsers/readers.py", line 482, in _read
    parser = TextFileReader(filepath_or_buffer, **kwds)
  File "/home/airflow/.local/lib/python3.7/site-packages/pandas/io/parsers/readers.py", line 811, in __init__
    self._engine = self._make_engine(self.engine)
  File "/home/airflow/.local/lib/python3.7/site-packages/pandas/io/parsers/readers.py", line 1040, in _make_engine
    return mapping[engine](self.f, **self.options)  # type: ignore[call-arg]
  File "/home/airflow/.local/lib/python3.7/site-packages/pandas/io/parsers/c_parser_wrapper.py", line 51, in __init__
    self._open_handles(src, kwds)
  File "/home/airflow/.local/lib/python3.7/site-packages/pandas/io/parsers/base_parser.py", line 229, in _open_handles
    errors=kwds.get("encoding_errors", "strict"),
  File "/home/airflow/.local/lib/python3.7/site-packages/pandas/io/common.py", line 707, in get_handle
    newline="",
FileNotFoundError: [Errno 2] No such file or directory: '/Users/80524/Downloads/apache_airflow/data/traffy_fondue_data.csv'
[2022-12-11T04:18:39.265+0000] {processor.py:768} WARNING - No viable dags retrieved from /opt/airflow/dags/data_tools_final_oprator.py
[2022-12-11T04:18:39.276+0000] {processor.py:176} INFO - Processing /opt/airflow/dags/data_tools_final_oprator.py took 1.840 seconds
[2022-12-11T04:19:09.641+0000] {processor.py:154} INFO - Started process (PID=26159) to work on /opt/airflow/dags/data_tools_final_oprator.py
[2022-12-11T04:19:09.643+0000] {processor.py:756} INFO - Processing file /opt/airflow/dags/data_tools_final_oprator.py for tasks to queue
[2022-12-11T04:19:09.644+0000] {logging_mixin.py:137} INFO - [2022-12-11T04:19:09.644+0000] {dagbag.py:537} INFO - Filling up the DagBag from /opt/airflow/dags/data_tools_final_oprator.py
[2022-12-11T04:19:11.458+0000] {logging_mixin.py:137} INFO - [2022-12-11T04:19:11.453+0000] {dagbag.py:342} ERROR - Failed to import: /opt/airflow/dags/data_tools_final_oprator.py
Traceback (most recent call last):
  File "/home/airflow/.local/lib/python3.7/site-packages/airflow/models/dagbag.py", line 338, in parse
    loader.exec_module(new_module)
  File "<frozen importlib._bootstrap_external>", line 728, in exec_module
  File "<frozen importlib._bootstrap>", line 219, in _call_with_frames_removed
  File "/opt/airflow/dags/data_tools_final_oprator.py", line 13, in <module>
    import datatool_model
  File "/opt/airflow/plugins/datatool_model.py", line 106, in <module>
    preprocess = traffy.import_data()
  File "/opt/airflow/plugins/datatool_model.py", line 24, in import_data
    df = pd.read_csv('/Users/80524/Downloads/apache_airflow/data/traffy_fondue_data.csv')
  File "/home/airflow/.local/lib/python3.7/site-packages/pandas/util/_decorators.py", line 311, in wrapper
    return func(*args, **kwargs)
  File "/home/airflow/.local/lib/python3.7/site-packages/pandas/io/parsers/readers.py", line 586, in read_csv
    return _read(filepath_or_buffer, kwds)
  File "/home/airflow/.local/lib/python3.7/site-packages/pandas/io/parsers/readers.py", line 482, in _read
    parser = TextFileReader(filepath_or_buffer, **kwds)
  File "/home/airflow/.local/lib/python3.7/site-packages/pandas/io/parsers/readers.py", line 811, in __init__
    self._engine = self._make_engine(self.engine)
  File "/home/airflow/.local/lib/python3.7/site-packages/pandas/io/parsers/readers.py", line 1040, in _make_engine
    return mapping[engine](self.f, **self.options)  # type: ignore[call-arg]
  File "/home/airflow/.local/lib/python3.7/site-packages/pandas/io/parsers/c_parser_wrapper.py", line 51, in __init__
    self._open_handles(src, kwds)
  File "/home/airflow/.local/lib/python3.7/site-packages/pandas/io/parsers/base_parser.py", line 229, in _open_handles
    errors=kwds.get("encoding_errors", "strict"),
  File "/home/airflow/.local/lib/python3.7/site-packages/pandas/io/common.py", line 707, in get_handle
    newline="",
FileNotFoundError: [Errno 2] No such file or directory: '/Users/80524/Downloads/apache_airflow/data/traffy_fondue_data.csv'
[2022-12-11T04:19:11.459+0000] {processor.py:768} WARNING - No viable dags retrieved from /opt/airflow/dags/data_tools_final_oprator.py
[2022-12-11T04:19:11.470+0000] {processor.py:176} INFO - Processing /opt/airflow/dags/data_tools_final_oprator.py took 1.831 seconds
[2022-12-11T04:19:41.883+0000] {processor.py:154} INFO - Started process (PID=26186) to work on /opt/airflow/dags/data_tools_final_oprator.py
[2022-12-11T04:19:41.886+0000] {processor.py:756} INFO - Processing file /opt/airflow/dags/data_tools_final_oprator.py for tasks to queue
[2022-12-11T04:19:41.888+0000] {logging_mixin.py:137} INFO - [2022-12-11T04:19:41.888+0000] {dagbag.py:537} INFO - Filling up the DagBag from /opt/airflow/dags/data_tools_final_oprator.py
[2022-12-11T04:19:43.738+0000] {logging_mixin.py:137} INFO - [2022-12-11T04:19:43.734+0000] {dagbag.py:342} ERROR - Failed to import: /opt/airflow/dags/data_tools_final_oprator.py
Traceback (most recent call last):
  File "/home/airflow/.local/lib/python3.7/site-packages/airflow/models/dagbag.py", line 338, in parse
    loader.exec_module(new_module)
  File "<frozen importlib._bootstrap_external>", line 728, in exec_module
  File "<frozen importlib._bootstrap>", line 219, in _call_with_frames_removed
  File "/opt/airflow/dags/data_tools_final_oprator.py", line 13, in <module>
    import datatool_model
  File "/opt/airflow/plugins/datatool_model.py", line 106, in <module>
    preprocess = traffy.import_data()
  File "/opt/airflow/plugins/datatool_model.py", line 24, in import_data
    df = pd.read_csv('/Users/80524/Downloads/apache_airflow/data/traffy_fondue_data.csv')
  File "/home/airflow/.local/lib/python3.7/site-packages/pandas/util/_decorators.py", line 311, in wrapper
    return func(*args, **kwargs)
  File "/home/airflow/.local/lib/python3.7/site-packages/pandas/io/parsers/readers.py", line 586, in read_csv
    return _read(filepath_or_buffer, kwds)
  File "/home/airflow/.local/lib/python3.7/site-packages/pandas/io/parsers/readers.py", line 482, in _read
    parser = TextFileReader(filepath_or_buffer, **kwds)
  File "/home/airflow/.local/lib/python3.7/site-packages/pandas/io/parsers/readers.py", line 811, in __init__
    self._engine = self._make_engine(self.engine)
  File "/home/airflow/.local/lib/python3.7/site-packages/pandas/io/parsers/readers.py", line 1040, in _make_engine
    return mapping[engine](self.f, **self.options)  # type: ignore[call-arg]
  File "/home/airflow/.local/lib/python3.7/site-packages/pandas/io/parsers/c_parser_wrapper.py", line 51, in __init__
    self._open_handles(src, kwds)
  File "/home/airflow/.local/lib/python3.7/site-packages/pandas/io/parsers/base_parser.py", line 229, in _open_handles
    errors=kwds.get("encoding_errors", "strict"),
  File "/home/airflow/.local/lib/python3.7/site-packages/pandas/io/common.py", line 707, in get_handle
    newline="",
FileNotFoundError: [Errno 2] No such file or directory: '/Users/80524/Downloads/apache_airflow/data/traffy_fondue_data.csv'
[2022-12-11T04:19:43.740+0000] {processor.py:768} WARNING - No viable dags retrieved from /opt/airflow/dags/data_tools_final_oprator.py
[2022-12-11T04:19:43.751+0000] {processor.py:176} INFO - Processing /opt/airflow/dags/data_tools_final_oprator.py took 1.870 seconds
[2022-12-11T04:20:14.080+0000] {processor.py:154} INFO - Started process (PID=26216) to work on /opt/airflow/dags/data_tools_final_oprator.py
[2022-12-11T04:20:14.082+0000] {processor.py:756} INFO - Processing file /opt/airflow/dags/data_tools_final_oprator.py for tasks to queue
[2022-12-11T04:20:14.084+0000] {logging_mixin.py:137} INFO - [2022-12-11T04:20:14.083+0000] {dagbag.py:537} INFO - Filling up the DagBag from /opt/airflow/dags/data_tools_final_oprator.py
[2022-12-11T04:20:15.990+0000] {logging_mixin.py:137} INFO - [2022-12-11T04:20:15.985+0000] {dagbag.py:342} ERROR - Failed to import: /opt/airflow/dags/data_tools_final_oprator.py
Traceback (most recent call last):
  File "/home/airflow/.local/lib/python3.7/site-packages/airflow/models/dagbag.py", line 338, in parse
    loader.exec_module(new_module)
  File "<frozen importlib._bootstrap_external>", line 728, in exec_module
  File "<frozen importlib._bootstrap>", line 219, in _call_with_frames_removed
  File "/opt/airflow/dags/data_tools_final_oprator.py", line 13, in <module>
    import datatool_model
  File "/opt/airflow/plugins/datatool_model.py", line 106, in <module>
    preprocess = traffy.import_data()
  File "/opt/airflow/plugins/datatool_model.py", line 24, in import_data
    df = pd.read_csv('/Users/80524/Downloads/apache_airflow/data/traffy_fondue_data.csv')
  File "/home/airflow/.local/lib/python3.7/site-packages/pandas/util/_decorators.py", line 311, in wrapper
    return func(*args, **kwargs)
  File "/home/airflow/.local/lib/python3.7/site-packages/pandas/io/parsers/readers.py", line 586, in read_csv
    return _read(filepath_or_buffer, kwds)
  File "/home/airflow/.local/lib/python3.7/site-packages/pandas/io/parsers/readers.py", line 482, in _read
    parser = TextFileReader(filepath_or_buffer, **kwds)
  File "/home/airflow/.local/lib/python3.7/site-packages/pandas/io/parsers/readers.py", line 811, in __init__
    self._engine = self._make_engine(self.engine)
  File "/home/airflow/.local/lib/python3.7/site-packages/pandas/io/parsers/readers.py", line 1040, in _make_engine
    return mapping[engine](self.f, **self.options)  # type: ignore[call-arg]
  File "/home/airflow/.local/lib/python3.7/site-packages/pandas/io/parsers/c_parser_wrapper.py", line 51, in __init__
    self._open_handles(src, kwds)
  File "/home/airflow/.local/lib/python3.7/site-packages/pandas/io/parsers/base_parser.py", line 229, in _open_handles
    errors=kwds.get("encoding_errors", "strict"),
  File "/home/airflow/.local/lib/python3.7/site-packages/pandas/io/common.py", line 707, in get_handle
    newline="",
FileNotFoundError: [Errno 2] No such file or directory: '/Users/80524/Downloads/apache_airflow/data/traffy_fondue_data.csv'
[2022-12-11T04:20:15.992+0000] {processor.py:768} WARNING - No viable dags retrieved from /opt/airflow/dags/data_tools_final_oprator.py
[2022-12-11T04:20:16.003+0000] {processor.py:176} INFO - Processing /opt/airflow/dags/data_tools_final_oprator.py took 1.927 seconds
[2022-12-11T04:20:46.319+0000] {processor.py:154} INFO - Started process (PID=26245) to work on /opt/airflow/dags/data_tools_final_oprator.py
[2022-12-11T04:20:46.320+0000] {processor.py:756} INFO - Processing file /opt/airflow/dags/data_tools_final_oprator.py for tasks to queue
[2022-12-11T04:20:46.321+0000] {logging_mixin.py:137} INFO - [2022-12-11T04:20:46.321+0000] {dagbag.py:537} INFO - Filling up the DagBag from /opt/airflow/dags/data_tools_final_oprator.py
[2022-12-11T04:20:48.173+0000] {logging_mixin.py:137} INFO - [2022-12-11T04:20:48.169+0000] {dagbag.py:342} ERROR - Failed to import: /opt/airflow/dags/data_tools_final_oprator.py
Traceback (most recent call last):
  File "/home/airflow/.local/lib/python3.7/site-packages/airflow/models/dagbag.py", line 338, in parse
    loader.exec_module(new_module)
  File "<frozen importlib._bootstrap_external>", line 728, in exec_module
  File "<frozen importlib._bootstrap>", line 219, in _call_with_frames_removed
  File "/opt/airflow/dags/data_tools_final_oprator.py", line 13, in <module>
    import datatool_model
  File "/opt/airflow/plugins/datatool_model.py", line 106, in <module>
    preprocess = traffy.import_data()
  File "/opt/airflow/plugins/datatool_model.py", line 24, in import_data
    df = pd.read_csv('/Users/80524/Downloads/apache_airflow/data/traffy_fondue_data.csv')
  File "/home/airflow/.local/lib/python3.7/site-packages/pandas/util/_decorators.py", line 311, in wrapper
    return func(*args, **kwargs)
  File "/home/airflow/.local/lib/python3.7/site-packages/pandas/io/parsers/readers.py", line 586, in read_csv
    return _read(filepath_or_buffer, kwds)
  File "/home/airflow/.local/lib/python3.7/site-packages/pandas/io/parsers/readers.py", line 482, in _read
    parser = TextFileReader(filepath_or_buffer, **kwds)
  File "/home/airflow/.local/lib/python3.7/site-packages/pandas/io/parsers/readers.py", line 811, in __init__
    self._engine = self._make_engine(self.engine)
  File "/home/airflow/.local/lib/python3.7/site-packages/pandas/io/parsers/readers.py", line 1040, in _make_engine
    return mapping[engine](self.f, **self.options)  # type: ignore[call-arg]
  File "/home/airflow/.local/lib/python3.7/site-packages/pandas/io/parsers/c_parser_wrapper.py", line 51, in __init__
    self._open_handles(src, kwds)
  File "/home/airflow/.local/lib/python3.7/site-packages/pandas/io/parsers/base_parser.py", line 229, in _open_handles
    errors=kwds.get("encoding_errors", "strict"),
  File "/home/airflow/.local/lib/python3.7/site-packages/pandas/io/common.py", line 707, in get_handle
    newline="",
FileNotFoundError: [Errno 2] No such file or directory: '/Users/80524/Downloads/apache_airflow/data/traffy_fondue_data.csv'
[2022-12-11T04:20:48.175+0000] {processor.py:768} WARNING - No viable dags retrieved from /opt/airflow/dags/data_tools_final_oprator.py
[2022-12-11T04:20:48.187+0000] {processor.py:176} INFO - Processing /opt/airflow/dags/data_tools_final_oprator.py took 1.870 seconds
[2022-12-11T04:21:18.510+0000] {processor.py:154} INFO - Started process (PID=26276) to work on /opt/airflow/dags/data_tools_final_oprator.py
[2022-12-11T04:21:18.512+0000] {processor.py:756} INFO - Processing file /opt/airflow/dags/data_tools_final_oprator.py for tasks to queue
[2022-12-11T04:21:18.513+0000] {logging_mixin.py:137} INFO - [2022-12-11T04:21:18.513+0000] {dagbag.py:537} INFO - Filling up the DagBag from /opt/airflow/dags/data_tools_final_oprator.py
[2022-12-11T04:21:20.338+0000] {logging_mixin.py:137} INFO - [2022-12-11T04:21:20.334+0000] {dagbag.py:342} ERROR - Failed to import: /opt/airflow/dags/data_tools_final_oprator.py
Traceback (most recent call last):
  File "/home/airflow/.local/lib/python3.7/site-packages/airflow/models/dagbag.py", line 338, in parse
    loader.exec_module(new_module)
  File "<frozen importlib._bootstrap_external>", line 728, in exec_module
  File "<frozen importlib._bootstrap>", line 219, in _call_with_frames_removed
  File "/opt/airflow/dags/data_tools_final_oprator.py", line 13, in <module>
    import datatool_model
  File "/opt/airflow/plugins/datatool_model.py", line 106, in <module>
    preprocess = traffy.import_data()
  File "/opt/airflow/plugins/datatool_model.py", line 24, in import_data
    df = pd.read_csv('/Users/80524/Downloads/apache_airflow/data/traffy_fondue_data.csv')
  File "/home/airflow/.local/lib/python3.7/site-packages/pandas/util/_decorators.py", line 311, in wrapper
    return func(*args, **kwargs)
  File "/home/airflow/.local/lib/python3.7/site-packages/pandas/io/parsers/readers.py", line 586, in read_csv
    return _read(filepath_or_buffer, kwds)
  File "/home/airflow/.local/lib/python3.7/site-packages/pandas/io/parsers/readers.py", line 482, in _read
    parser = TextFileReader(filepath_or_buffer, **kwds)
  File "/home/airflow/.local/lib/python3.7/site-packages/pandas/io/parsers/readers.py", line 811, in __init__
    self._engine = self._make_engine(self.engine)
  File "/home/airflow/.local/lib/python3.7/site-packages/pandas/io/parsers/readers.py", line 1040, in _make_engine
    return mapping[engine](self.f, **self.options)  # type: ignore[call-arg]
  File "/home/airflow/.local/lib/python3.7/site-packages/pandas/io/parsers/c_parser_wrapper.py", line 51, in __init__
    self._open_handles(src, kwds)
  File "/home/airflow/.local/lib/python3.7/site-packages/pandas/io/parsers/base_parser.py", line 229, in _open_handles
    errors=kwds.get("encoding_errors", "strict"),
  File "/home/airflow/.local/lib/python3.7/site-packages/pandas/io/common.py", line 707, in get_handle
    newline="",
FileNotFoundError: [Errno 2] No such file or directory: '/Users/80524/Downloads/apache_airflow/data/traffy_fondue_data.csv'
[2022-12-11T04:21:20.339+0000] {processor.py:768} WARNING - No viable dags retrieved from /opt/airflow/dags/data_tools_final_oprator.py
[2022-12-11T04:21:20.350+0000] {processor.py:176} INFO - Processing /opt/airflow/dags/data_tools_final_oprator.py took 1.841 seconds
[2022-12-11T04:21:50.674+0000] {processor.py:154} INFO - Started process (PID=26304) to work on /opt/airflow/dags/data_tools_final_oprator.py
[2022-12-11T04:21:50.676+0000] {processor.py:756} INFO - Processing file /opt/airflow/dags/data_tools_final_oprator.py for tasks to queue
[2022-12-11T04:21:50.678+0000] {logging_mixin.py:137} INFO - [2022-12-11T04:21:50.677+0000] {dagbag.py:537} INFO - Filling up the DagBag from /opt/airflow/dags/data_tools_final_oprator.py
[2022-12-11T04:21:52.535+0000] {logging_mixin.py:137} INFO - [2022-12-11T04:21:52.531+0000] {dagbag.py:342} ERROR - Failed to import: /opt/airflow/dags/data_tools_final_oprator.py
Traceback (most recent call last):
  File "/home/airflow/.local/lib/python3.7/site-packages/airflow/models/dagbag.py", line 338, in parse
    loader.exec_module(new_module)
  File "<frozen importlib._bootstrap_external>", line 728, in exec_module
  File "<frozen importlib._bootstrap>", line 219, in _call_with_frames_removed
  File "/opt/airflow/dags/data_tools_final_oprator.py", line 13, in <module>
    import datatool_model
  File "/opt/airflow/plugins/datatool_model.py", line 106, in <module>
    preprocess = traffy.import_data()
  File "/opt/airflow/plugins/datatool_model.py", line 24, in import_data
    df = pd.read_csv('/Users/80524/Downloads/apache_airflow/data/traffy_fondue_data.csv')
  File "/home/airflow/.local/lib/python3.7/site-packages/pandas/util/_decorators.py", line 311, in wrapper
    return func(*args, **kwargs)
  File "/home/airflow/.local/lib/python3.7/site-packages/pandas/io/parsers/readers.py", line 586, in read_csv
    return _read(filepath_or_buffer, kwds)
  File "/home/airflow/.local/lib/python3.7/site-packages/pandas/io/parsers/readers.py", line 482, in _read
    parser = TextFileReader(filepath_or_buffer, **kwds)
  File "/home/airflow/.local/lib/python3.7/site-packages/pandas/io/parsers/readers.py", line 811, in __init__
    self._engine = self._make_engine(self.engine)
  File "/home/airflow/.local/lib/python3.7/site-packages/pandas/io/parsers/readers.py", line 1040, in _make_engine
    return mapping[engine](self.f, **self.options)  # type: ignore[call-arg]
  File "/home/airflow/.local/lib/python3.7/site-packages/pandas/io/parsers/c_parser_wrapper.py", line 51, in __init__
    self._open_handles(src, kwds)
  File "/home/airflow/.local/lib/python3.7/site-packages/pandas/io/parsers/base_parser.py", line 229, in _open_handles
    errors=kwds.get("encoding_errors", "strict"),
  File "/home/airflow/.local/lib/python3.7/site-packages/pandas/io/common.py", line 707, in get_handle
    newline="",
FileNotFoundError: [Errno 2] No such file or directory: '/Users/80524/Downloads/apache_airflow/data/traffy_fondue_data.csv'
[2022-12-11T04:21:52.537+0000] {processor.py:768} WARNING - No viable dags retrieved from /opt/airflow/dags/data_tools_final_oprator.py
[2022-12-11T04:21:52.549+0000] {processor.py:176} INFO - Processing /opt/airflow/dags/data_tools_final_oprator.py took 1.879 seconds
[2022-12-11T04:22:22.902+0000] {processor.py:154} INFO - Started process (PID=26332) to work on /opt/airflow/dags/data_tools_final_oprator.py
[2022-12-11T04:22:22.904+0000] {processor.py:756} INFO - Processing file /opt/airflow/dags/data_tools_final_oprator.py for tasks to queue
[2022-12-11T04:22:22.905+0000] {logging_mixin.py:137} INFO - [2022-12-11T04:22:22.905+0000] {dagbag.py:537} INFO - Filling up the DagBag from /opt/airflow/dags/data_tools_final_oprator.py
[2022-12-11T04:22:24.753+0000] {logging_mixin.py:137} INFO - [2022-12-11T04:22:24.748+0000] {dagbag.py:342} ERROR - Failed to import: /opt/airflow/dags/data_tools_final_oprator.py
Traceback (most recent call last):
  File "/home/airflow/.local/lib/python3.7/site-packages/airflow/models/dagbag.py", line 338, in parse
    loader.exec_module(new_module)
  File "<frozen importlib._bootstrap_external>", line 728, in exec_module
  File "<frozen importlib._bootstrap>", line 219, in _call_with_frames_removed
  File "/opt/airflow/dags/data_tools_final_oprator.py", line 13, in <module>
    import datatool_model
  File "/opt/airflow/plugins/datatool_model.py", line 106, in <module>
    preprocess = traffy.import_data()
  File "/opt/airflow/plugins/datatool_model.py", line 24, in import_data
    df = pd.read_csv('/Users/80524/Downloads/apache_airflow/data/traffy_fondue_data.csv')
  File "/home/airflow/.local/lib/python3.7/site-packages/pandas/util/_decorators.py", line 311, in wrapper
    return func(*args, **kwargs)
  File "/home/airflow/.local/lib/python3.7/site-packages/pandas/io/parsers/readers.py", line 586, in read_csv
    return _read(filepath_or_buffer, kwds)
  File "/home/airflow/.local/lib/python3.7/site-packages/pandas/io/parsers/readers.py", line 482, in _read
    parser = TextFileReader(filepath_or_buffer, **kwds)
  File "/home/airflow/.local/lib/python3.7/site-packages/pandas/io/parsers/readers.py", line 811, in __init__
    self._engine = self._make_engine(self.engine)
  File "/home/airflow/.local/lib/python3.7/site-packages/pandas/io/parsers/readers.py", line 1040, in _make_engine
    return mapping[engine](self.f, **self.options)  # type: ignore[call-arg]
  File "/home/airflow/.local/lib/python3.7/site-packages/pandas/io/parsers/c_parser_wrapper.py", line 51, in __init__
    self._open_handles(src, kwds)
  File "/home/airflow/.local/lib/python3.7/site-packages/pandas/io/parsers/base_parser.py", line 229, in _open_handles
    errors=kwds.get("encoding_errors", "strict"),
  File "/home/airflow/.local/lib/python3.7/site-packages/pandas/io/common.py", line 707, in get_handle
    newline="",
FileNotFoundError: [Errno 2] No such file or directory: '/Users/80524/Downloads/apache_airflow/data/traffy_fondue_data.csv'
[2022-12-11T04:22:24.754+0000] {processor.py:768} WARNING - No viable dags retrieved from /opt/airflow/dags/data_tools_final_oprator.py
[2022-12-11T04:22:24.765+0000] {processor.py:176} INFO - Processing /opt/airflow/dags/data_tools_final_oprator.py took 1.866 seconds
[2022-12-11T04:22:55.231+0000] {processor.py:154} INFO - Started process (PID=26361) to work on /opt/airflow/dags/data_tools_final_oprator.py
[2022-12-11T04:22:55.234+0000] {processor.py:756} INFO - Processing file /opt/airflow/dags/data_tools_final_oprator.py for tasks to queue
[2022-12-11T04:22:55.236+0000] {logging_mixin.py:137} INFO - [2022-12-11T04:22:55.235+0000] {dagbag.py:537} INFO - Filling up the DagBag from /opt/airflow/dags/data_tools_final_oprator.py
[2022-12-11T04:22:57.138+0000] {logging_mixin.py:137} INFO - [2022-12-11T04:22:57.133+0000] {dagbag.py:342} ERROR - Failed to import: /opt/airflow/dags/data_tools_final_oprator.py
Traceback (most recent call last):
  File "/home/airflow/.local/lib/python3.7/site-packages/airflow/models/dagbag.py", line 338, in parse
    loader.exec_module(new_module)
  File "<frozen importlib._bootstrap_external>", line 728, in exec_module
  File "<frozen importlib._bootstrap>", line 219, in _call_with_frames_removed
  File "/opt/airflow/dags/data_tools_final_oprator.py", line 13, in <module>
    import datatool_model
  File "/opt/airflow/plugins/datatool_model.py", line 106, in <module>
    preprocess = traffy.import_data()
  File "/opt/airflow/plugins/datatool_model.py", line 24, in import_data
    df = pd.read_csv('/Users/80524/Downloads/apache_airflow/data/traffy_fondue_data.csv')
  File "/home/airflow/.local/lib/python3.7/site-packages/pandas/util/_decorators.py", line 311, in wrapper
    return func(*args, **kwargs)
  File "/home/airflow/.local/lib/python3.7/site-packages/pandas/io/parsers/readers.py", line 586, in read_csv
    return _read(filepath_or_buffer, kwds)
  File "/home/airflow/.local/lib/python3.7/site-packages/pandas/io/parsers/readers.py", line 482, in _read
    parser = TextFileReader(filepath_or_buffer, **kwds)
  File "/home/airflow/.local/lib/python3.7/site-packages/pandas/io/parsers/readers.py", line 811, in __init__
    self._engine = self._make_engine(self.engine)
  File "/home/airflow/.local/lib/python3.7/site-packages/pandas/io/parsers/readers.py", line 1040, in _make_engine
    return mapping[engine](self.f, **self.options)  # type: ignore[call-arg]
  File "/home/airflow/.local/lib/python3.7/site-packages/pandas/io/parsers/c_parser_wrapper.py", line 51, in __init__
    self._open_handles(src, kwds)
  File "/home/airflow/.local/lib/python3.7/site-packages/pandas/io/parsers/base_parser.py", line 229, in _open_handles
    errors=kwds.get("encoding_errors", "strict"),
  File "/home/airflow/.local/lib/python3.7/site-packages/pandas/io/common.py", line 707, in get_handle
    newline="",
FileNotFoundError: [Errno 2] No such file or directory: '/Users/80524/Downloads/apache_airflow/data/traffy_fondue_data.csv'
[2022-12-11T04:22:57.139+0000] {processor.py:768} WARNING - No viable dags retrieved from /opt/airflow/dags/data_tools_final_oprator.py
[2022-12-11T04:22:57.150+0000] {processor.py:176} INFO - Processing /opt/airflow/dags/data_tools_final_oprator.py took 1.924 seconds
[2022-12-11T04:23:27.513+0000] {processor.py:154} INFO - Started process (PID=26390) to work on /opt/airflow/dags/data_tools_final_oprator.py
[2022-12-11T04:23:27.515+0000] {processor.py:756} INFO - Processing file /opt/airflow/dags/data_tools_final_oprator.py for tasks to queue
[2022-12-11T04:23:27.517+0000] {logging_mixin.py:137} INFO - [2022-12-11T04:23:27.517+0000] {dagbag.py:537} INFO - Filling up the DagBag from /opt/airflow/dags/data_tools_final_oprator.py
[2022-12-11T04:23:29.362+0000] {logging_mixin.py:137} INFO - [2022-12-11T04:23:29.358+0000] {dagbag.py:342} ERROR - Failed to import: /opt/airflow/dags/data_tools_final_oprator.py
Traceback (most recent call last):
  File "/home/airflow/.local/lib/python3.7/site-packages/airflow/models/dagbag.py", line 338, in parse
    loader.exec_module(new_module)
  File "<frozen importlib._bootstrap_external>", line 728, in exec_module
  File "<frozen importlib._bootstrap>", line 219, in _call_with_frames_removed
  File "/opt/airflow/dags/data_tools_final_oprator.py", line 13, in <module>
    import datatool_model
  File "/opt/airflow/plugins/datatool_model.py", line 106, in <module>
    preprocess = traffy.import_data()
  File "/opt/airflow/plugins/datatool_model.py", line 24, in import_data
    df = pd.read_csv('/Users/80524/Downloads/apache_airflow/data/traffy_fondue_data.csv')
  File "/home/airflow/.local/lib/python3.7/site-packages/pandas/util/_decorators.py", line 311, in wrapper
    return func(*args, **kwargs)
  File "/home/airflow/.local/lib/python3.7/site-packages/pandas/io/parsers/readers.py", line 586, in read_csv
    return _read(filepath_or_buffer, kwds)
  File "/home/airflow/.local/lib/python3.7/site-packages/pandas/io/parsers/readers.py", line 482, in _read
    parser = TextFileReader(filepath_or_buffer, **kwds)
  File "/home/airflow/.local/lib/python3.7/site-packages/pandas/io/parsers/readers.py", line 811, in __init__
    self._engine = self._make_engine(self.engine)
  File "/home/airflow/.local/lib/python3.7/site-packages/pandas/io/parsers/readers.py", line 1040, in _make_engine
    return mapping[engine](self.f, **self.options)  # type: ignore[call-arg]
  File "/home/airflow/.local/lib/python3.7/site-packages/pandas/io/parsers/c_parser_wrapper.py", line 51, in __init__
    self._open_handles(src, kwds)
  File "/home/airflow/.local/lib/python3.7/site-packages/pandas/io/parsers/base_parser.py", line 229, in _open_handles
    errors=kwds.get("encoding_errors", "strict"),
  File "/home/airflow/.local/lib/python3.7/site-packages/pandas/io/common.py", line 707, in get_handle
    newline="",
FileNotFoundError: [Errno 2] No such file or directory: '/Users/80524/Downloads/apache_airflow/data/traffy_fondue_data.csv'
[2022-12-11T04:23:29.363+0000] {processor.py:768} WARNING - No viable dags retrieved from /opt/airflow/dags/data_tools_final_oprator.py
[2022-12-11T04:23:29.374+0000] {processor.py:176} INFO - Processing /opt/airflow/dags/data_tools_final_oprator.py took 1.864 seconds
[2022-12-11T04:23:59.695+0000] {processor.py:154} INFO - Started process (PID=26419) to work on /opt/airflow/dags/data_tools_final_oprator.py
[2022-12-11T04:23:59.697+0000] {processor.py:756} INFO - Processing file /opt/airflow/dags/data_tools_final_oprator.py for tasks to queue
[2022-12-11T04:23:59.698+0000] {logging_mixin.py:137} INFO - [2022-12-11T04:23:59.697+0000] {dagbag.py:537} INFO - Filling up the DagBag from /opt/airflow/dags/data_tools_final_oprator.py
[2022-12-11T04:24:01.516+0000] {logging_mixin.py:137} INFO - [2022-12-11T04:24:01.512+0000] {dagbag.py:342} ERROR - Failed to import: /opt/airflow/dags/data_tools_final_oprator.py
Traceback (most recent call last):
  File "/home/airflow/.local/lib/python3.7/site-packages/airflow/models/dagbag.py", line 338, in parse
    loader.exec_module(new_module)
  File "<frozen importlib._bootstrap_external>", line 728, in exec_module
  File "<frozen importlib._bootstrap>", line 219, in _call_with_frames_removed
  File "/opt/airflow/dags/data_tools_final_oprator.py", line 13, in <module>
    import datatool_model
  File "/opt/airflow/plugins/datatool_model.py", line 106, in <module>
    preprocess = traffy.import_data()
  File "/opt/airflow/plugins/datatool_model.py", line 24, in import_data
    df = pd.read_csv('/Users/80524/Downloads/apache_airflow/data/traffy_fondue_data.csv')
  File "/home/airflow/.local/lib/python3.7/site-packages/pandas/util/_decorators.py", line 311, in wrapper
    return func(*args, **kwargs)
  File "/home/airflow/.local/lib/python3.7/site-packages/pandas/io/parsers/readers.py", line 586, in read_csv
    return _read(filepath_or_buffer, kwds)
  File "/home/airflow/.local/lib/python3.7/site-packages/pandas/io/parsers/readers.py", line 482, in _read
    parser = TextFileReader(filepath_or_buffer, **kwds)
  File "/home/airflow/.local/lib/python3.7/site-packages/pandas/io/parsers/readers.py", line 811, in __init__
    self._engine = self._make_engine(self.engine)
  File "/home/airflow/.local/lib/python3.7/site-packages/pandas/io/parsers/readers.py", line 1040, in _make_engine
    return mapping[engine](self.f, **self.options)  # type: ignore[call-arg]
  File "/home/airflow/.local/lib/python3.7/site-packages/pandas/io/parsers/c_parser_wrapper.py", line 51, in __init__
    self._open_handles(src, kwds)
  File "/home/airflow/.local/lib/python3.7/site-packages/pandas/io/parsers/base_parser.py", line 229, in _open_handles
    errors=kwds.get("encoding_errors", "strict"),
  File "/home/airflow/.local/lib/python3.7/site-packages/pandas/io/common.py", line 707, in get_handle
    newline="",
FileNotFoundError: [Errno 2] No such file or directory: '/Users/80524/Downloads/apache_airflow/data/traffy_fondue_data.csv'
[2022-12-11T04:24:01.518+0000] {processor.py:768} WARNING - No viable dags retrieved from /opt/airflow/dags/data_tools_final_oprator.py
[2022-12-11T04:24:01.528+0000] {processor.py:176} INFO - Processing /opt/airflow/dags/data_tools_final_oprator.py took 1.836 seconds
[2022-12-11T04:24:31.868+0000] {processor.py:154} INFO - Started process (PID=26449) to work on /opt/airflow/dags/data_tools_final_oprator.py
[2022-12-11T04:24:31.870+0000] {processor.py:756} INFO - Processing file /opt/airflow/dags/data_tools_final_oprator.py for tasks to queue
[2022-12-11T04:24:31.872+0000] {logging_mixin.py:137} INFO - [2022-12-11T04:24:31.872+0000] {dagbag.py:537} INFO - Filling up the DagBag from /opt/airflow/dags/data_tools_final_oprator.py
[2022-12-11T04:24:33.688+0000] {logging_mixin.py:137} INFO - [2022-12-11T04:24:33.683+0000] {dagbag.py:342} ERROR - Failed to import: /opt/airflow/dags/data_tools_final_oprator.py
Traceback (most recent call last):
  File "/home/airflow/.local/lib/python3.7/site-packages/airflow/models/dagbag.py", line 338, in parse
    loader.exec_module(new_module)
  File "<frozen importlib._bootstrap_external>", line 728, in exec_module
  File "<frozen importlib._bootstrap>", line 219, in _call_with_frames_removed
  File "/opt/airflow/dags/data_tools_final_oprator.py", line 13, in <module>
    import datatool_model
  File "/opt/airflow/plugins/datatool_model.py", line 106, in <module>
    preprocess = traffy.import_data()
  File "/opt/airflow/plugins/datatool_model.py", line 24, in import_data
    df = pd.read_csv('/Users/80524/Downloads/apache_airflow/data/traffy_fondue_data.csv')
  File "/home/airflow/.local/lib/python3.7/site-packages/pandas/util/_decorators.py", line 311, in wrapper
    return func(*args, **kwargs)
  File "/home/airflow/.local/lib/python3.7/site-packages/pandas/io/parsers/readers.py", line 586, in read_csv
    return _read(filepath_or_buffer, kwds)
  File "/home/airflow/.local/lib/python3.7/site-packages/pandas/io/parsers/readers.py", line 482, in _read
    parser = TextFileReader(filepath_or_buffer, **kwds)
  File "/home/airflow/.local/lib/python3.7/site-packages/pandas/io/parsers/readers.py", line 811, in __init__
    self._engine = self._make_engine(self.engine)
  File "/home/airflow/.local/lib/python3.7/site-packages/pandas/io/parsers/readers.py", line 1040, in _make_engine
    return mapping[engine](self.f, **self.options)  # type: ignore[call-arg]
  File "/home/airflow/.local/lib/python3.7/site-packages/pandas/io/parsers/c_parser_wrapper.py", line 51, in __init__
    self._open_handles(src, kwds)
  File "/home/airflow/.local/lib/python3.7/site-packages/pandas/io/parsers/base_parser.py", line 229, in _open_handles
    errors=kwds.get("encoding_errors", "strict"),
  File "/home/airflow/.local/lib/python3.7/site-packages/pandas/io/common.py", line 707, in get_handle
    newline="",
FileNotFoundError: [Errno 2] No such file or directory: '/Users/80524/Downloads/apache_airflow/data/traffy_fondue_data.csv'
[2022-12-11T04:24:33.690+0000] {processor.py:768} WARNING - No viable dags retrieved from /opt/airflow/dags/data_tools_final_oprator.py
[2022-12-11T04:24:33.701+0000] {processor.py:176} INFO - Processing /opt/airflow/dags/data_tools_final_oprator.py took 1.838 seconds
[2022-12-11T04:25:04.061+0000] {processor.py:154} INFO - Started process (PID=26479) to work on /opt/airflow/dags/data_tools_final_oprator.py
[2022-12-11T04:25:04.064+0000] {processor.py:756} INFO - Processing file /opt/airflow/dags/data_tools_final_oprator.py for tasks to queue
[2022-12-11T04:25:04.065+0000] {logging_mixin.py:137} INFO - [2022-12-11T04:25:04.065+0000] {dagbag.py:537} INFO - Filling up the DagBag from /opt/airflow/dags/data_tools_final_oprator.py
[2022-12-11T04:25:05.899+0000] {logging_mixin.py:137} INFO - [2022-12-11T04:25:05.895+0000] {dagbag.py:342} ERROR - Failed to import: /opt/airflow/dags/data_tools_final_oprator.py
Traceback (most recent call last):
  File "/home/airflow/.local/lib/python3.7/site-packages/airflow/models/dagbag.py", line 338, in parse
    loader.exec_module(new_module)
  File "<frozen importlib._bootstrap_external>", line 728, in exec_module
  File "<frozen importlib._bootstrap>", line 219, in _call_with_frames_removed
  File "/opt/airflow/dags/data_tools_final_oprator.py", line 13, in <module>
    import datatool_model
  File "/opt/airflow/plugins/datatool_model.py", line 106, in <module>
    preprocess = traffy.import_data()
  File "/opt/airflow/plugins/datatool_model.py", line 24, in import_data
    df = pd.read_csv('/Users/80524/Downloads/apache_airflow/data/traffy_fondue_data.csv')
  File "/home/airflow/.local/lib/python3.7/site-packages/pandas/util/_decorators.py", line 311, in wrapper
    return func(*args, **kwargs)
  File "/home/airflow/.local/lib/python3.7/site-packages/pandas/io/parsers/readers.py", line 586, in read_csv
    return _read(filepath_or_buffer, kwds)
  File "/home/airflow/.local/lib/python3.7/site-packages/pandas/io/parsers/readers.py", line 482, in _read
    parser = TextFileReader(filepath_or_buffer, **kwds)
  File "/home/airflow/.local/lib/python3.7/site-packages/pandas/io/parsers/readers.py", line 811, in __init__
    self._engine = self._make_engine(self.engine)
  File "/home/airflow/.local/lib/python3.7/site-packages/pandas/io/parsers/readers.py", line 1040, in _make_engine
    return mapping[engine](self.f, **self.options)  # type: ignore[call-arg]
  File "/home/airflow/.local/lib/python3.7/site-packages/pandas/io/parsers/c_parser_wrapper.py", line 51, in __init__
    self._open_handles(src, kwds)
  File "/home/airflow/.local/lib/python3.7/site-packages/pandas/io/parsers/base_parser.py", line 229, in _open_handles
    errors=kwds.get("encoding_errors", "strict"),
  File "/home/airflow/.local/lib/python3.7/site-packages/pandas/io/common.py", line 707, in get_handle
    newline="",
FileNotFoundError: [Errno 2] No such file or directory: '/Users/80524/Downloads/apache_airflow/data/traffy_fondue_data.csv'
[2022-12-11T04:25:05.900+0000] {processor.py:768} WARNING - No viable dags retrieved from /opt/airflow/dags/data_tools_final_oprator.py
[2022-12-11T04:25:05.911+0000] {processor.py:176} INFO - Processing /opt/airflow/dags/data_tools_final_oprator.py took 1.853 seconds
[2022-12-11T04:25:36.321+0000] {processor.py:154} INFO - Started process (PID=26508) to work on /opt/airflow/dags/data_tools_final_oprator.py
[2022-12-11T04:25:36.324+0000] {processor.py:756} INFO - Processing file /opt/airflow/dags/data_tools_final_oprator.py for tasks to queue
[2022-12-11T04:25:36.325+0000] {logging_mixin.py:137} INFO - [2022-12-11T04:25:36.325+0000] {dagbag.py:537} INFO - Filling up the DagBag from /opt/airflow/dags/data_tools_final_oprator.py
[2022-12-11T04:25:38.147+0000] {logging_mixin.py:137} INFO - [2022-12-11T04:25:38.143+0000] {dagbag.py:342} ERROR - Failed to import: /opt/airflow/dags/data_tools_final_oprator.py
Traceback (most recent call last):
  File "/home/airflow/.local/lib/python3.7/site-packages/airflow/models/dagbag.py", line 338, in parse
    loader.exec_module(new_module)
  File "<frozen importlib._bootstrap_external>", line 728, in exec_module
  File "<frozen importlib._bootstrap>", line 219, in _call_with_frames_removed
  File "/opt/airflow/dags/data_tools_final_oprator.py", line 13, in <module>
    import datatool_model
  File "/opt/airflow/plugins/datatool_model.py", line 106, in <module>
    preprocess = traffy.import_data()
  File "/opt/airflow/plugins/datatool_model.py", line 24, in import_data
    df = pd.read_csv('/Users/80524/Downloads/apache_airflow/data/traffy_fondue_data.csv')
  File "/home/airflow/.local/lib/python3.7/site-packages/pandas/util/_decorators.py", line 311, in wrapper
    return func(*args, **kwargs)
  File "/home/airflow/.local/lib/python3.7/site-packages/pandas/io/parsers/readers.py", line 586, in read_csv
    return _read(filepath_or_buffer, kwds)
  File "/home/airflow/.local/lib/python3.7/site-packages/pandas/io/parsers/readers.py", line 482, in _read
    parser = TextFileReader(filepath_or_buffer, **kwds)
  File "/home/airflow/.local/lib/python3.7/site-packages/pandas/io/parsers/readers.py", line 811, in __init__
    self._engine = self._make_engine(self.engine)
  File "/home/airflow/.local/lib/python3.7/site-packages/pandas/io/parsers/readers.py", line 1040, in _make_engine
    return mapping[engine](self.f, **self.options)  # type: ignore[call-arg]
  File "/home/airflow/.local/lib/python3.7/site-packages/pandas/io/parsers/c_parser_wrapper.py", line 51, in __init__
    self._open_handles(src, kwds)
  File "/home/airflow/.local/lib/python3.7/site-packages/pandas/io/parsers/base_parser.py", line 229, in _open_handles
    errors=kwds.get("encoding_errors", "strict"),
  File "/home/airflow/.local/lib/python3.7/site-packages/pandas/io/common.py", line 707, in get_handle
    newline="",
FileNotFoundError: [Errno 2] No such file or directory: '/Users/80524/Downloads/apache_airflow/data/traffy_fondue_data.csv'
[2022-12-11T04:25:38.148+0000] {processor.py:768} WARNING - No viable dags retrieved from /opt/airflow/dags/data_tools_final_oprator.py
[2022-12-11T04:25:38.159+0000] {processor.py:176} INFO - Processing /opt/airflow/dags/data_tools_final_oprator.py took 1.841 seconds
[2022-12-11T04:26:08.528+0000] {processor.py:154} INFO - Started process (PID=26537) to work on /opt/airflow/dags/data_tools_final_oprator.py
[2022-12-11T04:26:08.530+0000] {processor.py:756} INFO - Processing file /opt/airflow/dags/data_tools_final_oprator.py for tasks to queue
[2022-12-11T04:26:08.531+0000] {logging_mixin.py:137} INFO - [2022-12-11T04:26:08.531+0000] {dagbag.py:537} INFO - Filling up the DagBag from /opt/airflow/dags/data_tools_final_oprator.py
[2022-12-11T04:26:10.406+0000] {logging_mixin.py:137} INFO - [2022-12-11T04:26:10.402+0000] {dagbag.py:342} ERROR - Failed to import: /opt/airflow/dags/data_tools_final_oprator.py
Traceback (most recent call last):
  File "/home/airflow/.local/lib/python3.7/site-packages/airflow/models/dagbag.py", line 338, in parse
    loader.exec_module(new_module)
  File "<frozen importlib._bootstrap_external>", line 728, in exec_module
  File "<frozen importlib._bootstrap>", line 219, in _call_with_frames_removed
  File "/opt/airflow/dags/data_tools_final_oprator.py", line 13, in <module>
    import datatool_model
  File "/opt/airflow/plugins/datatool_model.py", line 106, in <module>
    preprocess = traffy.import_data()
  File "/opt/airflow/plugins/datatool_model.py", line 24, in import_data
    df = pd.read_csv('/Users/80524/Downloads/apache_airflow/data/traffy_fondue_data.csv')
  File "/home/airflow/.local/lib/python3.7/site-packages/pandas/util/_decorators.py", line 311, in wrapper
    return func(*args, **kwargs)
  File "/home/airflow/.local/lib/python3.7/site-packages/pandas/io/parsers/readers.py", line 586, in read_csv
    return _read(filepath_or_buffer, kwds)
  File "/home/airflow/.local/lib/python3.7/site-packages/pandas/io/parsers/readers.py", line 482, in _read
    parser = TextFileReader(filepath_or_buffer, **kwds)
  File "/home/airflow/.local/lib/python3.7/site-packages/pandas/io/parsers/readers.py", line 811, in __init__
    self._engine = self._make_engine(self.engine)
  File "/home/airflow/.local/lib/python3.7/site-packages/pandas/io/parsers/readers.py", line 1040, in _make_engine
    return mapping[engine](self.f, **self.options)  # type: ignore[call-arg]
  File "/home/airflow/.local/lib/python3.7/site-packages/pandas/io/parsers/c_parser_wrapper.py", line 51, in __init__
    self._open_handles(src, kwds)
  File "/home/airflow/.local/lib/python3.7/site-packages/pandas/io/parsers/base_parser.py", line 229, in _open_handles
    errors=kwds.get("encoding_errors", "strict"),
  File "/home/airflow/.local/lib/python3.7/site-packages/pandas/io/common.py", line 707, in get_handle
    newline="",
FileNotFoundError: [Errno 2] No such file or directory: '/Users/80524/Downloads/apache_airflow/data/traffy_fondue_data.csv'
[2022-12-11T04:26:10.408+0000] {processor.py:768} WARNING - No viable dags retrieved from /opt/airflow/dags/data_tools_final_oprator.py
[2022-12-11T04:26:10.420+0000] {processor.py:176} INFO - Processing /opt/airflow/dags/data_tools_final_oprator.py took 1.895 seconds
[2022-12-11T04:26:40.828+0000] {processor.py:154} INFO - Started process (PID=26567) to work on /opt/airflow/dags/data_tools_final_oprator.py
[2022-12-11T04:26:40.831+0000] {processor.py:756} INFO - Processing file /opt/airflow/dags/data_tools_final_oprator.py for tasks to queue
[2022-12-11T04:26:40.832+0000] {logging_mixin.py:137} INFO - [2022-12-11T04:26:40.832+0000] {dagbag.py:537} INFO - Filling up the DagBag from /opt/airflow/dags/data_tools_final_oprator.py
[2022-12-11T04:26:42.668+0000] {logging_mixin.py:137} INFO - [2022-12-11T04:26:42.664+0000] {dagbag.py:342} ERROR - Failed to import: /opt/airflow/dags/data_tools_final_oprator.py
Traceback (most recent call last):
  File "/home/airflow/.local/lib/python3.7/site-packages/airflow/models/dagbag.py", line 338, in parse
    loader.exec_module(new_module)
  File "<frozen importlib._bootstrap_external>", line 728, in exec_module
  File "<frozen importlib._bootstrap>", line 219, in _call_with_frames_removed
  File "/opt/airflow/dags/data_tools_final_oprator.py", line 13, in <module>
    import datatool_model
  File "/opt/airflow/plugins/datatool_model.py", line 106, in <module>
    preprocess = traffy.import_data()
  File "/opt/airflow/plugins/datatool_model.py", line 24, in import_data
    df = pd.read_csv('/Users/80524/Downloads/apache_airflow/data/traffy_fondue_data.csv')
  File "/home/airflow/.local/lib/python3.7/site-packages/pandas/util/_decorators.py", line 311, in wrapper
    return func(*args, **kwargs)
  File "/home/airflow/.local/lib/python3.7/site-packages/pandas/io/parsers/readers.py", line 586, in read_csv
    return _read(filepath_or_buffer, kwds)
  File "/home/airflow/.local/lib/python3.7/site-packages/pandas/io/parsers/readers.py", line 482, in _read
    parser = TextFileReader(filepath_or_buffer, **kwds)
  File "/home/airflow/.local/lib/python3.7/site-packages/pandas/io/parsers/readers.py", line 811, in __init__
    self._engine = self._make_engine(self.engine)
  File "/home/airflow/.local/lib/python3.7/site-packages/pandas/io/parsers/readers.py", line 1040, in _make_engine
    return mapping[engine](self.f, **self.options)  # type: ignore[call-arg]
  File "/home/airflow/.local/lib/python3.7/site-packages/pandas/io/parsers/c_parser_wrapper.py", line 51, in __init__
    self._open_handles(src, kwds)
  File "/home/airflow/.local/lib/python3.7/site-packages/pandas/io/parsers/base_parser.py", line 229, in _open_handles
    errors=kwds.get("encoding_errors", "strict"),
  File "/home/airflow/.local/lib/python3.7/site-packages/pandas/io/common.py", line 707, in get_handle
    newline="",
FileNotFoundError: [Errno 2] No such file or directory: '/Users/80524/Downloads/apache_airflow/data/traffy_fondue_data.csv'
[2022-12-11T04:26:42.670+0000] {processor.py:768} WARNING - No viable dags retrieved from /opt/airflow/dags/data_tools_final_oprator.py
[2022-12-11T04:26:42.681+0000] {processor.py:176} INFO - Processing /opt/airflow/dags/data_tools_final_oprator.py took 1.856 seconds
[2022-12-11T04:27:12.823+0000] {processor.py:154} INFO - Started process (PID=26596) to work on /opt/airflow/dags/data_tools_final_oprator.py
[2022-12-11T04:27:12.826+0000] {processor.py:756} INFO - Processing file /opt/airflow/dags/data_tools_final_oprator.py for tasks to queue
[2022-12-11T04:27:12.827+0000] {logging_mixin.py:137} INFO - [2022-12-11T04:27:12.827+0000] {dagbag.py:537} INFO - Filling up the DagBag from /opt/airflow/dags/data_tools_final_oprator.py
[2022-12-11T04:27:14.646+0000] {logging_mixin.py:137} INFO - [2022-12-11T04:27:14.642+0000] {dagbag.py:342} ERROR - Failed to import: /opt/airflow/dags/data_tools_final_oprator.py
Traceback (most recent call last):
  File "/home/airflow/.local/lib/python3.7/site-packages/airflow/models/dagbag.py", line 338, in parse
    loader.exec_module(new_module)
  File "<frozen importlib._bootstrap_external>", line 728, in exec_module
  File "<frozen importlib._bootstrap>", line 219, in _call_with_frames_removed
  File "/opt/airflow/dags/data_tools_final_oprator.py", line 13, in <module>
    import datatool_model
  File "/opt/airflow/plugins/datatool_model.py", line 106, in <module>
    preprocess = traffy.import_data()
  File "/opt/airflow/plugins/datatool_model.py", line 24, in import_data
    df = pd.read_csv('/Users/80524/Downloads/apache_airflow/data/traffy_fondue_data.csv')
  File "/home/airflow/.local/lib/python3.7/site-packages/pandas/util/_decorators.py", line 311, in wrapper
    return func(*args, **kwargs)
  File "/home/airflow/.local/lib/python3.7/site-packages/pandas/io/parsers/readers.py", line 586, in read_csv
    return _read(filepath_or_buffer, kwds)
  File "/home/airflow/.local/lib/python3.7/site-packages/pandas/io/parsers/readers.py", line 482, in _read
    parser = TextFileReader(filepath_or_buffer, **kwds)
  File "/home/airflow/.local/lib/python3.7/site-packages/pandas/io/parsers/readers.py", line 811, in __init__
    self._engine = self._make_engine(self.engine)
  File "/home/airflow/.local/lib/python3.7/site-packages/pandas/io/parsers/readers.py", line 1040, in _make_engine
    return mapping[engine](self.f, **self.options)  # type: ignore[call-arg]
  File "/home/airflow/.local/lib/python3.7/site-packages/pandas/io/parsers/c_parser_wrapper.py", line 51, in __init__
    self._open_handles(src, kwds)
  File "/home/airflow/.local/lib/python3.7/site-packages/pandas/io/parsers/base_parser.py", line 229, in _open_handles
    errors=kwds.get("encoding_errors", "strict"),
  File "/home/airflow/.local/lib/python3.7/site-packages/pandas/io/common.py", line 707, in get_handle
    newline="",
FileNotFoundError: [Errno 2] No such file or directory: '/Users/80524/Downloads/apache_airflow/data/traffy_fondue_data.csv'
[2022-12-11T04:27:14.647+0000] {processor.py:768} WARNING - No viable dags retrieved from /opt/airflow/dags/data_tools_final_oprator.py
[2022-12-11T04:27:14.657+0000] {processor.py:176} INFO - Processing /opt/airflow/dags/data_tools_final_oprator.py took 1.838 seconds
[2022-12-11T04:27:45.115+0000] {processor.py:154} INFO - Started process (PID=26626) to work on /opt/airflow/dags/data_tools_final_oprator.py
[2022-12-11T04:27:45.117+0000] {processor.py:756} INFO - Processing file /opt/airflow/dags/data_tools_final_oprator.py for tasks to queue
[2022-12-11T04:27:45.118+0000] {logging_mixin.py:137} INFO - [2022-12-11T04:27:45.118+0000] {dagbag.py:537} INFO - Filling up the DagBag from /opt/airflow/dags/data_tools_final_oprator.py
[2022-12-11T04:27:46.996+0000] {logging_mixin.py:137} INFO - [2022-12-11T04:27:46.992+0000] {dagbag.py:342} ERROR - Failed to import: /opt/airflow/dags/data_tools_final_oprator.py
Traceback (most recent call last):
  File "/home/airflow/.local/lib/python3.7/site-packages/airflow/models/dagbag.py", line 338, in parse
    loader.exec_module(new_module)
  File "<frozen importlib._bootstrap_external>", line 728, in exec_module
  File "<frozen importlib._bootstrap>", line 219, in _call_with_frames_removed
  File "/opt/airflow/dags/data_tools_final_oprator.py", line 13, in <module>
    import datatool_model
  File "/opt/airflow/plugins/datatool_model.py", line 106, in <module>
    preprocess = traffy.import_data()
  File "/opt/airflow/plugins/datatool_model.py", line 24, in import_data
    df = pd.read_csv('/Users/80524/Downloads/apache_airflow/data/traffy_fondue_data.csv')
  File "/home/airflow/.local/lib/python3.7/site-packages/pandas/util/_decorators.py", line 311, in wrapper
    return func(*args, **kwargs)
  File "/home/airflow/.local/lib/python3.7/site-packages/pandas/io/parsers/readers.py", line 586, in read_csv
    return _read(filepath_or_buffer, kwds)
  File "/home/airflow/.local/lib/python3.7/site-packages/pandas/io/parsers/readers.py", line 482, in _read
    parser = TextFileReader(filepath_or_buffer, **kwds)
  File "/home/airflow/.local/lib/python3.7/site-packages/pandas/io/parsers/readers.py", line 811, in __init__
    self._engine = self._make_engine(self.engine)
  File "/home/airflow/.local/lib/python3.7/site-packages/pandas/io/parsers/readers.py", line 1040, in _make_engine
    return mapping[engine](self.f, **self.options)  # type: ignore[call-arg]
  File "/home/airflow/.local/lib/python3.7/site-packages/pandas/io/parsers/c_parser_wrapper.py", line 51, in __init__
    self._open_handles(src, kwds)
  File "/home/airflow/.local/lib/python3.7/site-packages/pandas/io/parsers/base_parser.py", line 229, in _open_handles
    errors=kwds.get("encoding_errors", "strict"),
  File "/home/airflow/.local/lib/python3.7/site-packages/pandas/io/common.py", line 707, in get_handle
    newline="",
FileNotFoundError: [Errno 2] No such file or directory: '/Users/80524/Downloads/apache_airflow/data/traffy_fondue_data.csv'
[2022-12-11T04:27:46.997+0000] {processor.py:768} WARNING - No viable dags retrieved from /opt/airflow/dags/data_tools_final_oprator.py
[2022-12-11T04:27:47.012+0000] {processor.py:176} INFO - Processing /opt/airflow/dags/data_tools_final_oprator.py took 1.901 seconds
[2022-12-11T04:28:17.418+0000] {processor.py:154} INFO - Started process (PID=26655) to work on /opt/airflow/dags/data_tools_final_oprator.py
[2022-12-11T04:28:17.421+0000] {processor.py:756} INFO - Processing file /opt/airflow/dags/data_tools_final_oprator.py for tasks to queue
[2022-12-11T04:28:17.422+0000] {logging_mixin.py:137} INFO - [2022-12-11T04:28:17.422+0000] {dagbag.py:537} INFO - Filling up the DagBag from /opt/airflow/dags/data_tools_final_oprator.py
[2022-12-11T04:28:19.280+0000] {logging_mixin.py:137} INFO - [2022-12-11T04:28:19.276+0000] {dagbag.py:342} ERROR - Failed to import: /opt/airflow/dags/data_tools_final_oprator.py
Traceback (most recent call last):
  File "/home/airflow/.local/lib/python3.7/site-packages/airflow/models/dagbag.py", line 338, in parse
    loader.exec_module(new_module)
  File "<frozen importlib._bootstrap_external>", line 728, in exec_module
  File "<frozen importlib._bootstrap>", line 219, in _call_with_frames_removed
  File "/opt/airflow/dags/data_tools_final_oprator.py", line 13, in <module>
    import datatool_model
  File "/opt/airflow/plugins/datatool_model.py", line 106, in <module>
    preprocess = traffy.import_data()
  File "/opt/airflow/plugins/datatool_model.py", line 24, in import_data
    df = pd.read_csv('/Users/80524/Downloads/apache_airflow/data/traffy_fondue_data.csv')
  File "/home/airflow/.local/lib/python3.7/site-packages/pandas/util/_decorators.py", line 311, in wrapper
    return func(*args, **kwargs)
  File "/home/airflow/.local/lib/python3.7/site-packages/pandas/io/parsers/readers.py", line 586, in read_csv
    return _read(filepath_or_buffer, kwds)
  File "/home/airflow/.local/lib/python3.7/site-packages/pandas/io/parsers/readers.py", line 482, in _read
    parser = TextFileReader(filepath_or_buffer, **kwds)
  File "/home/airflow/.local/lib/python3.7/site-packages/pandas/io/parsers/readers.py", line 811, in __init__
    self._engine = self._make_engine(self.engine)
  File "/home/airflow/.local/lib/python3.7/site-packages/pandas/io/parsers/readers.py", line 1040, in _make_engine
    return mapping[engine](self.f, **self.options)  # type: ignore[call-arg]
  File "/home/airflow/.local/lib/python3.7/site-packages/pandas/io/parsers/c_parser_wrapper.py", line 51, in __init__
    self._open_handles(src, kwds)
  File "/home/airflow/.local/lib/python3.7/site-packages/pandas/io/parsers/base_parser.py", line 229, in _open_handles
    errors=kwds.get("encoding_errors", "strict"),
  File "/home/airflow/.local/lib/python3.7/site-packages/pandas/io/common.py", line 707, in get_handle
    newline="",
FileNotFoundError: [Errno 2] No such file or directory: '/Users/80524/Downloads/apache_airflow/data/traffy_fondue_data.csv'
[2022-12-11T04:28:19.282+0000] {processor.py:768} WARNING - No viable dags retrieved from /opt/airflow/dags/data_tools_final_oprator.py
[2022-12-11T04:28:19.294+0000] {processor.py:176} INFO - Processing /opt/airflow/dags/data_tools_final_oprator.py took 1.879 seconds
[2022-12-11T04:28:49.657+0000] {processor.py:154} INFO - Started process (PID=26684) to work on /opt/airflow/dags/data_tools_final_oprator.py
[2022-12-11T04:28:49.659+0000] {processor.py:756} INFO - Processing file /opt/airflow/dags/data_tools_final_oprator.py for tasks to queue
[2022-12-11T04:28:49.661+0000] {logging_mixin.py:137} INFO - [2022-12-11T04:28:49.661+0000] {dagbag.py:537} INFO - Filling up the DagBag from /opt/airflow/dags/data_tools_final_oprator.py
[2022-12-11T04:28:51.485+0000] {logging_mixin.py:137} INFO - [2022-12-11T04:28:51.481+0000] {dagbag.py:342} ERROR - Failed to import: /opt/airflow/dags/data_tools_final_oprator.py
Traceback (most recent call last):
  File "/home/airflow/.local/lib/python3.7/site-packages/airflow/models/dagbag.py", line 338, in parse
    loader.exec_module(new_module)
  File "<frozen importlib._bootstrap_external>", line 728, in exec_module
  File "<frozen importlib._bootstrap>", line 219, in _call_with_frames_removed
  File "/opt/airflow/dags/data_tools_final_oprator.py", line 13, in <module>
    import datatool_model
  File "/opt/airflow/plugins/datatool_model.py", line 106, in <module>
    preprocess = traffy.import_data()
  File "/opt/airflow/plugins/datatool_model.py", line 24, in import_data
    df = pd.read_csv('/Users/80524/Downloads/apache_airflow/data/traffy_fondue_data.csv')
  File "/home/airflow/.local/lib/python3.7/site-packages/pandas/util/_decorators.py", line 311, in wrapper
    return func(*args, **kwargs)
  File "/home/airflow/.local/lib/python3.7/site-packages/pandas/io/parsers/readers.py", line 586, in read_csv
    return _read(filepath_or_buffer, kwds)
  File "/home/airflow/.local/lib/python3.7/site-packages/pandas/io/parsers/readers.py", line 482, in _read
    parser = TextFileReader(filepath_or_buffer, **kwds)
  File "/home/airflow/.local/lib/python3.7/site-packages/pandas/io/parsers/readers.py", line 811, in __init__
    self._engine = self._make_engine(self.engine)
  File "/home/airflow/.local/lib/python3.7/site-packages/pandas/io/parsers/readers.py", line 1040, in _make_engine
    return mapping[engine](self.f, **self.options)  # type: ignore[call-arg]
  File "/home/airflow/.local/lib/python3.7/site-packages/pandas/io/parsers/c_parser_wrapper.py", line 51, in __init__
    self._open_handles(src, kwds)
  File "/home/airflow/.local/lib/python3.7/site-packages/pandas/io/parsers/base_parser.py", line 229, in _open_handles
    errors=kwds.get("encoding_errors", "strict"),
  File "/home/airflow/.local/lib/python3.7/site-packages/pandas/io/common.py", line 707, in get_handle
    newline="",
FileNotFoundError: [Errno 2] No such file or directory: '/Users/80524/Downloads/apache_airflow/data/traffy_fondue_data.csv'
[2022-12-11T04:28:51.486+0000] {processor.py:768} WARNING - No viable dags retrieved from /opt/airflow/dags/data_tools_final_oprator.py
[2022-12-11T04:28:51.497+0000] {processor.py:176} INFO - Processing /opt/airflow/dags/data_tools_final_oprator.py took 1.844 seconds
[2022-12-11T04:29:21.864+0000] {processor.py:154} INFO - Started process (PID=26713) to work on /opt/airflow/dags/data_tools_final_oprator.py
[2022-12-11T04:29:21.866+0000] {processor.py:756} INFO - Processing file /opt/airflow/dags/data_tools_final_oprator.py for tasks to queue
[2022-12-11T04:29:21.867+0000] {logging_mixin.py:137} INFO - [2022-12-11T04:29:21.867+0000] {dagbag.py:537} INFO - Filling up the DagBag from /opt/airflow/dags/data_tools_final_oprator.py
[2022-12-11T04:29:23.675+0000] {logging_mixin.py:137} INFO - [2022-12-11T04:29:23.671+0000] {dagbag.py:342} ERROR - Failed to import: /opt/airflow/dags/data_tools_final_oprator.py
Traceback (most recent call last):
  File "/home/airflow/.local/lib/python3.7/site-packages/airflow/models/dagbag.py", line 338, in parse
    loader.exec_module(new_module)
  File "<frozen importlib._bootstrap_external>", line 728, in exec_module
  File "<frozen importlib._bootstrap>", line 219, in _call_with_frames_removed
  File "/opt/airflow/dags/data_tools_final_oprator.py", line 13, in <module>
    import datatool_model
  File "/opt/airflow/plugins/datatool_model.py", line 106, in <module>
    preprocess = traffy.import_data()
  File "/opt/airflow/plugins/datatool_model.py", line 24, in import_data
    df = pd.read_csv('/Users/80524/Downloads/apache_airflow/data/traffy_fondue_data.csv')
  File "/home/airflow/.local/lib/python3.7/site-packages/pandas/util/_decorators.py", line 311, in wrapper
    return func(*args, **kwargs)
  File "/home/airflow/.local/lib/python3.7/site-packages/pandas/io/parsers/readers.py", line 586, in read_csv
    return _read(filepath_or_buffer, kwds)
  File "/home/airflow/.local/lib/python3.7/site-packages/pandas/io/parsers/readers.py", line 482, in _read
    parser = TextFileReader(filepath_or_buffer, **kwds)
  File "/home/airflow/.local/lib/python3.7/site-packages/pandas/io/parsers/readers.py", line 811, in __init__
    self._engine = self._make_engine(self.engine)
  File "/home/airflow/.local/lib/python3.7/site-packages/pandas/io/parsers/readers.py", line 1040, in _make_engine
    return mapping[engine](self.f, **self.options)  # type: ignore[call-arg]
  File "/home/airflow/.local/lib/python3.7/site-packages/pandas/io/parsers/c_parser_wrapper.py", line 51, in __init__
    self._open_handles(src, kwds)
  File "/home/airflow/.local/lib/python3.7/site-packages/pandas/io/parsers/base_parser.py", line 229, in _open_handles
    errors=kwds.get("encoding_errors", "strict"),
  File "/home/airflow/.local/lib/python3.7/site-packages/pandas/io/common.py", line 707, in get_handle
    newline="",
FileNotFoundError: [Errno 2] No such file or directory: '/Users/80524/Downloads/apache_airflow/data/traffy_fondue_data.csv'
[2022-12-11T04:29:23.676+0000] {processor.py:768} WARNING - No viable dags retrieved from /opt/airflow/dags/data_tools_final_oprator.py
[2022-12-11T04:29:23.687+0000] {processor.py:176} INFO - Processing /opt/airflow/dags/data_tools_final_oprator.py took 1.827 seconds
[2022-12-11T04:29:54.096+0000] {processor.py:154} INFO - Started process (PID=26742) to work on /opt/airflow/dags/data_tools_final_oprator.py
[2022-12-11T04:29:54.097+0000] {processor.py:756} INFO - Processing file /opt/airflow/dags/data_tools_final_oprator.py for tasks to queue
[2022-12-11T04:29:54.098+0000] {logging_mixin.py:137} INFO - [2022-12-11T04:29:54.098+0000] {dagbag.py:537} INFO - Filling up the DagBag from /opt/airflow/dags/data_tools_final_oprator.py
[2022-12-11T04:29:55.941+0000] {logging_mixin.py:137} INFO - [2022-12-11T04:29:55.935+0000] {dagbag.py:342} ERROR - Failed to import: /opt/airflow/dags/data_tools_final_oprator.py
Traceback (most recent call last):
  File "/home/airflow/.local/lib/python3.7/site-packages/airflow/models/dagbag.py", line 338, in parse
    loader.exec_module(new_module)
  File "<frozen importlib._bootstrap_external>", line 728, in exec_module
  File "<frozen importlib._bootstrap>", line 219, in _call_with_frames_removed
  File "/opt/airflow/dags/data_tools_final_oprator.py", line 13, in <module>
    import datatool_model
  File "/opt/airflow/plugins/datatool_model.py", line 106, in <module>
    preprocess = traffy.import_data()
  File "/opt/airflow/plugins/datatool_model.py", line 24, in import_data
    df = pd.read_csv('/Users/80524/Downloads/apache_airflow/data/traffy_fondue_data.csv')
  File "/home/airflow/.local/lib/python3.7/site-packages/pandas/util/_decorators.py", line 311, in wrapper
    return func(*args, **kwargs)
  File "/home/airflow/.local/lib/python3.7/site-packages/pandas/io/parsers/readers.py", line 586, in read_csv
    return _read(filepath_or_buffer, kwds)
  File "/home/airflow/.local/lib/python3.7/site-packages/pandas/io/parsers/readers.py", line 482, in _read
    parser = TextFileReader(filepath_or_buffer, **kwds)
  File "/home/airflow/.local/lib/python3.7/site-packages/pandas/io/parsers/readers.py", line 811, in __init__
    self._engine = self._make_engine(self.engine)
  File "/home/airflow/.local/lib/python3.7/site-packages/pandas/io/parsers/readers.py", line 1040, in _make_engine
    return mapping[engine](self.f, **self.options)  # type: ignore[call-arg]
  File "/home/airflow/.local/lib/python3.7/site-packages/pandas/io/parsers/c_parser_wrapper.py", line 51, in __init__
    self._open_handles(src, kwds)
  File "/home/airflow/.local/lib/python3.7/site-packages/pandas/io/parsers/base_parser.py", line 229, in _open_handles
    errors=kwds.get("encoding_errors", "strict"),
  File "/home/airflow/.local/lib/python3.7/site-packages/pandas/io/common.py", line 707, in get_handle
    newline="",
FileNotFoundError: [Errno 2] No such file or directory: '/Users/80524/Downloads/apache_airflow/data/traffy_fondue_data.csv'
[2022-12-11T04:29:55.943+0000] {processor.py:768} WARNING - No viable dags retrieved from /opt/airflow/dags/data_tools_final_oprator.py
[2022-12-11T04:29:55.954+0000] {processor.py:176} INFO - Processing /opt/airflow/dags/data_tools_final_oprator.py took 1.861 seconds
[2022-12-11T04:30:26.304+0000] {processor.py:154} INFO - Started process (PID=26771) to work on /opt/airflow/dags/data_tools_final_oprator.py
[2022-12-11T04:30:26.306+0000] {processor.py:756} INFO - Processing file /opt/airflow/dags/data_tools_final_oprator.py for tasks to queue
[2022-12-11T04:30:26.308+0000] {logging_mixin.py:137} INFO - [2022-12-11T04:30:26.308+0000] {dagbag.py:537} INFO - Filling up the DagBag from /opt/airflow/dags/data_tools_final_oprator.py
[2022-12-11T04:30:28.178+0000] {logging_mixin.py:137} INFO - [2022-12-11T04:30:28.174+0000] {dagbag.py:342} ERROR - Failed to import: /opt/airflow/dags/data_tools_final_oprator.py
Traceback (most recent call last):
  File "/home/airflow/.local/lib/python3.7/site-packages/airflow/models/dagbag.py", line 338, in parse
    loader.exec_module(new_module)
  File "<frozen importlib._bootstrap_external>", line 728, in exec_module
  File "<frozen importlib._bootstrap>", line 219, in _call_with_frames_removed
  File "/opt/airflow/dags/data_tools_final_oprator.py", line 13, in <module>
    import datatool_model
  File "/opt/airflow/plugins/datatool_model.py", line 106, in <module>
    preprocess = traffy.import_data()
  File "/opt/airflow/plugins/datatool_model.py", line 24, in import_data
    df = pd.read_csv('/Users/80524/Downloads/apache_airflow/data/traffy_fondue_data.csv')
  File "/home/airflow/.local/lib/python3.7/site-packages/pandas/util/_decorators.py", line 311, in wrapper
    return func(*args, **kwargs)
  File "/home/airflow/.local/lib/python3.7/site-packages/pandas/io/parsers/readers.py", line 586, in read_csv
    return _read(filepath_or_buffer, kwds)
  File "/home/airflow/.local/lib/python3.7/site-packages/pandas/io/parsers/readers.py", line 482, in _read
    parser = TextFileReader(filepath_or_buffer, **kwds)
  File "/home/airflow/.local/lib/python3.7/site-packages/pandas/io/parsers/readers.py", line 811, in __init__
    self._engine = self._make_engine(self.engine)
  File "/home/airflow/.local/lib/python3.7/site-packages/pandas/io/parsers/readers.py", line 1040, in _make_engine
    return mapping[engine](self.f, **self.options)  # type: ignore[call-arg]
  File "/home/airflow/.local/lib/python3.7/site-packages/pandas/io/parsers/c_parser_wrapper.py", line 51, in __init__
    self._open_handles(src, kwds)
  File "/home/airflow/.local/lib/python3.7/site-packages/pandas/io/parsers/base_parser.py", line 229, in _open_handles
    errors=kwds.get("encoding_errors", "strict"),
  File "/home/airflow/.local/lib/python3.7/site-packages/pandas/io/common.py", line 707, in get_handle
    newline="",
FileNotFoundError: [Errno 2] No such file or directory: '/Users/80524/Downloads/apache_airflow/data/traffy_fondue_data.csv'
[2022-12-11T04:30:28.179+0000] {processor.py:768} WARNING - No viable dags retrieved from /opt/airflow/dags/data_tools_final_oprator.py
[2022-12-11T04:30:28.190+0000] {processor.py:176} INFO - Processing /opt/airflow/dags/data_tools_final_oprator.py took 1.891 seconds
[2022-12-11T04:30:58.588+0000] {processor.py:154} INFO - Started process (PID=26799) to work on /opt/airflow/dags/data_tools_final_oprator.py
[2022-12-11T04:30:58.589+0000] {processor.py:756} INFO - Processing file /opt/airflow/dags/data_tools_final_oprator.py for tasks to queue
[2022-12-11T04:30:58.591+0000] {logging_mixin.py:137} INFO - [2022-12-11T04:30:58.591+0000] {dagbag.py:537} INFO - Filling up the DagBag from /opt/airflow/dags/data_tools_final_oprator.py
[2022-12-11T04:31:00.490+0000] {logging_mixin.py:137} INFO - [2022-12-11T04:31:00.486+0000] {dagbag.py:342} ERROR - Failed to import: /opt/airflow/dags/data_tools_final_oprator.py
Traceback (most recent call last):
  File "/home/airflow/.local/lib/python3.7/site-packages/airflow/models/dagbag.py", line 338, in parse
    loader.exec_module(new_module)
  File "<frozen importlib._bootstrap_external>", line 728, in exec_module
  File "<frozen importlib._bootstrap>", line 219, in _call_with_frames_removed
  File "/opt/airflow/dags/data_tools_final_oprator.py", line 13, in <module>
    import datatool_model
  File "/opt/airflow/plugins/datatool_model.py", line 106, in <module>
    preprocess = traffy.import_data()
  File "/opt/airflow/plugins/datatool_model.py", line 24, in import_data
    df = pd.read_csv('/Users/80524/Downloads/apache_airflow/data/traffy_fondue_data.csv')
  File "/home/airflow/.local/lib/python3.7/site-packages/pandas/util/_decorators.py", line 311, in wrapper
    return func(*args, **kwargs)
  File "/home/airflow/.local/lib/python3.7/site-packages/pandas/io/parsers/readers.py", line 586, in read_csv
    return _read(filepath_or_buffer, kwds)
  File "/home/airflow/.local/lib/python3.7/site-packages/pandas/io/parsers/readers.py", line 482, in _read
    parser = TextFileReader(filepath_or_buffer, **kwds)
  File "/home/airflow/.local/lib/python3.7/site-packages/pandas/io/parsers/readers.py", line 811, in __init__
    self._engine = self._make_engine(self.engine)
  File "/home/airflow/.local/lib/python3.7/site-packages/pandas/io/parsers/readers.py", line 1040, in _make_engine
    return mapping[engine](self.f, **self.options)  # type: ignore[call-arg]
  File "/home/airflow/.local/lib/python3.7/site-packages/pandas/io/parsers/c_parser_wrapper.py", line 51, in __init__
    self._open_handles(src, kwds)
  File "/home/airflow/.local/lib/python3.7/site-packages/pandas/io/parsers/base_parser.py", line 229, in _open_handles
    errors=kwds.get("encoding_errors", "strict"),
  File "/home/airflow/.local/lib/python3.7/site-packages/pandas/io/common.py", line 707, in get_handle
    newline="",
FileNotFoundError: [Errno 2] No such file or directory: '/Users/80524/Downloads/apache_airflow/data/traffy_fondue_data.csv'
[2022-12-11T04:31:00.491+0000] {processor.py:768} WARNING - No viable dags retrieved from /opt/airflow/dags/data_tools_final_oprator.py
[2022-12-11T04:31:00.501+0000] {processor.py:176} INFO - Processing /opt/airflow/dags/data_tools_final_oprator.py took 1.918 seconds
[2022-12-11T04:31:31.008+0000] {processor.py:154} INFO - Started process (PID=26829) to work on /opt/airflow/dags/data_tools_final_oprator.py
[2022-12-11T04:31:31.010+0000] {processor.py:756} INFO - Processing file /opt/airflow/dags/data_tools_final_oprator.py for tasks to queue
[2022-12-11T04:31:31.013+0000] {logging_mixin.py:137} INFO - [2022-12-11T04:31:31.013+0000] {dagbag.py:537} INFO - Filling up the DagBag from /opt/airflow/dags/data_tools_final_oprator.py
[2022-12-11T04:31:32.873+0000] {logging_mixin.py:137} INFO - [2022-12-11T04:31:32.869+0000] {dagbag.py:342} ERROR - Failed to import: /opt/airflow/dags/data_tools_final_oprator.py
Traceback (most recent call last):
  File "/home/airflow/.local/lib/python3.7/site-packages/airflow/models/dagbag.py", line 338, in parse
    loader.exec_module(new_module)
  File "<frozen importlib._bootstrap_external>", line 728, in exec_module
  File "<frozen importlib._bootstrap>", line 219, in _call_with_frames_removed
  File "/opt/airflow/dags/data_tools_final_oprator.py", line 13, in <module>
    import datatool_model
  File "/opt/airflow/plugins/datatool_model.py", line 106, in <module>
    preprocess = traffy.import_data()
  File "/opt/airflow/plugins/datatool_model.py", line 24, in import_data
    df = pd.read_csv('/Users/80524/Downloads/apache_airflow/data/traffy_fondue_data.csv')
  File "/home/airflow/.local/lib/python3.7/site-packages/pandas/util/_decorators.py", line 311, in wrapper
    return func(*args, **kwargs)
  File "/home/airflow/.local/lib/python3.7/site-packages/pandas/io/parsers/readers.py", line 586, in read_csv
    return _read(filepath_or_buffer, kwds)
  File "/home/airflow/.local/lib/python3.7/site-packages/pandas/io/parsers/readers.py", line 482, in _read
    parser = TextFileReader(filepath_or_buffer, **kwds)
  File "/home/airflow/.local/lib/python3.7/site-packages/pandas/io/parsers/readers.py", line 811, in __init__
    self._engine = self._make_engine(self.engine)
  File "/home/airflow/.local/lib/python3.7/site-packages/pandas/io/parsers/readers.py", line 1040, in _make_engine
    return mapping[engine](self.f, **self.options)  # type: ignore[call-arg]
  File "/home/airflow/.local/lib/python3.7/site-packages/pandas/io/parsers/c_parser_wrapper.py", line 51, in __init__
    self._open_handles(src, kwds)
  File "/home/airflow/.local/lib/python3.7/site-packages/pandas/io/parsers/base_parser.py", line 229, in _open_handles
    errors=kwds.get("encoding_errors", "strict"),
  File "/home/airflow/.local/lib/python3.7/site-packages/pandas/io/common.py", line 707, in get_handle
    newline="",
FileNotFoundError: [Errno 2] No such file or directory: '/Users/80524/Downloads/apache_airflow/data/traffy_fondue_data.csv'
[2022-12-11T04:31:32.874+0000] {processor.py:768} WARNING - No viable dags retrieved from /opt/airflow/dags/data_tools_final_oprator.py
[2022-12-11T04:31:32.885+0000] {processor.py:176} INFO - Processing /opt/airflow/dags/data_tools_final_oprator.py took 1.881 seconds
[2022-12-11T04:32:03.303+0000] {processor.py:154} INFO - Started process (PID=26858) to work on /opt/airflow/dags/data_tools_final_oprator.py
[2022-12-11T04:32:03.306+0000] {processor.py:756} INFO - Processing file /opt/airflow/dags/data_tools_final_oprator.py for tasks to queue
[2022-12-11T04:32:03.307+0000] {logging_mixin.py:137} INFO - [2022-12-11T04:32:03.307+0000] {dagbag.py:537} INFO - Filling up the DagBag from /opt/airflow/dags/data_tools_final_oprator.py
[2022-12-11T04:32:05.160+0000] {logging_mixin.py:137} INFO - [2022-12-11T04:32:05.156+0000] {dagbag.py:342} ERROR - Failed to import: /opt/airflow/dags/data_tools_final_oprator.py
Traceback (most recent call last):
  File "/home/airflow/.local/lib/python3.7/site-packages/airflow/models/dagbag.py", line 338, in parse
    loader.exec_module(new_module)
  File "<frozen importlib._bootstrap_external>", line 728, in exec_module
  File "<frozen importlib._bootstrap>", line 219, in _call_with_frames_removed
  File "/opt/airflow/dags/data_tools_final_oprator.py", line 13, in <module>
    import datatool_model
  File "/opt/airflow/plugins/datatool_model.py", line 106, in <module>
    preprocess = traffy.import_data()
  File "/opt/airflow/plugins/datatool_model.py", line 24, in import_data
    df = pd.read_csv('/Users/80524/Downloads/apache_airflow/data/traffy_fondue_data.csv')
  File "/home/airflow/.local/lib/python3.7/site-packages/pandas/util/_decorators.py", line 311, in wrapper
    return func(*args, **kwargs)
  File "/home/airflow/.local/lib/python3.7/site-packages/pandas/io/parsers/readers.py", line 586, in read_csv
    return _read(filepath_or_buffer, kwds)
  File "/home/airflow/.local/lib/python3.7/site-packages/pandas/io/parsers/readers.py", line 482, in _read
    parser = TextFileReader(filepath_or_buffer, **kwds)
  File "/home/airflow/.local/lib/python3.7/site-packages/pandas/io/parsers/readers.py", line 811, in __init__
    self._engine = self._make_engine(self.engine)
  File "/home/airflow/.local/lib/python3.7/site-packages/pandas/io/parsers/readers.py", line 1040, in _make_engine
    return mapping[engine](self.f, **self.options)  # type: ignore[call-arg]
  File "/home/airflow/.local/lib/python3.7/site-packages/pandas/io/parsers/c_parser_wrapper.py", line 51, in __init__
    self._open_handles(src, kwds)
  File "/home/airflow/.local/lib/python3.7/site-packages/pandas/io/parsers/base_parser.py", line 229, in _open_handles
    errors=kwds.get("encoding_errors", "strict"),
  File "/home/airflow/.local/lib/python3.7/site-packages/pandas/io/common.py", line 707, in get_handle
    newline="",
FileNotFoundError: [Errno 2] No such file or directory: '/Users/80524/Downloads/apache_airflow/data/traffy_fondue_data.csv'
[2022-12-11T04:32:05.162+0000] {processor.py:768} WARNING - No viable dags retrieved from /opt/airflow/dags/data_tools_final_oprator.py
[2022-12-11T04:32:05.173+0000] {processor.py:176} INFO - Processing /opt/airflow/dags/data_tools_final_oprator.py took 1.874 seconds
[2022-12-11T04:32:35.560+0000] {processor.py:154} INFO - Started process (PID=26887) to work on /opt/airflow/dags/data_tools_final_oprator.py
[2022-12-11T04:32:35.562+0000] {processor.py:756} INFO - Processing file /opt/airflow/dags/data_tools_final_oprator.py for tasks to queue
[2022-12-11T04:32:35.562+0000] {logging_mixin.py:137} INFO - [2022-12-11T04:32:35.562+0000] {dagbag.py:537} INFO - Filling up the DagBag from /opt/airflow/dags/data_tools_final_oprator.py
[2022-12-11T04:32:37.458+0000] {logging_mixin.py:137} INFO - [2022-12-11T04:32:37.453+0000] {dagbag.py:342} ERROR - Failed to import: /opt/airflow/dags/data_tools_final_oprator.py
Traceback (most recent call last):
  File "/home/airflow/.local/lib/python3.7/site-packages/airflow/models/dagbag.py", line 338, in parse
    loader.exec_module(new_module)
  File "<frozen importlib._bootstrap_external>", line 728, in exec_module
  File "<frozen importlib._bootstrap>", line 219, in _call_with_frames_removed
  File "/opt/airflow/dags/data_tools_final_oprator.py", line 13, in <module>
    import datatool_model
  File "/opt/airflow/plugins/datatool_model.py", line 106, in <module>
    preprocess = traffy.import_data()
  File "/opt/airflow/plugins/datatool_model.py", line 24, in import_data
    df = pd.read_csv('/Users/80524/Downloads/apache_airflow/data/traffy_fondue_data.csv')
  File "/home/airflow/.local/lib/python3.7/site-packages/pandas/util/_decorators.py", line 311, in wrapper
    return func(*args, **kwargs)
  File "/home/airflow/.local/lib/python3.7/site-packages/pandas/io/parsers/readers.py", line 586, in read_csv
    return _read(filepath_or_buffer, kwds)
  File "/home/airflow/.local/lib/python3.7/site-packages/pandas/io/parsers/readers.py", line 482, in _read
    parser = TextFileReader(filepath_or_buffer, **kwds)
  File "/home/airflow/.local/lib/python3.7/site-packages/pandas/io/parsers/readers.py", line 811, in __init__
    self._engine = self._make_engine(self.engine)
  File "/home/airflow/.local/lib/python3.7/site-packages/pandas/io/parsers/readers.py", line 1040, in _make_engine
    return mapping[engine](self.f, **self.options)  # type: ignore[call-arg]
  File "/home/airflow/.local/lib/python3.7/site-packages/pandas/io/parsers/c_parser_wrapper.py", line 51, in __init__
    self._open_handles(src, kwds)
  File "/home/airflow/.local/lib/python3.7/site-packages/pandas/io/parsers/base_parser.py", line 229, in _open_handles
    errors=kwds.get("encoding_errors", "strict"),
  File "/home/airflow/.local/lib/python3.7/site-packages/pandas/io/common.py", line 707, in get_handle
    newline="",
FileNotFoundError: [Errno 2] No such file or directory: '/Users/80524/Downloads/apache_airflow/data/traffy_fondue_data.csv'
[2022-12-11T04:32:37.460+0000] {processor.py:768} WARNING - No viable dags retrieved from /opt/airflow/dags/data_tools_final_oprator.py
[2022-12-11T04:32:37.471+0000] {processor.py:176} INFO - Processing /opt/airflow/dags/data_tools_final_oprator.py took 1.914 seconds
[2022-12-11T04:33:07.865+0000] {processor.py:154} INFO - Started process (PID=26917) to work on /opt/airflow/dags/data_tools_final_oprator.py
[2022-12-11T04:33:07.867+0000] {processor.py:756} INFO - Processing file /opt/airflow/dags/data_tools_final_oprator.py for tasks to queue
[2022-12-11T04:33:07.869+0000] {logging_mixin.py:137} INFO - [2022-12-11T04:33:07.868+0000] {dagbag.py:537} INFO - Filling up the DagBag from /opt/airflow/dags/data_tools_final_oprator.py
[2022-12-11T04:33:09.771+0000] {logging_mixin.py:137} INFO - [2022-12-11T04:33:09.766+0000] {dagbag.py:342} ERROR - Failed to import: /opt/airflow/dags/data_tools_final_oprator.py
Traceback (most recent call last):
  File "/home/airflow/.local/lib/python3.7/site-packages/airflow/models/dagbag.py", line 338, in parse
    loader.exec_module(new_module)
  File "<frozen importlib._bootstrap_external>", line 728, in exec_module
  File "<frozen importlib._bootstrap>", line 219, in _call_with_frames_removed
  File "/opt/airflow/dags/data_tools_final_oprator.py", line 13, in <module>
    import datatool_model
  File "/opt/airflow/plugins/datatool_model.py", line 106, in <module>
    preprocess = traffy.import_data()
  File "/opt/airflow/plugins/datatool_model.py", line 24, in import_data
    df = pd.read_csv('/Users/80524/Downloads/apache_airflow/data/traffy_fondue_data.csv')
  File "/home/airflow/.local/lib/python3.7/site-packages/pandas/util/_decorators.py", line 311, in wrapper
    return func(*args, **kwargs)
  File "/home/airflow/.local/lib/python3.7/site-packages/pandas/io/parsers/readers.py", line 586, in read_csv
    return _read(filepath_or_buffer, kwds)
  File "/home/airflow/.local/lib/python3.7/site-packages/pandas/io/parsers/readers.py", line 482, in _read
    parser = TextFileReader(filepath_or_buffer, **kwds)
  File "/home/airflow/.local/lib/python3.7/site-packages/pandas/io/parsers/readers.py", line 811, in __init__
    self._engine = self._make_engine(self.engine)
  File "/home/airflow/.local/lib/python3.7/site-packages/pandas/io/parsers/readers.py", line 1040, in _make_engine
    return mapping[engine](self.f, **self.options)  # type: ignore[call-arg]
  File "/home/airflow/.local/lib/python3.7/site-packages/pandas/io/parsers/c_parser_wrapper.py", line 51, in __init__
    self._open_handles(src, kwds)
  File "/home/airflow/.local/lib/python3.7/site-packages/pandas/io/parsers/base_parser.py", line 229, in _open_handles
    errors=kwds.get("encoding_errors", "strict"),
  File "/home/airflow/.local/lib/python3.7/site-packages/pandas/io/common.py", line 707, in get_handle
    newline="",
FileNotFoundError: [Errno 2] No such file or directory: '/Users/80524/Downloads/apache_airflow/data/traffy_fondue_data.csv'
[2022-12-11T04:33:09.772+0000] {processor.py:768} WARNING - No viable dags retrieved from /opt/airflow/dags/data_tools_final_oprator.py
[2022-12-11T04:33:09.782+0000] {processor.py:176} INFO - Processing /opt/airflow/dags/data_tools_final_oprator.py took 1.920 seconds
[2022-12-11T04:33:40.184+0000] {processor.py:154} INFO - Started process (PID=26944) to work on /opt/airflow/dags/data_tools_final_oprator.py
[2022-12-11T04:33:40.186+0000] {processor.py:756} INFO - Processing file /opt/airflow/dags/data_tools_final_oprator.py for tasks to queue
[2022-12-11T04:33:40.187+0000] {logging_mixin.py:137} INFO - [2022-12-11T04:33:40.187+0000] {dagbag.py:537} INFO - Filling up the DagBag from /opt/airflow/dags/data_tools_final_oprator.py
[2022-12-11T04:33:42.114+0000] {logging_mixin.py:137} INFO - [2022-12-11T04:33:42.111+0000] {dagbag.py:342} ERROR - Failed to import: /opt/airflow/dags/data_tools_final_oprator.py
Traceback (most recent call last):
  File "/home/airflow/.local/lib/python3.7/site-packages/airflow/models/dagbag.py", line 338, in parse
    loader.exec_module(new_module)
  File "<frozen importlib._bootstrap_external>", line 728, in exec_module
  File "<frozen importlib._bootstrap>", line 219, in _call_with_frames_removed
  File "/opt/airflow/dags/data_tools_final_oprator.py", line 13, in <module>
    import datatool_model
  File "/opt/airflow/plugins/datatool_model.py", line 106, in <module>
    preprocess = traffy.import_data()
  File "/opt/airflow/plugins/datatool_model.py", line 24, in import_data
    df = pd.read_csv('/Users/80524/Downloads/apache_airflow/data/traffy_fondue_data.csv')
  File "/home/airflow/.local/lib/python3.7/site-packages/pandas/util/_decorators.py", line 311, in wrapper
    return func(*args, **kwargs)
  File "/home/airflow/.local/lib/python3.7/site-packages/pandas/io/parsers/readers.py", line 586, in read_csv
    return _read(filepath_or_buffer, kwds)
  File "/home/airflow/.local/lib/python3.7/site-packages/pandas/io/parsers/readers.py", line 482, in _read
    parser = TextFileReader(filepath_or_buffer, **kwds)
  File "/home/airflow/.local/lib/python3.7/site-packages/pandas/io/parsers/readers.py", line 811, in __init__
    self._engine = self._make_engine(self.engine)
  File "/home/airflow/.local/lib/python3.7/site-packages/pandas/io/parsers/readers.py", line 1040, in _make_engine
    return mapping[engine](self.f, **self.options)  # type: ignore[call-arg]
  File "/home/airflow/.local/lib/python3.7/site-packages/pandas/io/parsers/c_parser_wrapper.py", line 51, in __init__
    self._open_handles(src, kwds)
  File "/home/airflow/.local/lib/python3.7/site-packages/pandas/io/parsers/base_parser.py", line 229, in _open_handles
    errors=kwds.get("encoding_errors", "strict"),
  File "/home/airflow/.local/lib/python3.7/site-packages/pandas/io/common.py", line 707, in get_handle
    newline="",
FileNotFoundError: [Errno 2] No such file or directory: '/Users/80524/Downloads/apache_airflow/data/traffy_fondue_data.csv'
[2022-12-11T04:33:42.117+0000] {processor.py:768} WARNING - No viable dags retrieved from /opt/airflow/dags/data_tools_final_oprator.py
[2022-12-11T04:33:42.127+0000] {processor.py:176} INFO - Processing /opt/airflow/dags/data_tools_final_oprator.py took 1.946 seconds
[2022-12-11T04:34:12.513+0000] {processor.py:154} INFO - Started process (PID=26974) to work on /opt/airflow/dags/data_tools_final_oprator.py
[2022-12-11T04:34:12.514+0000] {processor.py:756} INFO - Processing file /opt/airflow/dags/data_tools_final_oprator.py for tasks to queue
[2022-12-11T04:34:12.516+0000] {logging_mixin.py:137} INFO - [2022-12-11T04:34:12.516+0000] {dagbag.py:537} INFO - Filling up the DagBag from /opt/airflow/dags/data_tools_final_oprator.py
[2022-12-11T04:34:14.447+0000] {logging_mixin.py:137} INFO - [2022-12-11T04:34:14.442+0000] {dagbag.py:342} ERROR - Failed to import: /opt/airflow/dags/data_tools_final_oprator.py
Traceback (most recent call last):
  File "/home/airflow/.local/lib/python3.7/site-packages/airflow/models/dagbag.py", line 338, in parse
    loader.exec_module(new_module)
  File "<frozen importlib._bootstrap_external>", line 728, in exec_module
  File "<frozen importlib._bootstrap>", line 219, in _call_with_frames_removed
  File "/opt/airflow/dags/data_tools_final_oprator.py", line 13, in <module>
    import datatool_model
  File "/opt/airflow/plugins/datatool_model.py", line 106, in <module>
    preprocess = traffy.import_data()
  File "/opt/airflow/plugins/datatool_model.py", line 24, in import_data
    df = pd.read_csv('/Users/80524/Downloads/apache_airflow/data/traffy_fondue_data.csv')
  File "/home/airflow/.local/lib/python3.7/site-packages/pandas/util/_decorators.py", line 311, in wrapper
    return func(*args, **kwargs)
  File "/home/airflow/.local/lib/python3.7/site-packages/pandas/io/parsers/readers.py", line 586, in read_csv
    return _read(filepath_or_buffer, kwds)
  File "/home/airflow/.local/lib/python3.7/site-packages/pandas/io/parsers/readers.py", line 482, in _read
    parser = TextFileReader(filepath_or_buffer, **kwds)
  File "/home/airflow/.local/lib/python3.7/site-packages/pandas/io/parsers/readers.py", line 811, in __init__
    self._engine = self._make_engine(self.engine)
  File "/home/airflow/.local/lib/python3.7/site-packages/pandas/io/parsers/readers.py", line 1040, in _make_engine
    return mapping[engine](self.f, **self.options)  # type: ignore[call-arg]
  File "/home/airflow/.local/lib/python3.7/site-packages/pandas/io/parsers/c_parser_wrapper.py", line 51, in __init__
    self._open_handles(src, kwds)
  File "/home/airflow/.local/lib/python3.7/site-packages/pandas/io/parsers/base_parser.py", line 229, in _open_handles
    errors=kwds.get("encoding_errors", "strict"),
  File "/home/airflow/.local/lib/python3.7/site-packages/pandas/io/common.py", line 707, in get_handle
    newline="",
FileNotFoundError: [Errno 2] No such file or directory: '/Users/80524/Downloads/apache_airflow/data/traffy_fondue_data.csv'
[2022-12-11T04:34:14.449+0000] {processor.py:768} WARNING - No viable dags retrieved from /opt/airflow/dags/data_tools_final_oprator.py
[2022-12-11T04:34:14.461+0000] {processor.py:176} INFO - Processing /opt/airflow/dags/data_tools_final_oprator.py took 1.951 seconds
[2022-12-11T04:34:44.789+0000] {processor.py:154} INFO - Started process (PID=27003) to work on /opt/airflow/dags/data_tools_final_oprator.py
[2022-12-11T04:34:44.790+0000] {processor.py:756} INFO - Processing file /opt/airflow/dags/data_tools_final_oprator.py for tasks to queue
[2022-12-11T04:34:44.792+0000] {logging_mixin.py:137} INFO - [2022-12-11T04:34:44.791+0000] {dagbag.py:537} INFO - Filling up the DagBag from /opt/airflow/dags/data_tools_final_oprator.py
[2022-12-11T04:34:46.740+0000] {logging_mixin.py:137} INFO - [2022-12-11T04:34:46.736+0000] {dagbag.py:342} ERROR - Failed to import: /opt/airflow/dags/data_tools_final_oprator.py
Traceback (most recent call last):
  File "/home/airflow/.local/lib/python3.7/site-packages/airflow/models/dagbag.py", line 338, in parse
    loader.exec_module(new_module)
  File "<frozen importlib._bootstrap_external>", line 728, in exec_module
  File "<frozen importlib._bootstrap>", line 219, in _call_with_frames_removed
  File "/opt/airflow/dags/data_tools_final_oprator.py", line 13, in <module>
    import datatool_model
  File "/opt/airflow/plugins/datatool_model.py", line 106, in <module>
    preprocess = traffy.import_data()
  File "/opt/airflow/plugins/datatool_model.py", line 24, in import_data
    df = pd.read_csv('/Users/80524/Downloads/apache_airflow/data/traffy_fondue_data.csv')
  File "/home/airflow/.local/lib/python3.7/site-packages/pandas/util/_decorators.py", line 311, in wrapper
    return func(*args, **kwargs)
  File "/home/airflow/.local/lib/python3.7/site-packages/pandas/io/parsers/readers.py", line 586, in read_csv
    return _read(filepath_or_buffer, kwds)
  File "/home/airflow/.local/lib/python3.7/site-packages/pandas/io/parsers/readers.py", line 482, in _read
    parser = TextFileReader(filepath_or_buffer, **kwds)
  File "/home/airflow/.local/lib/python3.7/site-packages/pandas/io/parsers/readers.py", line 811, in __init__
    self._engine = self._make_engine(self.engine)
  File "/home/airflow/.local/lib/python3.7/site-packages/pandas/io/parsers/readers.py", line 1040, in _make_engine
    return mapping[engine](self.f, **self.options)  # type: ignore[call-arg]
  File "/home/airflow/.local/lib/python3.7/site-packages/pandas/io/parsers/c_parser_wrapper.py", line 51, in __init__
    self._open_handles(src, kwds)
  File "/home/airflow/.local/lib/python3.7/site-packages/pandas/io/parsers/base_parser.py", line 229, in _open_handles
    errors=kwds.get("encoding_errors", "strict"),
  File "/home/airflow/.local/lib/python3.7/site-packages/pandas/io/common.py", line 707, in get_handle
    newline="",
FileNotFoundError: [Errno 2] No such file or directory: '/Users/80524/Downloads/apache_airflow/data/traffy_fondue_data.csv'
[2022-12-11T04:34:46.742+0000] {processor.py:768} WARNING - No viable dags retrieved from /opt/airflow/dags/data_tools_final_oprator.py
[2022-12-11T04:34:46.753+0000] {processor.py:176} INFO - Processing /opt/airflow/dags/data_tools_final_oprator.py took 1.967 seconds
[2022-12-11T04:35:17.163+0000] {processor.py:154} INFO - Started process (PID=27025) to work on /opt/airflow/dags/data_tools_final_oprator.py
[2022-12-11T04:35:17.167+0000] {processor.py:756} INFO - Processing file /opt/airflow/dags/data_tools_final_oprator.py for tasks to queue
[2022-12-11T04:35:17.171+0000] {logging_mixin.py:137} INFO - [2022-12-11T04:35:17.171+0000] {dagbag.py:537} INFO - Filling up the DagBag from /opt/airflow/dags/data_tools_final_oprator.py
[2022-12-11T04:35:19.144+0000] {logging_mixin.py:137} INFO - [2022-12-11T04:35:19.140+0000] {dagbag.py:342} ERROR - Failed to import: /opt/airflow/dags/data_tools_final_oprator.py
Traceback (most recent call last):
  File "/home/airflow/.local/lib/python3.7/site-packages/airflow/models/dagbag.py", line 338, in parse
    loader.exec_module(new_module)
  File "<frozen importlib._bootstrap_external>", line 728, in exec_module
  File "<frozen importlib._bootstrap>", line 219, in _call_with_frames_removed
  File "/opt/airflow/dags/data_tools_final_oprator.py", line 13, in <module>
    import datatool_model
  File "/opt/airflow/plugins/datatool_model.py", line 106, in <module>
    preprocess = traffy.import_data()
  File "/opt/airflow/plugins/datatool_model.py", line 24, in import_data
    df = pd.read_csv('/Users/80524/Downloads/apache_airflow/data/traffy_fondue_data.csv')
  File "/home/airflow/.local/lib/python3.7/site-packages/pandas/util/_decorators.py", line 311, in wrapper
    return func(*args, **kwargs)
  File "/home/airflow/.local/lib/python3.7/site-packages/pandas/io/parsers/readers.py", line 586, in read_csv
    return _read(filepath_or_buffer, kwds)
  File "/home/airflow/.local/lib/python3.7/site-packages/pandas/io/parsers/readers.py", line 482, in _read
    parser = TextFileReader(filepath_or_buffer, **kwds)
  File "/home/airflow/.local/lib/python3.7/site-packages/pandas/io/parsers/readers.py", line 811, in __init__
    self._engine = self._make_engine(self.engine)
  File "/home/airflow/.local/lib/python3.7/site-packages/pandas/io/parsers/readers.py", line 1040, in _make_engine
    return mapping[engine](self.f, **self.options)  # type: ignore[call-arg]
  File "/home/airflow/.local/lib/python3.7/site-packages/pandas/io/parsers/c_parser_wrapper.py", line 51, in __init__
    self._open_handles(src, kwds)
  File "/home/airflow/.local/lib/python3.7/site-packages/pandas/io/parsers/base_parser.py", line 229, in _open_handles
    errors=kwds.get("encoding_errors", "strict"),
  File "/home/airflow/.local/lib/python3.7/site-packages/pandas/io/common.py", line 707, in get_handle
    newline="",
FileNotFoundError: [Errno 2] No such file or directory: '/Users/80524/Downloads/apache_airflow/data/traffy_fondue_data.csv'
[2022-12-11T04:35:19.146+0000] {processor.py:768} WARNING - No viable dags retrieved from /opt/airflow/dags/data_tools_final_oprator.py
[2022-12-11T04:35:19.157+0000] {processor.py:176} INFO - Processing /opt/airflow/dags/data_tools_final_oprator.py took 1.998 seconds
[2022-12-11T04:35:49.565+0000] {processor.py:154} INFO - Started process (PID=27053) to work on /opt/airflow/dags/data_tools_final_oprator.py
[2022-12-11T04:35:49.570+0000] {processor.py:756} INFO - Processing file /opt/airflow/dags/data_tools_final_oprator.py for tasks to queue
[2022-12-11T04:35:49.571+0000] {logging_mixin.py:137} INFO - [2022-12-11T04:35:49.571+0000] {dagbag.py:537} INFO - Filling up the DagBag from /opt/airflow/dags/data_tools_final_oprator.py
[2022-12-11T04:35:51.753+0000] {logging_mixin.py:137} INFO - [2022-12-11T04:35:51.749+0000] {dagbag.py:342} ERROR - Failed to import: /opt/airflow/dags/data_tools_final_oprator.py
Traceback (most recent call last):
  File "/home/airflow/.local/lib/python3.7/site-packages/airflow/models/dagbag.py", line 338, in parse
    loader.exec_module(new_module)
  File "<frozen importlib._bootstrap_external>", line 728, in exec_module
  File "<frozen importlib._bootstrap>", line 219, in _call_with_frames_removed
  File "/opt/airflow/dags/data_tools_final_oprator.py", line 13, in <module>
    import datatool_model
  File "/opt/airflow/plugins/datatool_model.py", line 106, in <module>
    preprocess = traffy.import_data()
  File "/opt/airflow/plugins/datatool_model.py", line 24, in import_data
    df = pd.read_csv('/Users/80524/Downloads/apache_airflow/data/traffy_fondue_data.csv')
  File "/home/airflow/.local/lib/python3.7/site-packages/pandas/util/_decorators.py", line 311, in wrapper
    return func(*args, **kwargs)
  File "/home/airflow/.local/lib/python3.7/site-packages/pandas/io/parsers/readers.py", line 586, in read_csv
    return _read(filepath_or_buffer, kwds)
  File "/home/airflow/.local/lib/python3.7/site-packages/pandas/io/parsers/readers.py", line 482, in _read
    parser = TextFileReader(filepath_or_buffer, **kwds)
  File "/home/airflow/.local/lib/python3.7/site-packages/pandas/io/parsers/readers.py", line 811, in __init__
    self._engine = self._make_engine(self.engine)
  File "/home/airflow/.local/lib/python3.7/site-packages/pandas/io/parsers/readers.py", line 1040, in _make_engine
    return mapping[engine](self.f, **self.options)  # type: ignore[call-arg]
  File "/home/airflow/.local/lib/python3.7/site-packages/pandas/io/parsers/c_parser_wrapper.py", line 51, in __init__
    self._open_handles(src, kwds)
  File "/home/airflow/.local/lib/python3.7/site-packages/pandas/io/parsers/base_parser.py", line 229, in _open_handles
    errors=kwds.get("encoding_errors", "strict"),
  File "/home/airflow/.local/lib/python3.7/site-packages/pandas/io/common.py", line 707, in get_handle
    newline="",
FileNotFoundError: [Errno 2] No such file or directory: '/Users/80524/Downloads/apache_airflow/data/traffy_fondue_data.csv'
[2022-12-11T04:35:51.755+0000] {processor.py:768} WARNING - No viable dags retrieved from /opt/airflow/dags/data_tools_final_oprator.py
[2022-12-11T04:35:51.766+0000] {processor.py:176} INFO - Processing /opt/airflow/dags/data_tools_final_oprator.py took 2.208 seconds
[2022-12-11T04:36:21.869+0000] {processor.py:154} INFO - Started process (PID=27081) to work on /opt/airflow/dags/data_tools_final_oprator.py
[2022-12-11T04:36:21.872+0000] {processor.py:756} INFO - Processing file /opt/airflow/dags/data_tools_final_oprator.py for tasks to queue
[2022-12-11T04:36:21.874+0000] {logging_mixin.py:137} INFO - [2022-12-11T04:36:21.874+0000] {dagbag.py:537} INFO - Filling up the DagBag from /opt/airflow/dags/data_tools_final_oprator.py
[2022-12-11T04:36:24.417+0000] {logging_mixin.py:137} INFO - [2022-12-11T04:36:24.412+0000] {dagbag.py:342} ERROR - Failed to import: /opt/airflow/dags/data_tools_final_oprator.py
Traceback (most recent call last):
  File "/home/airflow/.local/lib/python3.7/site-packages/airflow/models/dagbag.py", line 338, in parse
    loader.exec_module(new_module)
  File "<frozen importlib._bootstrap_external>", line 728, in exec_module
  File "<frozen importlib._bootstrap>", line 219, in _call_with_frames_removed
  File "/opt/airflow/dags/data_tools_final_oprator.py", line 13, in <module>
    import datatool_model
  File "/opt/airflow/plugins/datatool_model.py", line 106, in <module>
    preprocess = traffy.import_data()
  File "/opt/airflow/plugins/datatool_model.py", line 24, in import_data
    df = pd.read_csv('/Users/80524/Downloads/apache_airflow/data/traffy_fondue_data.csv')
  File "/home/airflow/.local/lib/python3.7/site-packages/pandas/util/_decorators.py", line 311, in wrapper
    return func(*args, **kwargs)
  File "/home/airflow/.local/lib/python3.7/site-packages/pandas/io/parsers/readers.py", line 586, in read_csv
    return _read(filepath_or_buffer, kwds)
  File "/home/airflow/.local/lib/python3.7/site-packages/pandas/io/parsers/readers.py", line 482, in _read
    parser = TextFileReader(filepath_or_buffer, **kwds)
  File "/home/airflow/.local/lib/python3.7/site-packages/pandas/io/parsers/readers.py", line 811, in __init__
    self._engine = self._make_engine(self.engine)
  File "/home/airflow/.local/lib/python3.7/site-packages/pandas/io/parsers/readers.py", line 1040, in _make_engine
    return mapping[engine](self.f, **self.options)  # type: ignore[call-arg]
  File "/home/airflow/.local/lib/python3.7/site-packages/pandas/io/parsers/c_parser_wrapper.py", line 51, in __init__
    self._open_handles(src, kwds)
  File "/home/airflow/.local/lib/python3.7/site-packages/pandas/io/parsers/base_parser.py", line 229, in _open_handles
    errors=kwds.get("encoding_errors", "strict"),
  File "/home/airflow/.local/lib/python3.7/site-packages/pandas/io/common.py", line 707, in get_handle
    newline="",
FileNotFoundError: [Errno 2] No such file or directory: '/Users/80524/Downloads/apache_airflow/data/traffy_fondue_data.csv'
[2022-12-11T04:36:24.419+0000] {processor.py:768} WARNING - No viable dags retrieved from /opt/airflow/dags/data_tools_final_oprator.py
[2022-12-11T04:36:24.431+0000] {processor.py:176} INFO - Processing /opt/airflow/dags/data_tools_final_oprator.py took 2.566 seconds
[2022-12-11T04:36:54.764+0000] {processor.py:154} INFO - Started process (PID=27110) to work on /opt/airflow/dags/data_tools_final_oprator.py
[2022-12-11T04:36:54.767+0000] {processor.py:756} INFO - Processing file /opt/airflow/dags/data_tools_final_oprator.py for tasks to queue
[2022-12-11T04:36:54.769+0000] {logging_mixin.py:137} INFO - [2022-12-11T04:36:54.768+0000] {dagbag.py:537} INFO - Filling up the DagBag from /opt/airflow/dags/data_tools_final_oprator.py
[2022-12-11T04:36:56.967+0000] {logging_mixin.py:137} INFO - [2022-12-11T04:36:56.963+0000] {dagbag.py:342} ERROR - Failed to import: /opt/airflow/dags/data_tools_final_oprator.py
Traceback (most recent call last):
  File "/home/airflow/.local/lib/python3.7/site-packages/airflow/models/dagbag.py", line 338, in parse
    loader.exec_module(new_module)
  File "<frozen importlib._bootstrap_external>", line 728, in exec_module
  File "<frozen importlib._bootstrap>", line 219, in _call_with_frames_removed
  File "/opt/airflow/dags/data_tools_final_oprator.py", line 13, in <module>
    import datatool_model
  File "/opt/airflow/plugins/datatool_model.py", line 106, in <module>
    preprocess = traffy.import_data()
  File "/opt/airflow/plugins/datatool_model.py", line 24, in import_data
    df = pd.read_csv('/Users/80524/Downloads/apache_airflow/data/traffy_fondue_data.csv')
  File "/home/airflow/.local/lib/python3.7/site-packages/pandas/util/_decorators.py", line 311, in wrapper
    return func(*args, **kwargs)
  File "/home/airflow/.local/lib/python3.7/site-packages/pandas/io/parsers/readers.py", line 586, in read_csv
    return _read(filepath_or_buffer, kwds)
  File "/home/airflow/.local/lib/python3.7/site-packages/pandas/io/parsers/readers.py", line 482, in _read
    parser = TextFileReader(filepath_or_buffer, **kwds)
  File "/home/airflow/.local/lib/python3.7/site-packages/pandas/io/parsers/readers.py", line 811, in __init__
    self._engine = self._make_engine(self.engine)
  File "/home/airflow/.local/lib/python3.7/site-packages/pandas/io/parsers/readers.py", line 1040, in _make_engine
    return mapping[engine](self.f, **self.options)  # type: ignore[call-arg]
  File "/home/airflow/.local/lib/python3.7/site-packages/pandas/io/parsers/c_parser_wrapper.py", line 51, in __init__
    self._open_handles(src, kwds)
  File "/home/airflow/.local/lib/python3.7/site-packages/pandas/io/parsers/base_parser.py", line 229, in _open_handles
    errors=kwds.get("encoding_errors", "strict"),
  File "/home/airflow/.local/lib/python3.7/site-packages/pandas/io/common.py", line 707, in get_handle
    newline="",
FileNotFoundError: [Errno 2] No such file or directory: '/Users/80524/Downloads/apache_airflow/data/traffy_fondue_data.csv'
[2022-12-11T04:36:56.968+0000] {processor.py:768} WARNING - No viable dags retrieved from /opt/airflow/dags/data_tools_final_oprator.py
[2022-12-11T04:36:56.979+0000] {processor.py:176} INFO - Processing /opt/airflow/dags/data_tools_final_oprator.py took 2.220 seconds
[2022-12-11T04:37:27.271+0000] {processor.py:154} INFO - Started process (PID=27138) to work on /opt/airflow/dags/data_tools_final_oprator.py
[2022-12-11T04:37:27.275+0000] {processor.py:756} INFO - Processing file /opt/airflow/dags/data_tools_final_oprator.py for tasks to queue
[2022-12-11T04:37:27.277+0000] {logging_mixin.py:137} INFO - [2022-12-11T04:37:27.277+0000] {dagbag.py:537} INFO - Filling up the DagBag from /opt/airflow/dags/data_tools_final_oprator.py
[2022-12-11T04:37:29.440+0000] {logging_mixin.py:137} INFO - [2022-12-11T04:37:29.435+0000] {dagbag.py:342} ERROR - Failed to import: /opt/airflow/dags/data_tools_final_oprator.py
Traceback (most recent call last):
  File "/home/airflow/.local/lib/python3.7/site-packages/airflow/models/dagbag.py", line 338, in parse
    loader.exec_module(new_module)
  File "<frozen importlib._bootstrap_external>", line 728, in exec_module
  File "<frozen importlib._bootstrap>", line 219, in _call_with_frames_removed
  File "/opt/airflow/dags/data_tools_final_oprator.py", line 13, in <module>
    import datatool_model
  File "/opt/airflow/plugins/datatool_model.py", line 106, in <module>
    preprocess = traffy.import_data()
  File "/opt/airflow/plugins/datatool_model.py", line 24, in import_data
    df = pd.read_csv('/Users/80524/Downloads/apache_airflow/data/traffy_fondue_data.csv')
  File "/home/airflow/.local/lib/python3.7/site-packages/pandas/util/_decorators.py", line 311, in wrapper
    return func(*args, **kwargs)
  File "/home/airflow/.local/lib/python3.7/site-packages/pandas/io/parsers/readers.py", line 586, in read_csv
    return _read(filepath_or_buffer, kwds)
  File "/home/airflow/.local/lib/python3.7/site-packages/pandas/io/parsers/readers.py", line 482, in _read
    parser = TextFileReader(filepath_or_buffer, **kwds)
  File "/home/airflow/.local/lib/python3.7/site-packages/pandas/io/parsers/readers.py", line 811, in __init__
    self._engine = self._make_engine(self.engine)
  File "/home/airflow/.local/lib/python3.7/site-packages/pandas/io/parsers/readers.py", line 1040, in _make_engine
    return mapping[engine](self.f, **self.options)  # type: ignore[call-arg]
  File "/home/airflow/.local/lib/python3.7/site-packages/pandas/io/parsers/c_parser_wrapper.py", line 51, in __init__
    self._open_handles(src, kwds)
  File "/home/airflow/.local/lib/python3.7/site-packages/pandas/io/parsers/base_parser.py", line 229, in _open_handles
    errors=kwds.get("encoding_errors", "strict"),
  File "/home/airflow/.local/lib/python3.7/site-packages/pandas/io/common.py", line 707, in get_handle
    newline="",
FileNotFoundError: [Errno 2] No such file or directory: '/Users/80524/Downloads/apache_airflow/data/traffy_fondue_data.csv'
[2022-12-11T04:37:29.442+0000] {processor.py:768} WARNING - No viable dags retrieved from /opt/airflow/dags/data_tools_final_oprator.py
[2022-12-11T04:37:29.458+0000] {processor.py:176} INFO - Processing /opt/airflow/dags/data_tools_final_oprator.py took 2.192 seconds
[2022-12-11T04:37:59.627+0000] {processor.py:154} INFO - Started process (PID=27167) to work on /opt/airflow/dags/data_tools_final_oprator.py
[2022-12-11T04:37:59.629+0000] {processor.py:756} INFO - Processing file /opt/airflow/dags/data_tools_final_oprator.py for tasks to queue
[2022-12-11T04:37:59.631+0000] {logging_mixin.py:137} INFO - [2022-12-11T04:37:59.631+0000] {dagbag.py:537} INFO - Filling up the DagBag from /opt/airflow/dags/data_tools_final_oprator.py
[2022-12-11T04:38:01.712+0000] {logging_mixin.py:137} INFO - [2022-12-11T04:38:01.707+0000] {dagbag.py:342} ERROR - Failed to import: /opt/airflow/dags/data_tools_final_oprator.py
Traceback (most recent call last):
  File "/home/airflow/.local/lib/python3.7/site-packages/airflow/models/dagbag.py", line 338, in parse
    loader.exec_module(new_module)
  File "<frozen importlib._bootstrap_external>", line 728, in exec_module
  File "<frozen importlib._bootstrap>", line 219, in _call_with_frames_removed
  File "/opt/airflow/dags/data_tools_final_oprator.py", line 13, in <module>
    import datatool_model
  File "/opt/airflow/plugins/datatool_model.py", line 106, in <module>
    preprocess = traffy.import_data()
  File "/opt/airflow/plugins/datatool_model.py", line 24, in import_data
    df = pd.read_csv('/Users/80524/Downloads/apache_airflow/data/traffy_fondue_data.csv')
  File "/home/airflow/.local/lib/python3.7/site-packages/pandas/util/_decorators.py", line 311, in wrapper
    return func(*args, **kwargs)
  File "/home/airflow/.local/lib/python3.7/site-packages/pandas/io/parsers/readers.py", line 586, in read_csv
    return _read(filepath_or_buffer, kwds)
  File "/home/airflow/.local/lib/python3.7/site-packages/pandas/io/parsers/readers.py", line 482, in _read
    parser = TextFileReader(filepath_or_buffer, **kwds)
  File "/home/airflow/.local/lib/python3.7/site-packages/pandas/io/parsers/readers.py", line 811, in __init__
    self._engine = self._make_engine(self.engine)
  File "/home/airflow/.local/lib/python3.7/site-packages/pandas/io/parsers/readers.py", line 1040, in _make_engine
    return mapping[engine](self.f, **self.options)  # type: ignore[call-arg]
  File "/home/airflow/.local/lib/python3.7/site-packages/pandas/io/parsers/c_parser_wrapper.py", line 51, in __init__
    self._open_handles(src, kwds)
  File "/home/airflow/.local/lib/python3.7/site-packages/pandas/io/parsers/base_parser.py", line 229, in _open_handles
    errors=kwds.get("encoding_errors", "strict"),
  File "/home/airflow/.local/lib/python3.7/site-packages/pandas/io/common.py", line 707, in get_handle
    newline="",
FileNotFoundError: [Errno 2] No such file or directory: '/Users/80524/Downloads/apache_airflow/data/traffy_fondue_data.csv'
[2022-12-11T04:38:01.714+0000] {processor.py:768} WARNING - No viable dags retrieved from /opt/airflow/dags/data_tools_final_oprator.py
[2022-12-11T04:38:01.724+0000] {processor.py:176} INFO - Processing /opt/airflow/dags/data_tools_final_oprator.py took 2.102 seconds
[2022-12-11T04:38:31.981+0000] {processor.py:154} INFO - Started process (PID=27195) to work on /opt/airflow/dags/data_tools_final_oprator.py
[2022-12-11T04:38:31.984+0000] {processor.py:756} INFO - Processing file /opt/airflow/dags/data_tools_final_oprator.py for tasks to queue
[2022-12-11T04:38:31.987+0000] {logging_mixin.py:137} INFO - [2022-12-11T04:38:31.987+0000] {dagbag.py:537} INFO - Filling up the DagBag from /opt/airflow/dags/data_tools_final_oprator.py
[2022-12-11T04:38:34.167+0000] {logging_mixin.py:137} INFO - [2022-12-11T04:38:34.163+0000] {dagbag.py:342} ERROR - Failed to import: /opt/airflow/dags/data_tools_final_oprator.py
Traceback (most recent call last):
  File "/home/airflow/.local/lib/python3.7/site-packages/airflow/models/dagbag.py", line 338, in parse
    loader.exec_module(new_module)
  File "<frozen importlib._bootstrap_external>", line 728, in exec_module
  File "<frozen importlib._bootstrap>", line 219, in _call_with_frames_removed
  File "/opt/airflow/dags/data_tools_final_oprator.py", line 13, in <module>
    import datatool_model
  File "/opt/airflow/plugins/datatool_model.py", line 106, in <module>
    preprocess = traffy.import_data()
  File "/opt/airflow/plugins/datatool_model.py", line 24, in import_data
    df = pd.read_csv('/Users/80524/Downloads/apache_airflow/data/traffy_fondue_data.csv')
  File "/home/airflow/.local/lib/python3.7/site-packages/pandas/util/_decorators.py", line 311, in wrapper
    return func(*args, **kwargs)
  File "/home/airflow/.local/lib/python3.7/site-packages/pandas/io/parsers/readers.py", line 586, in read_csv
    return _read(filepath_or_buffer, kwds)
  File "/home/airflow/.local/lib/python3.7/site-packages/pandas/io/parsers/readers.py", line 482, in _read
    parser = TextFileReader(filepath_or_buffer, **kwds)
  File "/home/airflow/.local/lib/python3.7/site-packages/pandas/io/parsers/readers.py", line 811, in __init__
    self._engine = self._make_engine(self.engine)
  File "/home/airflow/.local/lib/python3.7/site-packages/pandas/io/parsers/readers.py", line 1040, in _make_engine
    return mapping[engine](self.f, **self.options)  # type: ignore[call-arg]
  File "/home/airflow/.local/lib/python3.7/site-packages/pandas/io/parsers/c_parser_wrapper.py", line 51, in __init__
    self._open_handles(src, kwds)
  File "/home/airflow/.local/lib/python3.7/site-packages/pandas/io/parsers/base_parser.py", line 229, in _open_handles
    errors=kwds.get("encoding_errors", "strict"),
  File "/home/airflow/.local/lib/python3.7/site-packages/pandas/io/common.py", line 707, in get_handle
    newline="",
FileNotFoundError: [Errno 2] No such file or directory: '/Users/80524/Downloads/apache_airflow/data/traffy_fondue_data.csv'
[2022-12-11T04:38:34.169+0000] {processor.py:768} WARNING - No viable dags retrieved from /opt/airflow/dags/data_tools_final_oprator.py
[2022-12-11T04:38:34.180+0000] {processor.py:176} INFO - Processing /opt/airflow/dags/data_tools_final_oprator.py took 2.204 seconds
