[2022-12-05T07:27:22.092+0000] {taskinstance.py:1165} INFO - Dependencies all met for <TaskInstance: traffy_fondue_data_analyst.model_processing scheduled__2022-12-04T00:00:00+00:00 [queued]>
[2022-12-05T07:27:22.099+0000] {taskinstance.py:1165} INFO - Dependencies all met for <TaskInstance: traffy_fondue_data_analyst.model_processing scheduled__2022-12-04T00:00:00+00:00 [queued]>
[2022-12-05T07:27:22.100+0000] {taskinstance.py:1362} INFO - 
--------------------------------------------------------------------------------
[2022-12-05T07:27:22.101+0000] {taskinstance.py:1363} INFO - Starting attempt 1 of 1
[2022-12-05T07:27:22.102+0000] {taskinstance.py:1364} INFO - 
--------------------------------------------------------------------------------
[2022-12-05T07:27:22.110+0000] {taskinstance.py:1383} INFO - Executing <Task(PythonOperator): model_processing> on 2022-12-04 00:00:00+00:00
[2022-12-05T07:27:22.119+0000] {standard_task_runner.py:55} INFO - Started process 195 to run task
[2022-12-05T07:27:22.122+0000] {standard_task_runner.py:82} INFO - Running: ['***', 'tasks', 'run', 'traffy_fondue_data_analyst', 'model_processing', 'scheduled__2022-12-04T00:00:00+00:00', '--job-id', '153', '--raw', '--subdir', 'DAGS_FOLDER/data_tools_final._oprator.py', '--cfg-path', '/tmp/tmpqeb5n9y5']
[2022-12-05T07:27:22.125+0000] {standard_task_runner.py:83} INFO - Job 153: Subtask model_processing
[2022-12-05T07:27:22.167+0000] {task_command.py:376} INFO - Running <TaskInstance: traffy_fondue_data_analyst.model_processing scheduled__2022-12-04T00:00:00+00:00 [running]> on host 0bd7e010c569
[2022-12-05T07:27:22.209+0000] {taskinstance.py:1592} INFO - Exporting the following env vars:
AIRFLOW_CTX_DAG_OWNER=***
AIRFLOW_CTX_DAG_ID=traffy_fondue_data_analyst
AIRFLOW_CTX_TASK_ID=model_processing
AIRFLOW_CTX_EXECUTION_DATE=2022-12-04T00:00:00+00:00
AIRFLOW_CTX_TRY_NUMBER=1
AIRFLOW_CTX_DAG_RUN_ID=scheduled__2022-12-04T00:00:00+00:00
[2022-12-05T07:27:22.211+0000] {taskinstance.py:1851} ERROR - Task failed with exception
Traceback (most recent call last):
  File "/home/airflow/.local/lib/python3.7/site-packages/airflow/operators/python.py", line 175, in execute
    return_value = self.execute_callable()
  File "/home/airflow/.local/lib/python3.7/site-packages/airflow/operators/python.py", line 193, in execute_callable
    return self.python_callable(*self.op_args, **self.op_kwargs)
  File "/opt/airflow/dags/data_tools_final._oprator.py", line 57, in Model_processing
    traffy = da(logistic_model)
TypeError: 'module' object is not callable
[2022-12-05T07:27:22.220+0000] {taskinstance.py:1406} INFO - Marking task as FAILED. dag_id=traffy_fondue_data_analyst, task_id=model_processing, execution_date=20221204T000000, start_date=20221205T072722, end_date=20221205T072722
[2022-12-05T07:27:22.231+0000] {standard_task_runner.py:105} ERROR - Failed to execute job 153 for task model_processing ('module' object is not callable; 195)
[2022-12-05T07:27:22.255+0000] {local_task_job.py:159} INFO - Task exited with return code 1
[2022-12-05T07:27:22.271+0000] {taskinstance.py:2623} INFO - 0 downstream tasks scheduled from follow-on schedule check
