[2022-12-05T00:11:04.738+0000] {taskinstance.py:1165} INFO - Dependencies all met for <TaskInstance: python_operator_pyspark.load_data scheduled__2022-12-04T00:00:00+00:00 [queued]>
[2022-12-05T00:11:04.757+0000] {taskinstance.py:1165} INFO - Dependencies all met for <TaskInstance: python_operator_pyspark.load_data scheduled__2022-12-04T00:00:00+00:00 [queued]>
[2022-12-05T00:11:04.759+0000] {taskinstance.py:1362} INFO - 
--------------------------------------------------------------------------------
[2022-12-05T00:11:04.761+0000] {taskinstance.py:1363} INFO - Starting attempt 1 of 1
[2022-12-05T00:11:04.763+0000] {taskinstance.py:1364} INFO - 
--------------------------------------------------------------------------------
[2022-12-05T00:11:04.803+0000] {taskinstance.py:1383} INFO - Executing <Task(PythonOperator): load_data> on 2022-12-04 00:00:00+00:00
[2022-12-05T00:11:04.809+0000] {standard_task_runner.py:55} INFO - Started process 6370 to run task
[2022-12-05T00:11:04.821+0000] {standard_task_runner.py:82} INFO - Running: ['***', 'tasks', 'run', 'python_operator_pyspark', 'load_data', 'scheduled__2022-12-04T00:00:00+00:00', '--job-id', '142', '--raw', '--subdir', 'DAGS_FOLDER/load_data_to_spark_backup.py', '--cfg-path', '/tmp/tmp4oiiezdn']
[2022-12-05T00:11:04.823+0000] {standard_task_runner.py:83} INFO - Job 142: Subtask load_data
[2022-12-05T00:11:04.912+0000] {task_command.py:376} INFO - Running <TaskInstance: python_operator_pyspark.load_data scheduled__2022-12-04T00:00:00+00:00 [running]> on host 71a129efd3d8
[2022-12-05T00:11:04.982+0000] {taskinstance.py:1592} INFO - Exporting the following env vars:
AIRFLOW_CTX_DAG_OWNER=***
AIRFLOW_CTX_DAG_ID=python_operator_pyspark
AIRFLOW_CTX_TASK_ID=load_data
AIRFLOW_CTX_EXECUTION_DATE=2022-12-04T00:00:00+00:00
AIRFLOW_CTX_TRY_NUMBER=1
AIRFLOW_CTX_DAG_RUN_ID=scheduled__2022-12-04T00:00:00+00:00
[2022-12-05T00:11:14.821+0000] {taskinstance.py:1851} ERROR - Task failed with exception
Traceback (most recent call last):
  File "/home/airflow/.local/lib/python3.7/site-packages/airflow/operators/python.py", line 175, in execute
    return_value = self.execute_callable()
  File "/home/airflow/.local/lib/python3.7/site-packages/airflow/operators/python.py", line 193, in execute_callable
    return self.python_callable(*self.op_args, **self.op_kwargs)
  File "/opt/airflow/dags/load_data_to_spark_backup.py", line 19, in load_data
    .json("./data/*.json")
  File "/opt/spark/python/pyspark/sql/readwriter.py", line 284, in json
    return self._df(self._jreader.json(self._spark._sc._jvm.PythonUtils.toSeq(path)))
  File "/opt/spark/python/lib/py4j-0.10.9.5-src.zip/py4j/java_gateway.py", line 1322, in __call__
    answer, self.gateway_client, self.target_id, self.name)
  File "/opt/spark/python/pyspark/sql/utils.py", line 196, in deco
    raise converted from None
pyspark.sql.utils.AnalysisException: Path does not exist: file:/opt/airflow/data/*.json
[2022-12-05T00:11:14.850+0000] {taskinstance.py:1406} INFO - Marking task as FAILED. dag_id=python_operator_pyspark, task_id=load_data, execution_date=20221204T000000, start_date=20221205T001104, end_date=20221205T001114
[2022-12-05T00:11:14.858+0000] {standard_task_runner.py:105} ERROR - Failed to execute job 142 for task load_data (Path does not exist: file:/opt/airflow/data/*.json; 6370)
[2022-12-05T00:11:14.907+0000] {local_task_job.py:159} INFO - Task exited with return code 1
[2022-12-05T00:11:15.150+0000] {taskinstance.py:2623} INFO - 0 downstream tasks scheduled from follow-on schedule check
